Workbook

Sheet Резюме
B2: БИЗНЕС-ПЛАН ИНВЕСТИЦИОННОГО ПРОЕКТА
B3: Освоение центральной части вольфрамового месторождения Сарикуль (1-я очередь)
B4: (Освоение вольфрамового месторождения Сарикул)
B6: 1. ОБЩИЕ СВЕДЕНИЯ
B7: Суть проекта | C7: Освоение центральной части вольфрамового месторождения Сарикуль (1-я очередь). Переработка 600 тыс. т руды в год; выпуск основной продукции - Вольфрамовый концентрат 57 8% WO3 4 200 t/год при проектной мощности; реализация - внутренний рынок.
B8: Заемщик | C8: АО «Узбекский комбинат технологических металлов» (АО «Ўзбекистон ТМК», UzTMK)
B9: Местоположение | C9: месторождение Сарикул
B10: Продукция | C10: Вольфрамовый концентрат 57,8% WO3
B11: Производственная мощность | C11: Переработка 600 тыс. т руды в год; выпуск основной продукции - 4 200 t/год
B12: Рынок сбыта | C12: внутренний рынок (поставка концентрата на переработку), цены в USD
B13: Сроки | C13: начало строительства - 01.09.2026; начало производства - 01.09.2027; выход на проектную мощность - 2030 г.
B14: Стадия проработки | C14: Предварительное ТЭО
B16: 2. ПАРАМЕТРЫ КРЕДИТА
B17: Сумма кредита, USD | C17: =ИНФОРМАЦИЯ!$C$26 -> 42783896
B18: Процентная ставка | C18: =ИНФОРМАЦИЯ!$C$27 -> 0.07
B19: Срок кредита | C19: 84 месяца (7 лет): льготный (инвестиционный) период - 12 месяцев (2027 г.), погашение - 72 месяца (2028-2033 гг.)
B20: Порядок погашения | C20: основной долг - ежемесячно равными долями; проценты - ежемесячно на остаток задолженности
B21: Проценты льготного периода | C21: =TEXT(LOANS!$C$106,"#,##0") & " USD - уплачиваются за счёт собственных средств заемщика (включены в стоимость проекта)" -> 3,036,468 USD - уплачиваются за счёт собственных средств заемщика (включены в стоимость проекта)
B22: Целевое назначение | C22: 30% авансовый платёж по EPC-контракту (E - проектирование, P - поставка оборудования, C - строительство)
B24: 3. СТОИМОСТЬ ПРОЕКТА И ИСТОЧНИКИ ФИНАНСИРОВАНИЯ
B25: Статья | C25: USD | D25: Доля
B26: Фиксированные активы | C26: =ProjCost!E5 -> 1.4161333e+08 | D26: =IFERROR(C26/ProjCost!$E$22,0) -> 0.8259959
B27: Рабочий капитал | C27: =ProjCost!E11 -> 25294194 | D27: =IFERROR(C27/ProjCost!$E$22,0) -> 0.14753484
B28: Проценты льготного периода и расходы подготовительного периода | C28: =ProjCost!E17 -> 4110198.3 | D28: =IFERROR(C28/ProjCost!$E$22,0) -> 0.02397378
B29: Резерв | C29: =ProjCost!E20 -> 427838.96 | D29: =IFERROR(C29/ProjCost!$E$22,0) -> 0.0024954799
B30: ВСЕГО СТОИМОСТЬ ПРОЕКТА | C30: =ProjCost!E22 -> 1.7144556e+08 | D30: =IFERROR(C30/ProjCost!$E$22,0) -> 1
B31: Собственные средства заемщика | C31: =FinPlan!$E$10 -> 1.2866167e+08 | D31: =IFERROR(C31/ProjCost!$E$22,0) -> 0.75045201
B32: Кредит банка | C32: =FinPlan!$E$14 -> 42783896 | D32: =IFERROR(C32/ProjCost!$E$22,0) -> 0.24954799
B34: 4. ОСНОВНЫЕ ФИНАНСОВЫЕ ПОКАЗАТЕЛИ ПО ГОДАМ
B35: ПОКАЗАТЕЛИ | C35: Ед. изм. | D35: 1 год (льготный / инвест.) | E35: 2 год | F35: 3 год | G35: 4 год | H35: 5 год | I35: 6 год | J35: 7 год
D36: 2027 | E36: 2028 | F36: 2029 | G36: 2030 | H36: 2031 | I36: 2032 | J36: 2033
B37: Выручка (без НДС) | C37: USD | D37: =ProfLoss!D10 -> 23861585 | E37: =ProfLoss!E10 -> 85083568 | F37: =ProfLoss!F10 -> 94036971 | G37: =ProfLoss!G10 -> 1.2209613e+08 | H37: =ProfLoss!H10 -> 1.19963e+08 | I37: =ProfLoss!I10 -> 1.2252059e+08 | J37: =ProfLoss!J10 -> 1.2521653e+08
B38: EBITDA | C38: USD | D38: =ProfLoss!D27 -> 11035331 | E38: =ProfLoss!E27 -> 53030081 | F38: =ProfLoss!F27 -> 56029869 | G38: =ProfLoss!G27 -> 63019565 | H38: =ProfLoss!H27 -> 52039956 | I38: =ProfLoss!I27 -> 53069157 | J38: =ProfLoss!J27 -> 54159268
B39: Чистая прибыль | C39: USD | D39: =ProfLoss!D22 -> 3541570.5 | E39: =ProfLoss!E22 -> 19438643 | F39: =ProfLoss!F22 -> 21292482 | G39: =ProfLoss!G22 -> 24368803 | H39: =ProfLoss!H22 -> 15587710 | I39: =ProfLoss!I22 -> 16481056 | J39: =ProfLoss!J22 -> 17415037
B40: Операционный поток наличности (A) | C40: USD | D40: =CashFlow!D18 -> -16752461 | E40: =CashFlow!E18 -> 52390242 | F40: =CashFlow!F18 -> 42237651 | G40: =CashFlow!G18 -> 40056298 | H40: =CashFlow!H18 -> 33451740 | I40: =CashFlow!I18 -> 33632223 | J40: =CashFlow!J18 -> 34187695
B41: Обслуживание долга (проценты + основной долг) | C41: USD | D41: =LOANS!$C$107 -> 3036468.2 | E41: =LOANS!$D$107 -> 9942271 | F41: =LOANS!$E$107 -> 9427989.5 | G41: =LOANS!$F$107 -> 8921911.4 | H41: =LOANS!$G$107 -> 8415833.4 | I41: =LOANS!$H$107 -> 7912412.9 | J41: =LOANS!$I$107 -> 7403677.3
B42: Чистый поток наличности | C42: USD | D42: =CashFlow!D26 -> 10043303 | E42: =CashFlow!E26 -> 41036542 | F42: =CashFlow!F26 -> 31398233 | G42: =CashFlow!G26 -> 29722958 | H42: =CashFlow!H26 -> 23624478 | I42: =CashFlow!I26 -> 24308382 | J42: =CashFlow!J26 -> 25372589
B43: Кумулятивный поток наличности | C43: USD | D43: =CashFlow!D27 -> 10043303 | E43: =CashFlow!E27 -> 51079845 | F43: =CashFlow!F27 -> 82478078 | G43: =CashFlow!G27 -> 1.1220104e+08 | H43: =CashFlow!H27 -> 1.3582551e+08 | I43: =CashFlow!I27 -> 1.601339e+08 | J43: =CashFlow!J27 -> 1.8550648e+08
B44: DSCR (с учётом поддерживающих капвложений) | C44: x | D44: =CashFlow!D30 -> - | E44: =CashFlow!E30 -> 5.1274818 | F44: =CashFlow!F30 -> 4.3303212 | G44: =CashFlow!G30 -> 4.3314563 | H44: =CashFlow!H30 -> 3.8071466 | I44: =CashFlow!I30 -> 4.0721832 | J44: =CashFlow!J30 -> 4.4270252
B45: Задолженность по кредиту на конец года | C45: USD | D45: =LOANS!$C$108 -> 42783896 | E45: =LOANS!$D$108 -> 35653247 | F45: =LOANS!$E$108 -> 28522598 | G45: =LOANS!$F$108 -> 21391948 | H45: =LOANS!$G$108 -> 14261299 | I45: =LOANS!$H$108 -> 7130649.4 | J45: =LOANS!$I$108 -> 0
...

Sheet ИНФОРМАЦИЯ
B2: ДАННЫЕ ПО ПРОЕКТУ
B4: ЗАЕМЩИК | C4: АО «Узбекский комбинат технологических металлов» (АО «Ўзбекистон ТМК», UzTMK)
B5: ИНН | C5: - (заполняется заемщиком)
B6: ДЕЯТЕЛЬНОСТЬ | C6: Добыча и переработка редких и тугоплавких металлов (вольфрам, молибден)
B7: НАИМЕНОВАНИЕ ПРОЕКТА | C7: Освоение центральной части вольфрамового месторождения Сарикуль (1-я очередь) (Освоение вольфрамового месторождения Сарикул)
B8: МЕСТО РЕАЛИЗАЦИИ | C8: месторождение Сарикул
B9: ПРОИЗВОДСТВЕННАЯ МОЩНОСТЬ | C9: Переработка 600 тыс. т руды в год
B10: ОСНОВНАЯ ПРОДУКЦИЯ | C10: Вольфрамовый концентрат 57,8% WO3
B11: СТАДИЯ ПРОРАБОТКИ | C11: Предварительное ТЭО (Pre-FS)
B12: НАЧАЛО СТРОИТЕЛЬСТВА | C12: 01.09.2026
B13: НАЧАЛО ПРОИЗВОДСТВА | C13: 01.09.2027
B14: СРОК РЕАЛИЗАЦИИ (по данным заемщика) | C14: декабрь 2027 г.
B16: УЧАСТНИКИ ПРОЕКТА
B17: Заемщик (инициатор проекта) | C17: АО «Узбекский комбинат технологических металлов» (АО «Ўзбекистон ТМК», UzTMK)
B18: Доля заемщика в проекте | C18: 100%
B19: Кредитор №1 | C19: Банк-кредитор (наименование уточняется)
B20: Генеральный подрядчик | C20: EPC-подрядчик (по EPC-контракту)
B22: ВАЛЮТА ПРОЕКТА | C22: Доллар США (экв.)
B23: 1 USD = (сум, средний курс 1-го года) | C23: 12218.063
B25: УСЛОВИЯ КРЕДИТА
B26: Сумма кредита, USD | C26: =O40 -> 42783896
B27: Процентная ставка, % годовых | C27: 0.07
B28: Срок кредита, месяцев | C28: 84
B29: Льготный период по основному долгу, месяцев | C29: 12
B30: Инвестиционный период, месяцев | C30: 12
B31: Дата выдачи кредита | C31: 46388
B32: База начисления процентов, дней в году (по форме банка) | C32: 360
B33: Погашение основного долга | C33: ежемесячно равными долями (72 платежа), с 31.01.2028 по 31.12.2033
B34: Уплата процентов | C34: ежемесячно; в льготный период (2027 г.) - за счёт собственных средств заемщика (включены в стоимость проекта)
B35: Целевое назначение | C35: 30% авансовый платёж по EPC-контракту (данные заемщика)
B36: Резерв (непредвиденные расходы) - % от суммы кредита (по форме банка) | C36: 0.01
B38: РАСПРЕДЕЛЕНИЕ КРЕДИТА 78 МЛН USD МЕЖДУ ПРОЕКТАМИ (по 30% авансу EPC-контрактов, файл заемщика от 14.10.2026)
B39: Проект | C39: Мощность | D39: Стоимость проекта, млн USD | E39: EPC: E (Engineering), млрд сум | F39: EPC: P (Procurement), млрд сум | G39: EPC: C (Construction), млрд сум | H39: EPC итого, млрд сум | I39: Курс EPC (тыс. сум/USD) | J39: EPC итого, экв. млн USD | K39: 30% аванс, млрд сум | L39: Курс аванса (тыс. сум/USD) | M39: 30% аванс, млн USD | N39: Доля в кредите | O39: Кредит, USD
B40: Освоение центральной части вольфрамового месторождения Сарикуль (1-я очередь) | C40: Переработка 600 тыс. т руды в год | D40: 158 | E40: 116.0323 | F40: 532.896 | G40: 1041.5674 | H40: =E40+F40+G40 -> 1690.4957 | I40: 12.2 | J40: =H40/I40 -> 138.56522 | K40: =H40*30% -> 507.1487 | L40: 11.838 | M40: =K40/L40 -> 42.840742 | N40: =M40/$M$43 -> 0.54851149 | O40: =N40*$O$44 -> 42783896
B41: Строительство нового гидрометаллургического завода по переработке вольфрамового концентрата (1-я очередь) | C41: Переработка 5 000 т вольфрамового концентрата в год | D41: 80 | E41: 25.272 | F41: 293.4 | G41: 353.99904 | H41: =E41+F41+G41 -> 672.67104 | I41: 12 | J41: =H41/I41 -> 56.05592 | K41: =H41*30% -> 201.80131 | L41: 11.838 | M41: =K41/L41 -> 17.046909 | N41: =M41/$M$43 -> 0.21826012 | O41: =N41*$O$44 -> 17024290
B42: Строительство нового гидрометаллургического завода по переработке промышленного продукта - молибденового огарка | C42: Переработка 5 000 т молибденового огарка (концентрата) в год | D42: 65 | E42: 25.35648 | F42: 251.13528 | G42: 442.311 | H42: =E42+F42+G42 -> 718.80276 | I42: 12 | J42: =H42/I42 -> 59.90023 | K42: =H42*30% -> 215.64083 | L42: 11.838 | M42: =K42/L42 -> 18.215985 | N42: =M42/$M$43 -> 0.23322838 | O42: =N42*$O$44 -> 18191814
B43: ИТОГО | D43: =SUM(D40:D42) -> 303 | E43: =SUM(E40:E42) -> 166.66078 | F43: =SUM(F40:F42) -> 1077.4313 | G43: =SUM(G40:G42) -> 1837.8774 | H43: =SUM(H40:H42) -> 3081.9695 | J43: =SUM(J40:J42) -> 254.52137 | K43: =SUM(K40:K42) -> 924.59084 | M43: =SUM(M40:M42) -> 78.103636 | N43: =SUM(N40:N42) -> 1 | O43: =SUM(O40:O42) -> 78000000
N44: Лимит кредита, USD | O44: 78000000
B46: Распределение кредита - пропорционально 30% авансу по EPC-контрактам, с приведением к лимиту 78,0 млн USD.

Sheet ProjCost
B2: ПЕРВОНАЧАЛЬНАЯ СТОИМОСТЬ ПРОЕКТА (в экв. долл. США) | F2: Приложение 1
B3: Инвестиционный период: с начала строительства по 31.12.2027 (1-й год кредита, льготный период).
B4: Наименование затрат | C4: МЕСТНАЯ ВАЛЮТА | D4: ТВЕРДАЯ ВАЛЮТА | E4: ВСЕГО | F4: СТРУКТУРА (%)
B5: ВСЕГО ФИКСИРОВАННЫЕ АКТИВЫ | C5: =SUM(C6:C10) -> 0 | D5: =SUM(D6:D10) -> 1.4161333e+08 | E5: =SUM(E6:E10) -> 1.4161333e+08 | F5: =IFERROR(E5/$E$22,0) -> 0.8259959
B6: Здания, сооружения и передаточные устройства | C6: =0 -> 0 | D6: 28000000 | E6: =C6+D6 -> 28000000 | F6: =IFERROR(E6/$E$22,0) -> 0.16331714
B7: Машины и оборудование | C7: =0 -> 0 | D7: 82470476 | E7: =C7+D7 -> 82470476 | F7: =IFERROR(E7/$E$22,0) -> 0.48103009
B8: Горно-капитальные работы и геологоразведка | C8: =0 -> 0 | D8: 22142857 | E8: =C8+D8 -> 22142857 | F8: =IFERROR(E8/$E$22,0) -> 0.12915386
B9: Транспортные средства | C9: =0 -> 0 | D9: 5000000 | E9: =C9+D9 -> 5000000 | F9: =IFERROR(E9/$E$22,0) -> 0.029163776
B10: Прочие основные средства | C10: =0 -> 0 | D10: 4000000 | E10: =C10+D10 -> 4000000 | F10: =IFERROR(E10/$E$22,0) -> 0.023331021
B11: РАБОЧИЙ КАПИТАЛ (на 31.12.2027), ВКЛЮЧАЯ: | C11: =SUM(C12:C16) -> 17580621 | D11: =SUM(D12:D16) -> 7713573.4 | E11: =SUM(E12:E16) -> 25294194 | F11: =IFERROR(E11/$E$22,0) -> 0.14753484
B12: Запасы сырья, материалов и готовой продукции | C12: 1521163.9 | D12: 0 | E12: =C12+D12 -> 1521163.9 | F12: =IFERROR(E12/$E$22,0) -> 0.0088725766
B13: Дебиторская задолженность покупателей | C13: 0 | D13: 7713573.4 | E13: =C13+D13 -> 7713573.4 | F13: =IFERROR(E13/$E$22,0) -> 0.044991385
B14: НДС к возмещению (в т.ч. по капитальным вложениям) | C14: 16825503 | D14: 0 | E14: =C14+D14 -> 16825503 | F14: =IFERROR(E14/$E$22,0) -> 0.098139038
B15: Кредиторская задолженность поставщикам (уменьшает потребность) | C15: -397060 | D15: 0 | E15: =C15+D15 -> -397060 | F15: =IFERROR(E15/$E$22,0) -> -0.0023159538
B16: Задолженность по оплате труда и налогам с ФОТ (уменьшает потребность) | C16: -368986 | D16: 0 | E16: =C16+D16 -> -368986 | F16: =IFERROR(E16/$E$22,0) -> -0.002152205
B17: ПРОЧИЕ ФИНАНСОВЫЕ ИЗДЕРЖКИ, ВКЛЮЧАЯ: | C17: =SUM(C18:C19) -> 1073730.1 | D17: =SUM(D18:D19) -> 3036468.2 | E17: =SUM(E18:E19) -> 4110198.3 | F17: =IFERROR(E17/$E$22,0) -> 0.02397378
B18: Проценты по кредиту за льготный период (2027 г.) - за счёт собственных средств | C18: 0 | D18: =LOANS!$C$106 -> 3036468.2 | E18: =C18+D18 -> 3036468.2 | F18: =IFERROR(E18/$E$22,0) -> 0.017710976
B19: Расходы подготовительного периода 2026 г. (административные и пусковые расходы) | C19: 1073730.1 | D19: 0 | E19: =C19+D19 -> 1073730.1 | F19: =IFERROR(E19/$E$22,0) -> 0.0062628049
B20: НЕПРЕДВИДЕННЫЕ РАСХОДЫ/РЕЗЕРВ (1% от суммы кредита) | C20: 0 | D20: =ИНФОРМАЦИЯ!$C$26*ИНФОРМАЦИЯ!$C$36 -> 427838.96 | E20: =C20+D20 -> 427838.96 | F20: =IFERROR(E20/$E$22,0) -> 0.0024954799
B22: ВСЕГО ПЕРВОНАЧАЛЬНАЯ СТОИМОСТЬ ПРОЕКТА | C22: =C5+C11+C17+C20 -> 18654351 | D22: =D5+D11+D17+D20 -> 1.5279121e+08 | E22: =E5+E11+E17+E20 -> 1.7144556e+08 | F22: =IFERROR(E22/$E$22,0) -> 1

Sheet FinPlan
B2: ФИНАНСОВЫЙ ПЛАН (в экв. долл. США) | G2: Приложение 2
B4: ПОКАЗАТЕЛИ | C4: МЕСТНАЯ ВАЛЮТА | D4: ТВЁРДАЯ ВАЛЮТА | E4: ВСЕГО | F4: СТРУКТУРА (%) | G4: ДОЛЯ В ФИНАНСИРОВАНИИ
B5: СОБСТВЕННЫЙ КАПИТАЛ
B6: АО «Узбекский комбинат технологических металлов» (АО «Ўзбекистон ТМК», UzTMK)
B7: Фиксированные активы | C7: ='Share of costs'!C6 -> 0 | D7: ='Share of costs'!D6 -> 98829437 | E7: =C7+D7 -> 98829437 | F7: =IFERROR(E7/$E$10,0) -> 0.76813427
B8: Рабочий капитал | C8: ='Share of costs'!C12 -> 17580621 | D8: ='Share of costs'!D12 -> 7713573.4 | E8: =C8+D8 -> 25294194 | F8: =IFERROR(E8/$E$10,0) -> 0.19659464
B9: Денежные средства (финансовые издержки льготного периода, расходы подготовительного периода, резерв) | C9: ='Share of costs'!C13+'Share of costs'!C16 -> 1073730.1 | D9: ='Share of costs'!D13+'Share of costs'!D16 -> 3464307.2 | E9: =C9+D9 -> 4538037.3 | F9: =IFERROR(E9/$E$10,0) -> 0.03527109
B10: ВСЕГО | C10: =SUM(C7:C9) -> 18654351 | D10: =SUM(D7:D9) -> 1.1000732e+08 | E10: =SUM(E7:E9) -> 1.2866167e+08 | F10: =IFERROR(E10/$E$10,0) -> 1 | G10: =IFERROR(E10/$E$15,0) -> 0.75045201
B11: КРЕДИТЫ
B12: Банк (кредит 7% годовых, 84 мес., льготный период 12 мес.) | C12: =C13 -> 0 | D12: =D13 -> 42783896 | E12: =C12+D12 -> 42783896 | F12: =IFERROR(E12/$E$14,0) -> 1
B13: Фиксированные активы (30% аванс по EPC-контракту) | C13: ='Share of costs'!E6 -> 0 | D13: ='Share of costs'!F6 -> 42783896 | E13: =C13+D13 -> 42783896 | F13: =IFERROR(E13/$E$14,0) -> 1
B14: ВСЕГО | C14: =C12 -> 0 | D14: =D12 -> 42783896 | E14: =E12 -> 42783896 | F14: =IFERROR(E14/$E$14,0) -> 1 | G14: =IFERROR(E14/$E$15,0) -> 0.24954799
B15: ВСЕГО ФИНАНСИРОВАНИЯ | C15: =C14+C10 -> 18654351 | D15: =D14+D10 -> 1.5279121e+08 | E15: =E14+E10 -> 1.7144556e+08 | G15: =IFERROR(E15/$E$15,0) -> 1

Sheet Share of costs
B2: ПЕРВОНАЧАЛЬНАЯ СТОИМОСТЬ ПРОЕКТА ПО ИСТОЧНИКАМ ФИНАНСИРОВАНИЯ (в экв. долл. США) | H2: Приложение 3
B4: Наименование затрат | C4: Собственные средства заемщика | E4: Кредит банка | G4: Всего
C5: в местной валюте | D5: в твердой валюте | E5: в местной валюте | F5: в твердой валюте | G5: в местной валюте | H5: в твердой валюте
B6: ВСЕГО ФИКСИРОВАННЫЕ АКТИВЫ | C6: =SUM(C7:C11) -> 0 | D6: =SUM(D7:D11) -> 98829437 | E6: =SUM(E7:E11) -> 0 | F6: =SUM(F7:F11) -> 42783896 | G6: =SUM(G7:G11) -> 0 | H6: =SUM(H7:H11) -> 1.4161333e+08
B7: Здания, сооружения и передаточные устройства | C7: =ProjCost!$C$6 -> 0 | D7: =ProjCost!$D$6-F7 -> 12848992 | E7: 0 | F7: =ИНФОРМАЦИЯ!$C$26*(1-ИНФОРМАЦИЯ!$F$40/ИНФОРМАЦИЯ!$H$40)*ProjCost!$E$6/(ProjCost!$E$6+ProjCost!$E$8+ProjCost!$E$10) -> 15151008 | G7: =C7+E7 -> 0 | H7: =D7+F7 -> 28000000
B8: Машины и оборудование | C8: =ProjCost!$C$7 -> 0 | D8: =ProjCost!$D$7-F8 -> 69754616 | E8: 0 | F8: =ИНФОРМАЦИЯ!$C$26*ИНФОРМАЦИЯ!$F$40/ИНФОРМАЦИЯ!$H$40*ProjCost!$E$7/(ProjCost!$E$7+ProjCost!$E$9) -> 12715860 | G8: =C8+E8 -> 0 | H8: =D8+F8 -> 82470476
B9: Горно-капитальные работы и геологоразведка | C9: =ProjCost!$C$8 -> 0 | D9: =ProjCost!$D$8-F9 -> 10161193 | E9: 0 | F9: =ИНФОРМАЦИЯ!$C$26*(1-ИНФОРМАЦИЯ!$F$40/ИНФОРМАЦИЯ!$H$40)*ProjCost!$E$8/(ProjCost!$E$6+ProjCost!$E$8+ProjCost!$E$10) -> 11981664 | G9: =C9+E9 -> 0 | H9: =D9+F9 -> 22142857
B10: Транспортные средства | C10: =ProjCost!$C$9 -> 0 | D10: =ProjCost!$D$9-F10 -> 4229065.9 | E10: 0 | F10: =ИНФОРМАЦИЯ!$C$26*ИНФОРМАЦИЯ!$F$40/ИНФОРМАЦИЯ!$H$40*ProjCost!$E$9/(ProjCost!$E$7+ProjCost!$E$9) -> 770934.08 | G10: =C10+E10 -> 0 | H10: =D10+F10 -> 5000000
B11: Прочие основные средства | C11: =ProjCost!$C$10 -> 0 | D11: =ProjCost!$D$10-F11 -> 1835570.3 | E11: 0 | F11: =ИНФОРМАЦИЯ!$C$26*(1-ИНФОРМАЦИЯ!$F$40/ИНФОРМАЦИЯ!$H$40)*ProjCost!$E$10/(ProjCost!$E$6+ProjCost!$E$8+ProjCost!$E$10) -> 2164429.7 | G11: =C11+E11 -> 0 | H11: =D11+F11 -> 4000000
B12: РАБОЧИЙ КАПИТАЛ | C12: =ProjCost!$C$11 -> 17580621 | D12: =ProjCost!$D$11 -> 7713573.4 | E12: 0 | F12: 0 | G12: =C12+E12 -> 17580621 | H12: =D12+F12 -> 7713573.4
B13: ПРОЧИЕ ФИНАНСОВЫЕ ИЗДЕРЖКИ | C13: =ProjCost!$C$17 -> 1073730.1 | D13: =ProjCost!$D$17 -> 3036468.2 | E13: 0 | F13: 0 | G13: =C13+E13 -> 1073730.1 | H13: =D13+F13 -> 3036468.2
B14: в т.ч. проценты по кредиту за льготный период | C14: =ProjCost!$C$18 -> 0 | D14: =ProjCost!$D$18 -> 3036468.2 | E14: 0 | F14: 0 | G14: =C14+E14 -> 0 | H14: =D14+F14 -> 3036468.2
B15: в т.ч. расходы подготовительного периода 2026 г. | C15: =ProjCost!$C$19 -> 1073730.1 | D15: =ProjCost!$D$19 -> 0 | E15: 0 | F15: 0 | G15: =C15+E15 -> 1073730.1 | H15: =D15+F15 -> 0
B16: НЕПРЕДВИДЕННЫЕ РАСХОДЫ/РЕЗЕРВ | C16: =ProjCost!$C$20 -> 0 | D16: =ProjCost!$D$20 -> 427838.96 | E16: 0 | F16: 0 | G16: =C16+E16 -> 0 | H16: =D16+F16 -> 427838.96
B18: ВСЕГО ПЕРВОНАЧАЛЬНАЯ СТОИМОСТЬ ПРОЕКТА | C18: =C6+C12+C13+C16 -> 18654351 | D18: =D6+D12+D13+D16 -> 1.1000732e+08 | E18: =E6+E12+E13+E16 -> 0 | F18: =F6+F12+F13+F16 -> 42783896 | G18: =G6+G12+G13+G16 -> 18654351 | H18: =H6+H12+H13+H16 -> 1.5279121e+08
B19: Итого по источнику | C19: =C18+D18 -> 1.2866167e+08 | E19: =E18+F18 -> 42783896 | G19: =G18+H18 -> 1.7144556e+08
B21: Кредит банка направляется на 30% авансовый платёж по EPC-контракту; распределение по группам активов - пропорционально составу EPC-контракта: P (поставка оборудования) - машины и оборудование, E+C (проектирование и строительство) - здания, сооружения и прочие объекты.

Sheet Depreciate
B2: АМОРТИЗАЦИЯ (в долл. США) | N2: Приложение 4
B3: Линейный метод. Проценты льготного периода капитализированы в стоимость основных средств (МСФО IAS 23).
B5: ОБЪЕКТЫ АМОРТИЗАЦИИ | C5: Группа основных средств | D5: Первоначальная стоимость | E5: Срок, лет | F5: Норма, % | G5: 1 год | H5: 2 год | I5: 3 год | J5: 4 год | K5: 5 год | L5: 6 год | M5: 7 год
G6: 2027 | H6: 2028 | I6: 2029 | J6: 2030 | K6: 2031 | L6: 2032 | M6: 2033
B7: Хвостохранилище | C7: Здания, сооружения и передаточные устройства | D7: 10000000 | E7: 9 | F7: =1/E7 -> 0.11111111 | G7: 370370.37 | H7: 1111111.1 | I7: 1111111.1 | J7: 1111111.1 | K7: 1111111.1 | L7: 1111111.1 | M7: 1111111.1
B8: Здания | C8: Здания, сооружения и передаточные устройства | D8: 8000000 | E8: 9 | F8: =1/E8 -> 0.11111111 | G8: 296296.3 | H8: 888888.89 | I8: 888888.89 | J8: 888888.89 | K8: 888888.89 | L8: 888888.89 | M8: 888888.89
B9: Тоннель и автодороги | C9: Здания, сооружения и передаточные устройства | D9: 5000000 | E9: 9 | F9: =1/E9 -> 0.11111111 | G9: 185185.19 | H9: 555555.56 | I9: 555555.56 | J9: 555555.56 | K9: 555555.56 | L9: 555555.56 | M9: 555555.56
B10: Обогатительная фабрика | C10: Машины и оборудование | D10: 82000000 | E10: 9 | F10: =1/E10 -> 0.11111111 | G10: 3037037 | H10: 9111111.1 | I10: 9111111.1 | J10: 9111111.1 | K10: 9111111.1 | L10: 9111111.1 | M10: 9111111.1
B11: Электро- и водоснабжение | C11: Здания, сооружения и передаточные устройства | D11: 5000000 | E11: 9 | F11: =1/E11 -> 0.11111111 | G11: 185185.19 | H11: 555555.56 | I11: 555555.56 | J11: 555555.56 | K11: 555555.56 | L11: 555555.56 | M11: 555555.56
B12: Карьер (открытые горные работы) | C12: Горно-капитальные работы и геологоразведка | D12: 5000000 | E12: 9 | F12: =1/E12 -> 0.11111111 | G12: 185185.19 | H12: 555555.56 | I12: 555555.56 | J12: 555555.56 | K12: 555555.56 | L12: 555555.56 | M12: 555555.56
B13: Подземный рудник | C13: Горно-капитальные работы и геологоразведка | D13: 10000000 | E13: 9 | F13: =1/E13 -> 0.11111111 | G13: 370370.37 | H13: 1111111.1 | I13: 1111111.1 | J13: 1111111.1 | K13: 1111111.1 | L13: 1111111.1 | M13: 1111111.1
B14: Транспортные средства | C14: Транспортные средства | D14: 5000000 | E14: 9 | F14: =1/E14 -> 0.11111111 | G14: 185185.19 | H14: 555555.56 | I14: 555555.56 | J14: 555555.56 | K14: 555555.56 | L14: 555555.56 | M14: 555555.56
B15: Прочие объекты | C15: Прочие основные средства | D15: 4000000 | E15: 9 | F15: =1/E15 -> 0.11111111 | G15: 148148.15 | H15: 444444.44 | I15: 444444.44 | J15: 444444.44 | K15: 444444.44 | L15: 444444.44 | M15: 444444.44
B16: Геологоразведочные и прочие исследования (выполненные) | C16: Горно-капитальные работы и геологоразведка | D16: 7142857.1 | E16: 9 | F16: =1/E16 -> 0.11111111 | G16: 264550.26 | H16: 793650.79 | I16: 793650.79 | J16: 793650.79 | K16: 793650.79 | L16: 793650.79 | M16: 793650.79
B17: Поддерживающие капвложения (% от первоначальной стоимости ОС) | C17: Машины и оборудование | D17: 8939047.6 | E17: 10 | F17: =1/E17 -> 0.1 | G17: 9801.5873 | H17: 188190.48 | I17: 329333.33 | J17: 470476.19 | K17: 611619.05 | L17: 752761.9 | M17: 893904.76
B18: Капитализированные проценты по кредиту за льготный период (2027 г.) | C18: Затраты по займам (МСФО IAS 23) | D18: =LOANS!$C$106 -> 3036468.2 | E18: 20 | F18: =1/E18 -> 0.05 | G18: 50607.803 | H18: =D18/E18 -> 151823.41 | I18: =D18/E18 -> 151823.41 | J18: =D18/E18 -> 151823.41 | K18: =D18/E18 -> 151823.41 | L18: =D18/E18 -> 151823.41 | M18: =D18/E18 -> 151823.41
B19: ВСЕГО | C19: Х | D19: =SUM(D7:D18) -> 1.5311837e+08 | G19: =SUM(G7:G18) -> 5287922.6 | H19: =SUM(H7:H18) -> 16022554 | I19: =SUM(I7:I18) -> 16163696 | J19: =SUM(J7:J18) -> 16304839 | K19: =SUM(K7:K18) -> 16445982 | L19: =SUM(L7:L18) -> 16587125 | M19: =SUM(M7:M18) -> 16728268
B20: в т.ч. в себестоимости продукции | G20: =G19-G21 -> 5287922.6 | H20: =H19-H21 -> 16022554 | I20: =I19-I21 -> 16163696 | J20: =J19-J21 -> 16304839 | K20: =K19-K21 -> 16445982 | L20: =L19-L21 -> 16587125 | M20: =M19-M21 -> 16728268
B21: в т.ч. в административных расходах | G21: 0 | H21: 0 | I21: 0 | J21: 0 | K21: 0 | L21: 0 | M21: 0
B23: Накопленная амортизация | G23: =SUM($G$19:G19) -> 5287922.6 | H23: =SUM($G$19:H19) -> 21310476 | I23: =SUM($G$19:I19) -> 37474173 | J23: =SUM($G$19:J19) -> 53779012 | K23: =SUM($G$19:K19) -> 70224994 | L23: =SUM($G$19:L19) -> 86812119 | M23: =SUM($G$19:M19) -> 1.0354039e+08
B24: Остаточная стоимость основных средств (на конец года) | G24: 1.3936188e+08 | H24: 1.2475075e+08 | I24: 1.0999849e+08 | J24: 95105075 | K24: 80070522 | L24: 64894825 | M24: 49577986

Sheet ProdPlan
B2: ПРОИЗВОДСТВЕННЫЙ ПЛАН | K2: Приложение 5
B4: Н А И М Е Н О В А Н И Е | C4: Ед. изм. | D4: Мощность в год | E4: Рынок сбыта | F4: Цена за единицу, USD (2030 г.) | G4: Выручка при полной мощности: экспорт | H4: Выручка при полной мощности: внутр. рынок
B5: Вольфрамовый концентрат 57,8% WO3 | C5: t | D5: 4200 | E5: внутренний рынок | F5: 38116 | G5: 0 | H5: =D5*F5 -> 160087200
B6: Всего | G6: =SUM(G5:G5) -> 0 | H6: =SUM(H5:H5) -> 160087200
B8: ПОКАЗАТЕЛИ | C8: Ед. изм. | D8: 1 год (льготный / инвест.) | E8: 2 год | F8: 3 год | G8: 4 год | H8: 5 год | I8: 6 год | J8: 7 год
D9: 2027 | E9: 2028 | F9: 2029 | G9: 2030 | H9: 2031 | I9: 2032 | J9: 2033
B10: ОСВОЕНИЕ МОЩНОСТЕЙ
B11: Вольфрамовый концентрат 57,8% WO3 | C11: % | D11: 0.15786295 | E11: 0.55511995 | F11: 0.600342 | G11: 0.76268516 | H11: 0.73323971 | I11: 0.73275148 | J11: 0.73275148
B12: КОЛИЧЕСТВО ПРОИЗВОДСТВА
B13: Вольфрамовый концентрат 57,8% WO3 | C13: t | D13: =$D$5*D11 -> 663.02439 | E13: =$D$5*E11 -> 2331.5038 | F13: =$D$5*F11 -> 2521.4364 | G13: =$D$5*G11 -> 3203.2777 | H13: =$D$5*H11 -> 3079.6068 | I13: =$D$5*I11 -> 3077.5562 | J13: =$D$5*J11 -> 3077.5562
B14: КОЛИЧЕСТВО ДЛЯ РЕАЛИЗАЦИИ
B15: Вольфрамовый концентрат 57,8% WO3 - экспорт | C15: t | D15: 0 | E15: 0 | F15: 0 | G15: 0 | H15: 0 | I15: 0 | J15: 0
B16: Вольфрамовый концентрат 57,8% WO3 - внутренний рынок | C16: t | D16: 663.02439 | E16: 2331.5038 | F16: 2521.4364 | G16: 3203.2777 | H16: 3079.6068 | I16: 3077.5562 | J16: 3077.5562
B17: КОЛИЧЕСТВО ЗАПАСА ГОТОВОЙ ПРОДУКЦИИ НА КОНЕЦ ГОДА
B18: Вольфрамовый концентрат 57,8% WO3 | C18: t | D18: =0+D13-D15-D16 -> 0 | E18: =D18+E13-E15-E16 -> 0 | F18: =E18+F13-F15-F16 -> 0 | G18: =F18+G13-G15-G16 -> 0 | H18: =G18+H13-H15-H16 -> 0 | I18: =H18+I13-I15-I16 -> 0 | J18: =I18+J13-J15-J16 -> 0
B19: ЦЕНА РЕАЛИЗАЦИИ
B20: Вольфрамовый концентрат 57,8% WO3 | C20: USD/t | D20: 35989 | E20: 36493 | F20: 37295 | G20: 38116 | H20: 38954 | I20: 39811 | J20: 40687

Sheet SalePlan
B2: ПЛАН ПРОДАЖ (в экв. долл. США, без НДС) | K2: Приложение 6
B4: ПОКАЗАТЕЛИ | C4: Ед. изм. | D4: 1 год (льготный / инвест.) | E4: 2 год | F4: 3 год | G4: 4 год | H4: 5 год | I4: 6 год | J4: 7 год
D5: 2027 | E5: 2028 | F5: 2029 | G5: 2030 | H5: 2031 | I5: 2032 | J5: 2033
B6: ЭКСПОРТ
B7: Вольфрамовый концентрат 57,8% WO3 | C7: USD | D7: =ProdPlan!D15*ProdPlan!D20 -> 0 | E7: =ProdPlan!E15*ProdPlan!E20 -> 0 | F7: =ProdPlan!F15*ProdPlan!F20 -> 0 | G7: =ProdPlan!G15*ProdPlan!G20 -> 0 | H7: =ProdPlan!H15*ProdPlan!H20 -> 0 | I7: =ProdPlan!I15*ProdPlan!I20 -> 0 | J7: =ProdPlan!J15*ProdPlan!J20 -> 0
B8: Всего | C8: USD | D8: =SUM(D7:D7) -> 0 | E8: =SUM(E7:E7) -> 0 | F8: =SUM(F7:F7) -> 0 | G8: =SUM(G7:G7) -> 0 | H8: =SUM(H7:H7) -> 0 | I8: =SUM(I7:I7) -> 0 | J8: =SUM(J7:J7) -> 0
B10: ВНУТРЕННИЕ ПРОДАЖИ
B11: Вольфрамовый концентрат 57,8% WO3 | C11: USD | D11: =ProdPlan!D16*ProdPlan!D20 -> 23861585 | E11: =ProdPlan!E16*ProdPlan!E20 -> 85083568 | F11: =ProdPlan!F16*ProdPlan!F20 -> 94036971 | G11: =ProdPlan!G16*ProdPlan!G20 -> 1.2209613e+08 | H11: =ProdPlan!H16*ProdPlan!H20 -> 1.19963e+08 | I11: =ProdPlan!I16*ProdPlan!I20 -> 1.2252059e+08 | J11: =ProdPlan!J16*ProdPlan!J20 -> 1.2521653e+08
B12: Всего | C12: USD | D12: =SUM(D11:D11) -> 23861585 | E12: =SUM(E11:E11) -> 85083568 | F12: =SUM(F11:F11) -> 94036971 | G12: =SUM(G11:G11) -> 1.2209613e+08 | H12: =SUM(H11:H11) -> 1.19963e+08 | I12: =SUM(I11:I11) -> 1.2252059e+08 | J12: =SUM(J11:J11) -> 1.2521653e+08
B14: ВСЕГО ПРОДАЖ | C14: USD | D14: =D8+D12 -> 23861585 | E14: =E8+E12 -> 85083568 | F14: =F8+F12 -> 94036971 | G14: =G8+G12 -> 1.2209613e+08 | H14: =H8+H12 -> 1.19963e+08 | I14: =I8+I12 -> 1.2252059e+08 | J14: =J8+J12 -> 1.2521653e+08
B15: Доля экспорта в выручке | C15: % | D15: =IFERROR(D8/D14,0) -> 0 | E15: =IFERROR(E8/E14,0) -> 0 | F15: =IFERROR(F8/F14,0) -> 0 | G15: =IFERROR(G8/G14,0) -> 0 | H15: =IFERROR(H8/H14,0) -> 0 | I15: =IFERROR(I8/I14,0) -> 0 | J15: =IFERROR(J8/J14,0) -> 0

Sheet RawMat
B2: СТОИМОСТЬ СЫРЬЯ И МАТЕРИАЛОВ ПРИ ПРОЕКТНОЙ МОЩНОСТИ (в экв. долл. США, 2030 г.) | G2: Приложение 7
B3: Базовый год - 2030 г. (освоение мощности 76%); цены - в номинальном выражении ТЭО; без НДС.
B5: НАИМЕНОВАНИЕ | C5: Ед. изм. | D5: Цена за единицу, USD | E5: Годовая потребность | F5: Годовая стоимость, USD | G5: ДОЛЯ (%) | H5: Примечание
B6: СЫРЬЁ, МАТЕРИАЛЫ И ПЕРЕМЕННЫЕ ЗАТРАТЫ С ЦЕНОЙ В ТВЁРДОЙ ВАЛЮТЕ (USD)
B7: Добыча (USD 31/т руды, без ФОТ) | C7: t | D7: =IFERROR(F7/E7,0) -> 28.389042 | E7: 600000 | F7: 17033425 | G7: =IFERROR(F7/$F$16,0) -> 0.54006132 | H7: Прочие производственные расходы
B8: Переработка (USD 25/т руды, без ФОТ) | C8: t | D8: =IFERROR(F8/E8,0) -> 23.189764 | E8: 600000 | F8: 13913858 | G8: =IFERROR(F8/$F$16,0) -> 0.44115242 | H8: Прочие производственные расходы
B9: Транспортировка концентрата | C9: t | D9: =IFERROR(F9/E9,0) -> 166.87098 | E9: 3203.2777 | F9: 534534.07 | G9: =IFERROR(F9/$F$16,0) -> 0.016947923 | H9: Прочие производственные расходы
B10: ВСЕГО В ТВЁРДОЙ ВАЛЮТЕ | F10: =SUM(F7:F9) -> 31481818 | G10: =IFERROR(F10/$F$16,0) -> 0.99816167
B12: СЫРЬЁ, МАТЕРИАЛЫ И ПЕРЕМЕННЫЕ ЗАТРАТЫ С ЦЕНОЙ В НАЦИОНАЛЬНОЙ ВАЛЮТЕ (UZS)
B13: Налог за пользование водой | C13: m3 | D13: =IFERROR(F13/E13,0) -> 0.096634468 | E13: 600000 | F13: 57980.681 | G13: =IFERROR(F13/$F$16,0) -> 0.0018383339 | H13: Прочие производственные расходы
B14: ВСЕГО В НАЦИОНАЛЬНОЙ ВАЛЮТЕ | F14: =SUM(F13:F13) -> 57980.681 | G14: =IFERROR(F14/$F$16,0) -> 0.0018383339
B16: ИТОГО СЫРЬЁ, МАТЕРИАЛЫ И ПРОЧИЕ ПЕРЕМЕННЫЕ ЗАТРАТЫ | F16: =F10+F14 -> 31539799 | G16: =IFERROR(F16/$F$16,0) -> 1
B18: ПРОЧИЕ ПРОИЗВОДСТВЕННЫЕ РАСХОДЫ (постоянные)
B19: Статьи затрат | F19: Годовая стоимость, USD | H19: Состав затрат
B20: Ремонт и техническое обслуживание | F20: 0
B21: Прочие производственные расходы (охрана труда, накладные и др.) | F21: 467556.21 | H21: Питание персонала
B22: Налог за пользование недрами (НДПИ) | F22: 3296595.5
B23: Итого: | F23: =SUM(F20:F22) -> 3764151.8

Sheet Labour
B2: ЭНЕРГОРЕСУРСЫ И ОПЛАТА ТРУДА ПРИ ПРОЕКТНОЙ МОЩНОСТИ (в экв. долл. США, 2030 г.) | G2: Приложение 8
B5: СТАТЬИ ЗАТРАТ | C5: Ед. изм. | D5: Годовая потребность | E5: Цена за единицу, USD | F5: Годовая стоимость, USD
B6: Электроэнергия - постоянная часть | F6: 0
B7: Природный газ / топливо - постоянная часть | F7: 0
B8: Вода - постоянная часть | F8: 0
B9: ВСЕГО ЭНЕРГОРЕСУРСЫ | F9: =SUM(F6:F8) -> 0
B11: РАСЧЕТ ЗАРАБОТНОЙ ПЛАТЫ
B12: ПОКАЗАТЕЛИ | C12: Количество, чел. | D12: Среднемесячная з/плата на 1 чел., сум (в ценах 2026 г.) | E12: Среднемесячная з/плата на 1 чел., USD | F12: Годовой фонд з/платы, USD | G12: Отчисления (соц. налог), USD
B13: ПРОИЗВОДСТВЕННЫЙ ПЕРСОНАЛ
B14: Горный отдел - иностранные специалисты | C14: 10 | D14: - | E14: =IFERROR(F14/C14/12,0) -> 5144.687 | F14: 617362.45 | G14: 74083.493
B15: Горный отдел - местный персонал | C15: 31 | D15: - | E15: =IFERROR(F15/C15/12,0) -> 2529.3983 | F15: 940936.18 | G15: 112912.34
B16: Геологический отдел - иностранные специалисты | C16: 8 | D16: - | E16: =IFERROR(F16/C16/12,0) -> 6092.3926 | F16: 584869.68 | G16: 70184.362
B17: Геологический отдел - местный персонал | C17: 32 | D17: - | E17: =IFERROR(F17/C17/12,0) -> 1071.8098 | F17: 411574.96 | G17: 49388.996
B18: Обогатительный отдел (фабрика) - иностранные специалисты | C18: 9 | D18: - | E18: =IFERROR(F18/C18/12,0) -> 4888.957 | F18: 528007.35 | G18: 63360.883
B19: Обогатительный отдел (фабрика) - местный персонал | C19: 47 | D19: - | E19: =IFERROR(F19/C19/12,0) -> 1212.2373 | F19: 683701.83 | G19: 82044.22
B20: Служба технического обслуживания и ремонта - иностранные специалисты | C20: 9 | D20: - | E20: =IFERROR(F20/C20/12,0) -> 4588.0981 | F20: 495514.59 | G20: 59461.751
B21: Служба технического обслуживания и ремонта - местный персонал | C21: 33 | D21: - | E21: =IFERROR(F21/C21/12,0) -> 1517.9699 | F21: 601116.07 | G21: 72133.928
B22: Пробирно-аналитическая лаборатория - иностранные специалисты | C22: 3 | D22: - | E22: =IFERROR(F22/C22/12,0) -> 6994.9692 | F22: 251818.89 | G22: 30218.267
B23: Пробирно-аналитическая лаборатория - местный персонал | C23: 19 | D23: - | E23: =IFERROR(F23/C23/12,0) -> 1466.6871 | F23: 334404.66 | G23: 40128.559
B24: Отдел охраны труда, промбезопасности и экологии - иностранные специалисты | C24: 3 | D24: - | E24: =IFERROR(F24/C24/12,0) -> 6994.9692 | F24: 251818.89 | G24: 30218.267
B25: Отдел охраны труда, промбезопасности и экологии - местный персонал | C25: 17 | D25: - | E25: =IFERROR(F25/C25/12,0) -> 1327.3186 | F25: 270773 | G25: 32492.76
B26: Административный отдел - обслуживание площадки - местный персонал | C26: 56 | D26: - | E26: =IFERROR(F26/C26/12,0) -> 741.40227 | F26: 498222.32 | G26: 59786.679
B27: ВСЕГО | C27: =SUM(C14:C26) -> 277 | F27: =SUM(F14:F26) -> 6470120.9 | G27: =SUM(G14:G26) -> 776414.51
B28: ИТОГО (фонд оплаты труда + социальный налог) | F28: =F27+G27 -> 7246535.4
B30: АДМИНИСТРАЦИЯ
B31: Руководство - местный персонал | C31: 7 | D31: - | E31: =IFERROR(F31/C31/12,0) -> 4529.5723 | F31: 380484.07 | G31: 45658.088
B32: Руководство - иностранные специалисты | C32: 2 | D32: - | E32: =IFERROR(F32/C32/12,0) -> 9477.0551 | F32: 227449.32 | G32: 27293.919
B33: Административный отдел - офис - местный персонал | C33: 20 | D33: - | E33: =IFERROR(F33/C33/12,0) -> 792.57514 | F33: 190218.03 | G33: 22826.164
B34: Отдел кадров - местный персонал | C34: 6 | D34: - | E34: =IFERROR(F34/C34/12,0) -> 2388.0675 | F34: 171940.86 | G34: 20632.903
B35: Отдел закупок - местный персонал | C35: 15 | D35: - | E35: =IFERROR(F35/C35/12,0) -> 1624.638 | F35: 292434.84 | G35: 35092.181
B36: Отдел закупок - иностранные специалисты | C36: 1 | D36: - | E36: =IFERROR(F36/C36/12,0) -> 7446.2576 | F36: 89355.091 | G36: 10722.611
B37: Финансовый отдел - местный персонал | C37: 4 | D37: - | E37: =IFERROR(F37/C37/12,0) -> 3384.6625 | F37: 162463.8 | G37: 19495.656
B38: Юридический отдел - местный персонал | C38: 2 | D38: - | E38: =IFERROR(F38/C38/12,0) -> 3384.6625 | F38: 81231.901 | G38: 9747.8281
B39: Отдел по связям с местным сообществом - местный персонал | C39: 2 | D39: - | E39: =IFERROR(F39/C39/12,0) -> 3102.6073 | F39: 74462.576 | G39: 8935.5091
B40: ВСЕГО | C40: =SUM(C31:C39) -> 59 | F40: =SUM(F31:F39) -> 1670040.5 | G40: =SUM(G31:G39) -> 200404.86
B41: ИТОГО (фонд оплаты труда + социальный налог) | F41: =F40+G40 -> 1870445.4
B43: ОБЩАЯ СУММА | C43: =C27+C40 -> 336 | F43: =F28+F41 -> 9116980.7
B44: Заработная плата установлена в сумах (в ценах 2026 г.) и пересчитана в USD с учётом индексации и курса.

Sheet Taxes
B2: НАЛОГИ И СБОРЫ (в экв. долл. США) | K2: Приложение 9
B4: ПОКАЗАТЕЛИ | C4: Ставка | D4: 1 год (льготный / инвест.) | E4: 2 год | F4: 3 год | G4: 4 год | H4: 5 год | I4: 6 год | J4: 7 год
D5: 2027 | E5: 2028 | F5: 2029 | G5: 2030 | H5: 2031 | I5: 2032 | J5: 2033
B6: Налоги и сборы, включаемые в расходы | D6: =SUM(D7:D11) -> 2530637.3 | E6: =SUM(E7:E11) -> 4646251.3 | F6: =SUM(F7:F11) -> 4967501.3 | G6: =SUM(G7:G11) -> 17195569 | H6: =SUM(H7:H11) -> 24664671 | I6: =SUM(I7:I11) -> 25251269 | J6: =SUM(J7:J11) -> 25884855 | K6: =SUM(K7:K11) -> 0
B7: Налог на имущество | C7: 0.75% | D7: =CostSold!D34 -> 68379.63 | E7: =CostSold!E34 -> 357777.78 | F7: =CostSold!F34 -> 311111.11 | G7: =CostSold!G34 -> 264444.44 | H7: =CostSold!H34 -> 217777.78 | I7: =CostSold!I34 -> 171111.11 | J7: =CostSold!J34 -> 124444.44
B8: Земельный налог | D8: =CostSold!D35 -> 1056000 | E8: =CostSold!E35 -> 1056000 | F8: =CostSold!F35 -> 1161600 | G8: =CostSold!G35 -> 1277760 | H8: =CostSold!H35 -> 1405536 | I8: =CostSold!I35 -> 1546089.6 | J8: =CostSold!J35 -> 1700698.6
B9: Специальный рентный налог | C9: 25% | D9: =CostSold!D36 -> 0 | E9: =CostSold!E36 -> 0 | F9: =CostSold!F36 -> 0 | G9: =CostSold!G36 -> 11379950 | H9: =CostSold!H36 -> 18804047 | I9: =CostSold!I36 -> 19205740 | J9: =CostSold!J36 -> 19636147
B10: Налог за пользование недрами (НДПИ) - в себестоимости | D10: =CostSold!D19 -> 644262.79 | E10: =CostSold!E19 -> 2297256.3 | F10: =CostSold!F19 -> 2538998.2 | G10: =CostSold!G19 -> 3296595.5 | H10: =CostSold!H19 -> 3239001.1 | I10: =CostSold!I19 -> 3308056 | J10: =CostSold!J19 -> 3380846.3
B11: Социальный налог (производственный и административный персонал) | C11: 12% | D11: 761994.9 | E11: 935217.17 | F11: 955791.94 | G11: 976819.37 | H11: 998309.39 | I11: 1020272.2 | J11: 1042718.2
B13: Прочие налоги | D13: =D14+D15 -> 2205838.3 | E13: =E14+E15 -> 23056840 | F13: =F14+F15 -> 25123650 | G13: =G14+G15 -> 31964119 | H13: =H14+H15 -> 29808987 | I13: =I14+I15 -> 30545023 | J13: =J14+J15 -> 31321698 | K13: =K14+K15 -> 0
B14: Налог на прибыль (Приложение 13) | D14: =ProfLoss!D21 -> 2205838.3 | E14: =ProfLoss!E21 -> 14757263 | F14: =ProfLoss!F21 -> 16276351 | G14: =ProfLoss!G21 -> 20554661 | H14: =ProfLoss!H21 -> 18721079 | I14: =ProfLoss!I21 -> 19219212 | J14: =ProfLoss!J21 -> 19742935
B15: НДС к уплате в бюджет (при превышении входящего НДС - к возмещению, см. ниже) | C15: 12% | D15: =MAX(0,D22) -> 0 | E15: =MAX(0,E22) -> 8299577 | F15: =MAX(0,F22) -> 8847299.1 | G15: =MAX(0,G22) -> 11409458 | H15: =MAX(0,H22) -> 11087908 | I15: =MAX(0,I22) -> 11325811 | J15: =MAX(0,J22) -> 11578763
B16: ВСЕГО НАЛОГОВ И ОТЧИСЛЕНИЙ | D16: =D6+D13 -> 4736475.6 | E16: =E6+E13 -> 27703092 | F16: =F6+F13 -> 30091151 | G16: =G6+G13 -> 49159688 | H16: =H6+H13 -> 54473658 | I16: =I6+I13 -> 55796292 | J16: =J6+J13 -> 57206552
B18: Расчет НДС
B19: НДС исходящий (реализация на внутреннем рынке; экспорт - 0%) | D19: 2863390.2 | E19: 10210028 | F19: 11284437 | G19: 14651536 | H19: 14395560 | I19: 14702471 | J19: 15025984
B20: НДС входящий - по операционным затратам | D20: 463843.01 | E20: 1741079.8 | F20: 2267766 | G20: 3072706.1 | H20: 3138280.9 | I20: 3207288.7 | J20: 3277849.1
B21: НДС входящий - по капитальным вложениям (1-й год вкл. 2026 г.) | D21: 16993600 | E21: 169371.43 | F21: 169371.43 | G21: 169371.43 | H21: 169371.43 | I21: 169371.43 | J21: 169371.43
B22: НДС к уплате (+) / к возмещению из бюджета (-) | D22: =D19-D20-D21 -> -14594053 | E22: =E19-E20-E21 -> 8299577 | F22: =F19-F20-F21 -> 8847299.1 | G22: =G19-G20-G21 -> 11409458 | H22: =H19-H20-H21 -> 11087908 | I22: =I19-I20-I21 -> 11325811 | J22: =J19-J20-J21 -> 11578763
B24: Расчет налога на прибыль
B25: Прибыль (убыток) до налогообложения (Приложение 13) | D25: =ProfLoss!D20 -> 5747408.8 | E25: =ProfLoss!E20 -> 34195906 | F25: =ProfLoss!F20 -> 37568832 | G25: =ProfLoss!G20 -> 44923464 | H25: =ProfLoss!H20 -> 34308789 | I25: =ProfLoss!I20 -> 35700268 | J25: =ProfLoss!J20 -> 37157972
B26: Налоговые корректировки (вменённый доход по реализации со скидкой и др.) | D26: 23663768 | E26: 64185850 | F26: 70940171 | G26: 92107608 | H26: 90498405 | I26: 92427814 | J26: 94461593
B27: Налогооблагаемая прибыль | D27: =D25+D26 -> 29411177 | E27: =E25+E26 -> 98381756 | F27: =F25+F26 -> 1.08509e+08 | G27: =G25+G26 -> 1.3703107e+08 | H27: =H25+H26 -> 1.2480719e+08 | I27: =I25+I26 -> 1.2812808e+08 | J27: =J25+J26 -> 1.3161957e+08
B28: Ставка налога на прибыль | C28: % | D28: 0.075 | E28: 0.15 | F28: 0.15 | G28: 0.15 | H28: 0.15 | I28: 0.15 | J28: 0.15
B29: Налог на прибыль | D29: =D27*D28 -> 2205838.3 | E29: =E27*E28 -> 14757263 | F29: =F27*F28 -> 16276351 | G29: =G27*G28 -> 20554661 | H29: =H27*H28 -> 18721079 | I29: =I27*I28 -> 19219212 | J29: =J27*J28 -> 19742935

Sheet CostTotal
B2: СТОИМОСТЬ ПРОДУКЦИИ ПРИ ПРОЕКТНОЙ МОЩНОСТИ (в экв. долл. США, 2030 г.) | H2: Приложение 10
B3: Разделение на постоянные и переменные затраты.
B5: Статьи издержек | C5: Всего стоимость | D5: Доля постоянных затрат (%) | E5: Доля переменных затрат (%) | F5: Фиксированная стоимость | G5: Переменная стоимость
B6: Сырьё, материалы и прочие переменные затраты по статьям ТЭО | C6: =C7+C8 -> 31539799 | D6: =IFERROR(F6/C6,0) -> 0 | E6: =IFERROR(G6/C6,0) -> 1 | F6: =F7+F8 -> 0 | G6: =G7+G8 -> 31539799
B7: с ценой в твёрдой валюте (USD) | C7: =F7+G7 -> 31481818 | D7: =IFERROR(F7/C7,0) -> 0 | E7: =IFERROR(G7/C7,0) -> 1 | F7: 0 | G7: 31481818
B8: с ценой в национальной валюте | C8: =F8+G8 -> 57980.681 | D8: =IFERROR(F8/C8,0) -> 0 | E8: =IFERROR(G8/C8,0) -> 1 | F8: 0 | G8: 57980.681
B9: Энергоресурсы (электроэнергия, газ, вода) | C9: =F9+G9 -> 0 | D9: =IFERROR(F9/C9,0) -> 0 | E9: =IFERROR(G9/C9,0) -> 0 | F9: 0 | G9: =0 -> 0
B10: Зарплата производственного персонала (с соц. налогом) | C10: =F10+G10 -> 7246535.4 | D10: =IFERROR(F10/C10,0) -> 1 | E10: =IFERROR(G10/C10,0) -> 0 | F10: 7246535.4 | G10: 0
B11: Зарплата административного персонала (с соц. налогом) | C11: =F11+G11 -> 1870445.4 | D11: =IFERROR(F11/C11,0) -> 1 | E11: =IFERROR(G11/C11,0) -> 0 | F11: 1870445.4 | G11: 0
B12: Ремонт и техническое обслуживание (постоянная часть) | C12: =F12+G12 -> 0 | D12: =IFERROR(F12/C12,0) -> 0 | E12: =IFERROR(G12/C12,0) -> 0 | F12: 0 | G12: 0
B13: Прочие производственные расходы (постоянная часть) | C13: =F13+G13 -> 467556.21 | D13: =IFERROR(F13/C13,0) -> 1 | E13: =IFERROR(G13/C13,0) -> 0 | F13: 467556.21 | G13: 0
B14: Налог за пользование недрами (НДПИ) | C14: =F14+G14 -> 3296595.5 | D14: =IFERROR(F14/C14,0) -> 0 | E14: =IFERROR(G14/C14,0) -> 1 | F14: 0 | G14: 3296595.5
B15: Административные расходы (без персонала и амортизации) | C15: =F15+G15 -> 0 | D15: =IFERROR(F15/C15,0) -> 0 | E15: =IFERROR(G15/C15,0) -> 0 | F15: 0 | G15: 0
B16: Коммерческие расходы | C16: =F16+G16 -> 0 | D16: =IFERROR(F16/C16,0) -> 0 | E16: =IFERROR(G16/C16,0) -> 0 | F16: 0 | G16: 0
B17: Налог на имущество и земельный налог | C17: =F17+G17 -> 1542204.4 | D17: =IFERROR(F17/C17,0) -> 1 | E17: =IFERROR(G17/C17,0) -> 0 | F17: 1542204.4 | G17: 0
B18: Специальный рентный налог | C18: =F18+G18 -> 11379950 | D18: =IFERROR(F18/C18,0) -> 0 | E18: =IFERROR(G18/C18,0) -> 1 | F18: 0 | G18: 11379950
B19: Резерв на непредвиденные операционные расходы | C19: =F19+G19 -> 2250361.9 | D19: =IFERROR(F19/C19,0) -> 0 | E19: =IFERROR(G19/C19,0) -> 1 | F19: 0 | G19: 2250361.9
B20: Прочие операционные расходы / (доходы) | C20: =F20+G20 -> 0 | D20: =IFERROR(F20/C20,0) -> 0 | E20: =IFERROR(G20/C20,0) -> 0 | F20: 0 | G20: 0
B21: Амортизация (Приложение 4) | C21: =F21+G21 -> 16304839 | D21: =IFERROR(F21/C21,0) -> 1 | E21: =IFERROR(G21/C21,0) -> 0 | F21: =Depreciate!J19 -> 16304839 | G21: 0
B22: ИТОГО | C22: =SUM(C6:C21)-C6 -> 75898286 | D22: =IFERROR(F22/C22,0) -> 0.36142556 | E22: =IFERROR(G22/C22,0) -> 0.63857444 | F22: =SUM(F6:F21)-F6 -> 27431581 | G22: =SUM(G6:G21)-G6 -> 48466706
B23: в т.ч. в местной валюте | C23: =C22-C24 -> 32393405
B24: в т.ч. в твёрдой валюте (производственные затраты в USD) | C24: 43504881
B26: Выручка (2030 г.) | C26: =SalePlan!G14 -> 1.2209613e+08
B27: Затраты на 1 USD выручки | C27: =IFERROR(C22/C26,0) -> 0.62162728
B28: Полная себестоимость единицы основной продукции, USD/t | C28: =IFERROR(C22/ProdPlan!G13,0) -> 23693.946

Sheet CostSold
B2: ГОДОВАЯ СТОИМОСТЬ ПРОДАННОЙ ПРОДУКЦИИ (в экв. долл. США) | K2: Приложение 11
B4: ПОКАЗАТЕЛИ | C4: Ед. изм. | D4: 1 год (льготный / инвест.) | E4: 2 год | F4: 3 год | G4: 4 год | H4: 5 год | I4: 6 год | J4: 7 год
D5: 2027 | E5: 2028 | F5: 2029 | G5: 2030 | H5: 2031 | I5: 2032 | J5: 2033
B6: Освоение мощностей (основная продукция) | C6: % | D6: =ProdPlan!D11 -> 0.15786295 | E6: =ProdPlan!E11 -> 0.55511995 | F6: =ProdPlan!F11 -> 0.600342 | G6: =ProdPlan!G11 -> 0.76268516 | H6: =ProdPlan!H11 -> 0.73323971 | I6: =ProdPlan!I11 -> 0.73275148 | J6: =ProdPlan!J11 -> 0.73275148
B8: ПРОИЗВОДСТВЕННАЯ СЕБЕСТОИМОСТЬ ПО ЭЛЕМЕНТАМ
B9: Сырьё | C9: USD | D9: 0 | E9: 0 | F9: 0 | G9: 0 | H9: 0 | I9: 0 | J9: 0
B10: Вспомогательные материалы | C10: USD | D10: 0 | E10: 0 | F10: 0 | G10: 0 | H10: 0 | I10: 0 | J10: 0
B11: Электроэнергия | C11: USD | D11: 0 | E11: 0 | F11: 0 | G11: 0 | H11: 0 | I11: 0 | J11: 0
B12: Природный газ / топливо | C12: USD | D12: 0 | E12: 0 | F12: 0 | G12: 0 | H12: 0 | I12: 0 | J12: 0
B13: Вода | C13: USD | D13: 0 | E13: 0 | F13: 0 | G13: 0 | H13: 0 | I13: 0 | J13: 0
B14: Заработная плата | C14: USD | D14: 4921963 | E14: 6194562 | F14: 6330842.4 | G14: 6470120.9 | H14: 6612463.5 | I14: 6757937.7 | J14: 6906612.4
B15: Социальный налог | C15: USD | D15: 590635.56 | E15: 743347.44 | F15: 759701.08 | G15: 776414.51 | H15: 793495.63 | I15: 810952.53 | J15: 828793.49
B16: Амортизация (Приложение 4) | C16: USD | D16: =Depreciate!$G$20 -> 5287922.6 | E16: =Depreciate!$H$20 -> 16022554 | F16: =Depreciate!$I$20 -> 16163696 | G16: =Depreciate!$J$20 -> 16304839 | H16: =Depreciate!$K$20 -> 16445982 | I16: =Depreciate!$L$20 -> 16587125 | J16: =Depreciate!$M$20 -> 16728268
B17: Ремонт и техобслуживание | C17: USD | D17: 0 | E17: 0 | F17: 0 | G17: 0 | H17: 0 | I17: 0 | J17: 0
B18: Прочие производственные расходы (без НДПИ) | C18: USD | D18: 4831698 | E18: 18136248 | F18: 23622563 | G18: 32007355 | H18: 32690426 | I18: 33409258 | J18: 34144261
B19: Налог за пользование недрами (НДПИ) | C19: USD | D19: 644262.79 | E19: 2297256.3 | F19: 2538998.2 | G19: 3296595.5 | H19: 3239001.1 | I19: 3308056 | J19: 3380846.3
B20: Себестоимость произведенной продукции | C20: USD | D20: =SUM(D9:D19) -> 16276482 | E20: =SUM(E9:E19) -> 43393967 | F20: =SUM(F9:F19) -> 49415801 | G20: =SUM(G9:G19) -> 58855325 | H20: =SUM(H9:H19) -> 59781368 | I20: =SUM(I9:I19) -> 60873329 | J20: =SUM(J9:J19) -> 61988781
B21: Изменение остатков готовой продукции (- прирост запаса) | C21: USD | D21: -4959831.2 | E21: -1025.6981 | F21: -324589.05 | G21: -516881.18 | H21: -42449.905 | I21: -52772.575 | J21: -54095.411
B22: Себестоимость реализованной продукции | C22: USD | D22: =D20+D21 -> 11316651 | E22: =E20+E21 -> 43392942 | F22: =F20+F21 -> 49091212 | G22: =G20+G21 -> 58338444 | H22: =H20+H21 -> 59738918 | I22: =I20+I21 -> 60820556 | J22: =J20+J21 -> 61934686
B23: в т.ч. затраты в твёрдой валюте (USD) | C23: USD | D23: 11316651 | E23: 43392942 | F23: 49091212 | G23: 58338444 | H23: 59738918 | I23: 60820556 | J23: 61934686
B24: в т.ч. затраты в национальной валюте | C24: USD | D24: =D22-D23 -> -4.0978193e-08 | E24: =E22-E23 -> 0 | F24: =F22-F23 -> 0 | G24: =G22-G23 -> 0 | H24: =H22-H23 -> 0 | I24: =I22-I23 -> 0 | J24: =J22-J23 -> 0
B26: РАСХОДЫ ПЕРИОДА
B27: Зарплата административного персонала (с соц. налогом) | C27: USD | D27: 1599353.8 | E27: 1790784.1 | F27: 1830181.4 | G27: 1870445.4 | H27: 1911595.2 | I27: 1953650.2 | J27: 1996630.5
B28: Амортизация административных активов | C28: USD | D28: =Depreciate!$G$21 -> 0 | E28: =Depreciate!$H$21 -> 0 | F28: =Depreciate!$I$21 -> 0 | G28: =Depreciate!$J$21 -> 0 | H28: =Depreciate!$K$21 -> 0 | I28: =Depreciate!$L$21 -> 0 | J28: =Depreciate!$M$21 -> 0
B29: Прочие административные расходы (аренда, налог за воду, прочие) | C29: USD | D29: 0 | E29: 0 | F29: 0 | G29: 0 | H29: 0 | I29: 0 | J29: 0
B30: Коммерческие расходы (расходы по реализации) | C30: USD | D30: 0 | E30: 0 | F30: 0 | G30: 0 | H30: 0 | I30: 0 | J30: 0
B31: Итого расходы периода | C31: USD | D31: =SUM(D27:D30) -> 1599353.8 | E31: =SUM(E27:E30) -> 1790784.1 | F31: =SUM(F27:F30) -> 1830181.4 | G31: =SUM(G27:G30) -> 1870445.4 | H31: =SUM(H27:H30) -> 1911595.2 | I31: =SUM(I27:I30) -> 1953650.2 | J31: =SUM(J27:J30) -> 1996630.5
B33: НАЛОГИ И ПРОЧИЕ ОПЕРАЦИОННЫЕ РАСХОДЫ
B34: Налог на имущество | C34: USD | D34: 68379.63 | E34: 357777.78 | F34: 311111.11 | G34: 264444.44 | H34: 217777.78 | I34: 171111.11 | J34: 124444.44
B35: Земельный налог | C35: USD | D35: 1056000 | E35: 1056000 | F35: 1161600 | G35: 1277760 | H35: 1405536 | I35: 1546089.6 | J35: 1700698.6
B36: Специальный рентный налог | C36: USD | D36: 0 | E36: 0 | F36: 0 | G36: 11379950 | H36: 18804047 | I36: 19205740 | J36: 19636147
B37: Резерв на непредвиденные операционные расходы | C37: USD | D37: 635124.7 | E37: 1478537.2 | F37: 1776694.6 | G37: 2250361.9 | H37: 2291154.9 | I37: 2341412.6 | J37: 2392923.7
B38: Прочие операционные расходы / (доходы) | C38: USD | D38: 3438667.3 | E38: 0 | F38: 0 | G38: 0 | H38: 0 | I38: 0 | J38: 0
B39: Итого налоги и прочие операционные расходы | C39: USD | D39: =SUM(D34:D38) -> 5198171.6 | E39: =SUM(E34:E38) -> 2892315 | F39: =SUM(F34:F38) -> 3249405.7 | G39: =SUM(G34:G38) -> 15172516 | H39: =SUM(H34:H38) -> 22718516 | I39: =SUM(I34:I38) -> 23264353 | J39: =SUM(J34:J38) -> 23854214
B41: ФИНАНСОВЫЕ ИЗДЕРЖКИ
B42: Проценты за кредит (1-й год - капитализированы, оплачены за счёт собственных средств) | C42: USD | D42: =0 -> 0 | E42: =LOANS!$D$106 -> 2811621.7 | F42: =LOANS!$E$106 -> 2297340.1 | G42: =LOANS!$F$106 -> 1791262 | H42: =LOANS!$G$106 -> 1285184 | I42: =LOANS!$H$106 -> 781763.46 | J42: =LOANS!$I$106 -> 273027.94
B44: ПОЛНАЯ СТОИМОСТЬ ПРОДАННОЙ ПРОДУКЦИИ | C44: USD | D44: =D22+D31+D39+D42 -> 18114176 | E44: =E22+E31+E39+E42 -> 50887662 | F44: =F22+F31+F39+F42 -> 56468139 | G44: =G22+G31+G39+G42 -> 77172667 | H44: =H22+H31+H39+H42 -> 85654213 | I44: =I22+I31+I39+I42 -> 86820323 | J44: =J22+J31+J39+J42 -> 88058558
B45: Полная себестоимость единицы основной продукции | C45: USD/t | D45: =IFERROR(D44/(ProdPlan!D15+ProdPlan!D16),0) -> 27320.527 | E45: =IFERROR(E44/(ProdPlan!E15+ProdPlan!E16),0) -> 21826.112 | F45: =IFERROR(F44/(ProdPlan!F15+ProdPlan!F16),0) -> 22395.226 | G45: =IFERROR(G44/(ProdPlan!G15+ProdPlan!G16),0) -> 24091.782 | H45: =IFERROR(H44/(ProdPlan!H15+ProdPlan!H16),0) -> 27813.36 | I45: =IFERROR(I44/(ProdPlan!I15+ProdPlan!I16),0) -> 28210.8 | J45: =IFERROR(J44/(ProdPlan!J15+ProdPlan!J16),0) -> 28613.144

Sheet LOANS
B2: СХЕМА ВЫПЛАТЫ КРЕДИТА (в долл. США) | H2: Приложение 12
B5: Срок кредита | C5: =ИНФОРМАЦИЯ!$C$28 -> 84 | D5: месяцев
B6: Льготный период | C6: =ИНФОРМАЦИЯ!$C$29 -> 12 | D6: месяцев
B7: Инвестиционный период | C7: =ИНФОРМАЦИЯ!$C$30 -> 12 | D7: месяцев
B8: Процентная ставка | C8: =ИНФОРМАЦИЯ!$C$27 -> 0.07 | D8: годовых
B9: Сумма кредита | C9: =ИНФОРМАЦИЯ!$C$26 -> 42783896 | D9: USD
B10: Дата выдачи | C10: =ИНФОРМАЦИЯ!$C$31 -> 46388
B11: База начисления процентов | C11: =ИНФОРМАЦИЯ!$C$32 -> 360 | D11: дней
B12: Количество платежей по основному долгу | C12: =C5-C6 -> 72 | D12: платежей
B13: Ежемесячный платёж по основному долгу | C13: =C9/C12 -> 594220.78 | D13: USD
A15: № | B15: Дата платежа | C15: Остаток на начало | D15: Погашение основного долга | E15: Проценты | F15: Всего выплат | G15: Остаток на конец | H15: Год | I15: № года
A16: 1 | B16: =EOMONTH($C$10,0) -> 46418 | C16: =$C$9 -> 42783896 | D16: =IF(A16>$C$6,MIN(C16,$C$13),0) -> 0 | E16: =C16*$C$8*DAY(B16)/$C$11 -> 257891.82 | F16: =D16+E16 -> 257891.82 | G16: =C16-D16 -> 42783896 | H16: =YEAR(B16) -> 2027 | I16: =H16-2026 -> 1
A17: 2 | B17: =EOMONTH($C$10,1) -> 46446 | C17: =G16 -> 42783896 | D17: =IF(A17>$C$6,MIN(C17,$C$13),0) -> 0 | E17: =C17*$C$8*DAY(B17)/$C$11 -> 232934.55 | F17: =D17+E17 -> 232934.55 | G17: =C17-D17 -> 42783896 | H17: =YEAR(B17) -> 2027 | I17: =H17-2026 -> 1
A18: 3 | B18: =EOMONTH($C$10,2) -> 46477 | C18: =G17 -> 42783896 | D18: =IF(A18>$C$6,MIN(C18,$C$13),0) -> 0 | E18: =C18*$C$8*DAY(B18)/$C$11 -> 257891.82 | F18: =D18+E18 -> 257891.82 | G18: =C18-D18 -> 42783896 | H18: =YEAR(B18) -> 2027 | I18: =H18-2026 -> 1
A19: 4 | B19: =EOMONTH($C$10,3) -> 46507 | C19: =G18 -> 42783896 | D19: =IF(A19>$C$6,MIN(C19,$C$13),0) -> 0 | E19: =C19*$C$8*DAY(B19)/$C$11 -> 249572.73 | F19: =D19+E19 -> 249572.73 | G19: =C19-D19 -> 42783896 | H19: =YEAR(B19) -> 2027 | I19: =H19-2026 -> 1
A20: 5 | B20: =EOMONTH($C$10,4) -> 46538 | C20: =G19 -> 42783896 | D20: =IF(A20>$C$6,MIN(C20,$C$13),0) -> 0 | E20: =C20*$C$8*DAY(B20)/$C$11 -> 257891.82 | F20: =D20+E20 -> 257891.82 | G20: =C20-D20 -> 42783896 | H20: =YEAR(B20) -> 2027 | I20: =H20-2026 -> 1
A21: 6 | B21: =EOMONTH($C$10,5) -> 46568 | C21: =G20 -> 42783896 | D21: =IF(A21>$C$6,MIN(C21,$C$13),0) -> 0 | E21: =C21*$C$8*DAY(B21)/$C$11 -> 249572.73 | F21: =D21+E21 -> 249572.73 | G21: =C21-D21 -> 42783896 | H21: =YEAR(B21) -> 2027 | I21: =H21-2026 -> 1
A22: 7 | B22: =EOMONTH($C$10,6) -> 46599 | C22: =G21 -> 42783896 | D22: =IF(A22>$C$6,MIN(C22,$C$13),0) -> 0 | E22: =C22*$C$8*DAY(B22)/$C$11 -> 257891.82 | F22: =D22+E22 -> 257891.82 | G22: =C22-D22 -> 42783896 | H22: =YEAR(B22) -> 2027 | I22: =H22-2026 -> 1
A23: 8 | B23: =EOMONTH($C$10,7) -> 46630 | C23: =G22 -> 42783896 | D23: =IF(A23>$C$6,MIN(C23,$C$13),0) -> 0 | E23: =C23*$C$8*DAY(B23)/$C$11 -> 257891.82 | F23: =D23+E23 -> 257891.82 | G23: =C23-D23 -> 42783896 | H23: =YEAR(B23) -> 2027 | I23: =H23-2026 -> 1
A24: 9 | B24: =EOMONTH($C$10,8) -> 46660 | C24: =G23 -> 42783896 | D24: =IF(A24>$C$6,MIN(C24,$C$13),0) -> 0 | E24: =C24*$C$8*DAY(B24)/$C$11 -> 249572.73 | F24: =D24+E24 -> 249572.73 | G24: =C24-D24 -> 42783896 | H24: =YEAR(B24) -> 2027 | I24: =H24-2026 -> 1
A25: 10 | B25: =EOMONTH($C$10,9) -> 46691 | C25: =G24 -> 42783896 | D25: =IF(A25>$C$6,MIN(C25,$C$13),0) -> 0 | E25: =C25*$C$8*DAY(B25)/$C$11 -> 257891.82 | F25: =D25+E25 -> 257891.82 | G25: =C25-D25 -> 42783896 | H25: =YEAR(B25) -> 2027 | I25: =H25-2026 -> 1
A26: 11 | B26: =EOMONTH($C$10,10) -> 46721 | C26: =G25 -> 42783896 | D26: =IF(A26>$C$6,MIN(C26,$C$13),0) -> 0 | E26: =C26*$C$8*DAY(B26)/$C$11 -> 249572.73 | F26: =D26+E26 -> 249572.73 | G26: =C26-D26 -> 42783896 | H26: =YEAR(B26) -> 2027 | I26: =H26-2026 -> 1
A27: 12 | B27: =EOMONTH($C$10,11) -> 46752 | C27: =G26 -> 42783896 | D27: =IF(A27>$C$6,MIN(C27,$C$13),0) -> 0 | E27: =C27*$C$8*DAY(B27)/$C$11 -> 257891.82 | F27: =D27+E27 -> 257891.82 | G27: =C27-D27 -> 42783896 | H27: =YEAR(B27) -> 2027 | I27: =H27-2026 -> 1
A28: 13 | B28: =EOMONTH($C$10,12) -> 46783 | C28: =G27 -> 42783896 | D28: =IF(A28>$C$6,MIN(C28,$C$13),0) -> 594220.78 | E28: =C28*$C$8*DAY(B28)/$C$11 -> 257891.82 | F28: =D28+E28 -> 852112.6 | G28: =C28-D28 -> 42189676 | H28: =YEAR(B28) -> 2028 | I28: =H28-2026 -> 2
A29: 14 | B29: =EOMONTH($C$10,13) -> 46812 | C29: =G28 -> 42189676 | D29: =IF(A29>$C$6,MIN(C29,$C$13),0) -> 594220.78 | E29: =C29*$C$8*DAY(B29)/$C$11 -> 237902.89 | F29: =D29+E29 -> 832123.68 | G29: =C29-D29 -> 41595455 | H29: =YEAR(B29) -> 2028 | I29: =H29-2026 -> 2
A30: 15 | B30: =EOMONTH($C$10,14) -> 46843 | C30: =G29 -> 41595455 | D30: =IF(A30>$C$6,MIN(C30,$C$13),0) -> 594220.78 | E30: =C30*$C$8*DAY(B30)/$C$11 -> 250728.16 | F30: =D30+E30 -> 844948.94 | G30: =C30-D30 -> 41001234 | H30: =YEAR(B30) -> 2028 | I30: =H30-2026 -> 2
A31: 16 | B31: =EOMONTH($C$10,15) -> 46873 | C31: =G30 -> 41001234 | D31: =IF(A31>$C$6,MIN(C31,$C$13),0) -> 594220.78 | E31: =C31*$C$8*DAY(B31)/$C$11 -> 239173.86 | F31: =D31+E31 -> 833394.65 | G31: =C31-D31 -> 40407013 | H31: =YEAR(B31) -> 2028 | I31: =H31-2026 -> 2
A32: 17 | B32: =EOMONTH($C$10,16) -> 46904 | C32: =G31 -> 40407013 | D32: =IF(A32>$C$6,MIN(C32,$C$13),0) -> 594220.78 | E32: =C32*$C$8*DAY(B32)/$C$11 -> 243564.5 | F32: =D32+E32 -> 837785.28 | G32: =C32-D32 -> 39812792 | H32: =YEAR(B32) -> 2028 | I32: =H32-2026 -> 2
A33: 18 | B33: =EOMONTH($C$10,17) -> 46934 | C33: =G32 -> 39812792 | D33: =IF(A33>$C$6,MIN(C33,$C$13),0) -> 594220.78 | E33: =C33*$C$8*DAY(B33)/$C$11 -> 232241.29 | F33: =D33+E33 -> 826462.07 | G33: =C33-D33 -> 39218572 | H33: =YEAR(B33) -> 2028 | I33: =H33-2026 -> 2
A34: 19 | B34: =EOMONTH($C$10,18) -> 46965 | C34: =G33 -> 39218572 | D34: =IF(A34>$C$6,MIN(C34,$C$13),0) -> 594220.78 | E34: =C34*$C$8*DAY(B34)/$C$11 -> 236400.83 | F34: =D34+E34 -> 830621.62 | G34: =C34-D34 -> 38624351 | H34: =YEAR(B34) -> 2028 | I34: =H34-2026 -> 2
A35: 20 | B35: =EOMONTH($C$10,19) -> 46996 | C35: =G34 -> 38624351 | D35: =IF(A35>$C$6,MIN(C35,$C$13),0) -> 594220.78 | E35: =C35*$C$8*DAY(B35)/$C$11 -> 232819 | F35: =D35+E35 -> 827039.79 | G35: =C35-D35 -> 38030130 | H35: =YEAR(B35) -> 2028 | I35: =H35-2026 -> 2
A36: 21 | B36: =EOMONTH($C$10,20) -> 47026 | C36: =G35 -> 38030130 | D36: =IF(A36>$C$6,MIN(C36,$C$13),0) -> 594220.78 | E36: =C36*$C$8*DAY(B36)/$C$11 -> 221842.43 | F36: =D36+E36 -> 816063.21 | G36: =C36-D36 -> 37435909 | H36: =YEAR(B36) -> 2028 | I36: =H36-2026 -> 2
A37: 22 | B37: =EOMONTH($C$10,21) -> 47057 | C37: =G36 -> 37435909 | D37: =IF(A37>$C$6,MIN(C37,$C$13),0) -> 594220.78 | E37: =C37*$C$8*DAY(B37)/$C$11 -> 225655.34 | F37: =D37+E37 -> 819876.12 | G37: =C37-D37 -> 36841689 | H37: =YEAR(B37) -> 2028 | I37: =H37-2026 -> 2
A38: 23 | B38: =EOMONTH($C$10,22) -> 47087 | C38: =G37 -> 36841689 | D38: =IF(A38>$C$6,MIN(C38,$C$13),0) -> 594220.78 | E38: =C38*$C$8*DAY(B38)/$C$11 -> 214909.85 | F38: =D38+E38 -> 809130.63 | G38: =C38-D38 -> 36247468 | H38: =YEAR(B38) -> 2028 | I38: =H38-2026 -> 2
A39: 24 | B39: =EOMONTH($C$10,23) -> 47118 | C39: =G38 -> 36247468 | D39: =IF(A39>$C$6,MIN(C39,$C$13),0) -> 594220.78 | E39: =C39*$C$8*DAY(B39)/$C$11 -> 218491.68 | F39: =D39+E39 -> 812712.46 | G39: =C39-D39 -> 35653247 | H39: =YEAR(B39) -> 2028 | I39: =H39-2026 -> 2
A40: 25 | B40: =EOMONTH($C$10,24) -> 47149 | C40: =G39 -> 35653247 | D40: =IF(A40>$C$6,MIN(C40,$C$13),0) -> 594220.78 | E40: =C40*$C$8*DAY(B40)/$C$11 -> 214909.85 | F40: =D40+E40 -> 809130.63 | G40: =C40-D40 -> 35059026 | H40: =YEAR(B40) -> 2029 | I40: =H40-2026 -> 3
A41: 26 | B41: =EOMONTH($C$10,25) -> 47177 | C41: =G40 -> 35059026 | D41: =IF(A41>$C$6,MIN(C41,$C$13),0) -> 594220.78 | E41: =C41*$C$8*DAY(B41)/$C$11 -> 190876.92 | F41: =D41+E41 -> 785097.7 | G41: =C41-D41 -> 34464805 | H41: =YEAR(B41) -> 2029 | I41: =H41-2026 -> 3
A42: 27 | B42: =EOMONTH($C$10,26) -> 47208 | C42: =G41 -> 34464805 | D42: =IF(A42>$C$6,MIN(C42,$C$13),0) -> 594220.78 | E42: =C42*$C$8*DAY(B42)/$C$11 -> 207746.19 | F42: =D42+E42 -> 801966.97 | G42: =C42-D42 -> 33870585 | H42: =YEAR(B42) -> 2029 | I42: =H42-2026 -> 3
A43: 28 | B43: =EOMONTH($C$10,27) -> 47238 | C43: =G42 -> 33870585 | D43: =IF(A43>$C$6,MIN(C43,$C$13),0) -> 594220.78 | E43: =C43*$C$8*DAY(B43)/$C$11 -> 197578.41 | F43: =D43+E43 -> 791799.19 | G43: =C43-D43 -> 33276364 | H43: =YEAR(B43) -> 2029 | I43: =H43-2026 -> 3
A44: 29 | B44: =EOMONTH($C$10,28) -> 47269 | C44: =G43 -> 33276364 | D44: =IF(A44>$C$6,MIN(C44,$C$13),0) -> 594220.78 | E44: =C44*$C$8*DAY(B44)/$C$11 -> 200582.53 | F44: =D44+E44 -> 794803.31 | G44: =C44-D44 -> 32682143 | H44: =YEAR(B44) -> 2029 | I44: =H44-2026 -> 3
...

Sheet ProfLoss
B2: ПРЕДПОЛАГАЕМЫЕ СЧЕТА ПРИБЫЛЕЙ И УБЫТКОВ (в экв. долл. США) | K2: Приложение 13
B4: ПОКАЗАТЕЛИ | C4: Ед. изм. | D4: 1 год (льготный / инвест.) | E4: 2 год | F4: 3 год | G4: 4 год | H4: 5 год | I4: 6 год | J4: 7 год
D5: 2027 | E5: 2028 | F5: 2029 | G5: 2030 | H5: 2031 | I5: 2032 | J5: 2033
B6: Выручка от реализации продукции (с НДС) | C6: USD | D6: =D7+D8 -> 26724975 | E6: =E7+E8 -> 95293597 | F6: =F7+F8 -> 1.0532141e+08 | G6: =G7+G8 -> 1.3674767e+08 | H6: =H7+H8 -> 1.3435856e+08 | I6: =I7+I8 -> 1.3722306e+08 | J6: =J7+J8 -> 1.4024251e+08
B7: экспорт (в твёрдой валюте) | C7: USD | D7: =SalePlan!D8 -> 0 | E7: =SalePlan!E8 -> 0 | F7: =SalePlan!F8 -> 0 | G7: =SalePlan!G8 -> 0 | H7: =SalePlan!H8 -> 0 | I7: =SalePlan!I8 -> 0 | J7: =SalePlan!J8 -> 0
B8: внутренний рынок (с НДС) | C8: USD | D8: =SalePlan!D12+Taxes!D19 -> 26724975 | E8: =SalePlan!E12+Taxes!E19 -> 95293597 | F8: =SalePlan!F12+Taxes!F19 -> 1.0532141e+08 | G8: =SalePlan!G12+Taxes!G19 -> 1.3674767e+08 | H8: =SalePlan!H12+Taxes!H19 -> 1.3435856e+08 | I8: =SalePlan!I12+Taxes!I19 -> 1.3722306e+08 | J8: =SalePlan!J12+Taxes!J19 -> 1.4024251e+08
B9: НДС, начисленный с реализации | C9: USD | D9: =Taxes!D19 -> 2863390.2 | E9: =Taxes!E19 -> 10210028 | F9: =Taxes!F19 -> 11284437 | G9: =Taxes!G19 -> 14651536 | H9: =Taxes!H19 -> 14395560 | I9: =Taxes!I19 -> 14702471 | J9: =Taxes!J19 -> 15025984
B10: Чистая выручка от реализации продукции | C10: USD | D10: =D6-D9 -> 23861585 | E10: =E6-E9 -> 85083568 | F10: =F6-F9 -> 94036971 | G10: =G6-G9 -> 1.2209613e+08 | H10: =H6-H9 -> 1.19963e+08 | I10: =I6-I9 -> 1.2252059e+08 | J10: =J6-J9 -> 1.2521653e+08
B11: Себестоимость реализованной продукции | C11: USD | D11: =CostSold!D22 -> 11316651 | E11: =CostSold!E22 -> 43392942 | F11: =CostSold!F22 -> 49091212 | G11: =CostSold!G22 -> 58338444 | H11: =CostSold!H22 -> 59738918 | I11: =CostSold!I22 -> 60820556 | J11: =CostSold!J22 -> 61934686
B12: в твёрдой валюте | C12: USD | D12: =CostSold!D23 -> 11316651 | E12: =CostSold!E23 -> 43392942 | F12: =CostSold!F23 -> 49091212 | G12: =CostSold!G23 -> 58338444 | H12: =CostSold!H23 -> 59738918 | I12: =CostSold!I23 -> 60820556 | J12: =CostSold!J23 -> 61934686
B13: в местной валюте | C13: USD | D13: =CostSold!D24 -> -4.0978193e-08 | E13: =CostSold!E24 -> 0 | F13: =CostSold!F24 -> 0 | G13: =CostSold!G24 -> 0 | H13: =CostSold!H24 -> 0 | I13: =CostSold!I24 -> 0 | J13: =CostSold!J24 -> 0
B14: Валовая прибыль (убыток) | C14: USD | D14: =D10-D11 -> 12544934 | E14: =E10-E11 -> 41690627 | F14: =F10-F11 -> 44945759 | G14: =G10-G11 -> 63757687 | H14: =H10-H11 -> 60224084 | I14: =I10-I11 -> 61700035 | J14: =J10-J11 -> 63281844
B15: Расходы периода (административные и коммерческие) | C15: USD | D15: =CostSold!D31 -> 1599353.8 | E15: =CostSold!E31 -> 1790784.1 | F15: =CostSold!F31 -> 1830181.4 | G15: =CostSold!G31 -> 1870445.4 | H15: =CostSold!H31 -> 1911595.2 | I15: =CostSold!I31 -> 1953650.2 | J15: =CostSold!J31 -> 1996630.5
B16: Налоги и прочие операционные расходы | C16: USD | D16: =CostSold!D39 -> 5198171.6 | E16: =CostSold!E39 -> 2892315 | F16: =CostSold!F39 -> 3249405.7 | G16: =CostSold!G39 -> 15172516 | H16: =CostSold!H39 -> 22718516 | I16: =CostSold!I39 -> 23264353 | J16: =CostSold!J39 -> 23854214
B17: Прибыль (убыток) от основной деятельности (EBIT) | C17: USD | D17: =D14-D15-D16 -> 5747408.8 | E17: =E14-E15-E16 -> 37007528 | F17: =F14-F15-F16 -> 39866172 | G17: =G14-G15-G16 -> 46714726 | H17: =H14-H15-H16 -> 35593973 | I17: =I14-I15-I16 -> 36482032 | J17: =J14-J15-J16 -> 37431000
