Workbook

Sheet Резюме
B2: БИЗНЕС-ПЛАН ИНВЕСТИЦИОННОГО ПРОЕКТА
B3: Строительство нового гидрометаллургического завода по переработке вольфрамового концентрата (1-я очередь)
B4: (Цех по переработке вольфрамового концентрата)
B6: 1. ОБЩИЕ СВЕДЕНИЯ
B7: Суть проекта | C7: Строительство нового гидрометаллургического завода по переработке вольфрамового концентрата (1-я очередь). Переработка 5 000 т вольфрамового концентрата в год; выпуск основной продукции - Триоксид вольфрама WO3 2 656.5 t/год при проектной мощности; реализация - экспорт.
B8: Заемщик | C8: АО «Узбекский комбинат технологических металлов» (АО «Ўзбекистон ТМК», UzTMK)
B9: Местоположение | C9: Самаркандская обл., Нурабадский р-н, 9,6 га
B10: Продукция | C10: Триоксид вольфрама WO3
B11: Производственная мощность | C11: Переработка 5 000 т вольфрамового концентрата в год; выпуск основной продукции - 2 656 t/год
B12: Рынок сбыта | C12: экспорт (100% выручки в USD)
B13: Сроки | C13: начало строительства - 01.10.2026; начало производства - 01.10.2027; выход на проектную мощность - 3-й год
B14: Стадия проработки | C14: ТЭО
B16: 2. ПАРАМЕТРЫ КРЕДИТА
B17: Кредитор | C17: Национальный банк внешнеэкономической деятельности Республики Узбекистан
B18: Сумма кредита, USD | C18: =ИНФОРМАЦИЯ!$C$26 -> 17024290
B19: Процентная ставка | C19: =ИНФОРМАЦИЯ!$C$27 -> 0.07
B20: Срок кредита | C20: 84 месяца (7 лет): льготный (инвестиционный) период - 12 месяцев (1-й год), погашение - 72 месяца (2-7 годы)
B21: Порядок погашения | C21: основной долг - ежемесячно равными долями; проценты - ежемесячно на остаток задолженности
B22: Проценты льготного периода | C22: =TEXT(LOANS!$C$106,"#,##0") & " USD - уплачиваются за счёт собственных средств заемщика (включены в стоимость проекта)" -> 1,208,252 USD - уплачиваются за счёт собственных средств заемщика (включены в стоимость проекта)
B23: Целевое назначение | C23: 30% авансовый платёж по EPC-контракту (E - проектирование, P - поставка оборудования, C - строительство)
B25: 3. СТОИМОСТЬ ПРОЕКТА И ИСТОЧНИКИ ФИНАНСИРОВАНИЯ
B26: Статья | C26: USD | D26: Доля
B27: Фиксированные активы | C27: =ProjCost!E5 -> 47761338 | D27: =IFERROR(C27/ProjCost!$E$16,0) -> 0.61136616
B28: Рабочий капитал | C28: =ProjCost!E10 -> 28280512 | D28: =IFERROR(C28/ProjCost!$E$16,0) -> 0.36200301
B29: Проценты льготного периода и расходы подготовительного периода | C29: =ProjCost!E11 -> 1910218.9 | D29: =IFERROR(C29/ProjCost!$E$16,0) -> 0.024451643
B30: Резерв | C30: =ProjCost!E14 -> 170242.9 | D30: =IFERROR(C30/ProjCost!$E$16,0) -> 0.0021791841
B31: ВСЕГО СТОИМОСТЬ ПРОЕКТА | C31: =ProjCost!E16 -> 78122312 | D31: =IFERROR(C31/ProjCost!$E$16,0) -> 1
B32: Собственные средства заемщика | C32: =FinPlan!$E$10 -> 61098022 | D32: =IFERROR(C32/ProjCost!$E$16,0) -> 0.78208159
B33: Кредит НБУ | C33: =FinPlan!$E$14 -> 17024290 | D33: =IFERROR(C33/ProjCost!$E$16,0) -> 0.21791841
B35: 4. ОСНОВНЫЕ ФИНАНСОВЫЕ ПОКАЗАТЕЛИ ПО ГОДАМ
B36: ПОКАЗАТЕЛИ | C36: Ед. изм. | D36: 1 год (льготный период) | E36: 2 год | F36: 3 год | G36: 4 год | H36: 5 год | I36: 6 год | J36: 7 год
B38: Выручка (без НДС) | C38: USD | D38: =ProfLoss!D10 -> 28331250 | E38: =ProfLoss!E10 -> 2.4740556e+08 | F38: =ProfLoss!F10 -> 3.079196e+08 | G38: =ProfLoss!G10 -> 3.186764e+08 | H38: =ProfLoss!H10 -> 325686900 | I38: =ProfLoss!I10 -> 3.3285148e+08 | J38: =ProfLoss!J10 -> 340175451
B39: EBITDA | C39: USD | D39: =ProfLoss!D27 -> 4067929.8 | E39: =ProfLoss!E27 -> 22679487 | F39: =ProfLoss!F27 -> 28130752 | G39: =ProfLoss!G27 -> 30221089 | H39: =ProfLoss!H27 -> 30902858 | I39: =ProfLoss!I27 -> 31599285 | J39: =ProfLoss!J27 -> 32312606
B40: Чистая прибыль | C40: USD | D40: =ProfLoss!D22 -> 2927686.4 | E40: =ProfLoss!E22 -> 16162513 | F40: =ProfLoss!F22 -> 20929536 | G40: =ProfLoss!G22 -> 22836995 | H40: =ProfLoss!H22 -> 23547172 | I40: =ProfLoss!I22 -> 24271186 | J40: =ProfLoss!J22 -> 25015911
B41: Операционный поток наличности (A) | C41: USD | D41: =CashFlow!D18 -> -25431200 | E41: =CashFlow!E18 -> 5266470.1 | F41: =CashFlow!F18 -> 14249199 | G41: =CashFlow!G18 -> 24697202 | H41: =CashFlow!H18 -> 25548304 | I41: =CashFlow!I18 -> 26090595 | J41: =CashFlow!J18 -> 26645386
B42: Обслуживание долга (проценты + основной долг) | C42: USD | D42: =LOANS!$C$107 -> 1208251.7 | E42: =LOANS!$D$107 -> 3956163.8 | F42: =LOANS!$E$107 -> 3751524.2 | G42: =LOANS!$F$107 -> 3550149 | H42: =LOANS!$G$107 -> 3348773.7 | I42: =LOANS!$H$107 -> 3148455.8 | J42: =LOANS!$I$107 -> 2946023.1
B43: Чистый поток наличности | C43: USD | D43: =CashFlow!D26 -> 3721522.2 | E43: =CashFlow!E26 -> 833883.94 | F43: =CashFlow!F26 -> 10021253 | G43: =CashFlow!G26 -> 20670631 | H43: =CashFlow!H26 -> 21723108 | I43: =CashFlow!I26 -> 22465717 | J43: =CashFlow!J26 -> 23222941
B44: Кумулятивный поток наличности | C44: USD | D44: =CashFlow!D27 -> 3721522.2 | E44: =CashFlow!E27 -> 4555406.1 | F44: =CashFlow!F27 -> 14576659 | G44: =CashFlow!G27 -> 35247290 | H44: =CashFlow!H27 -> 56970399 | I44: =CashFlow!I27 -> 79436115 | J44: =CashFlow!J27 -> 1.0265906e+08
B45: DSCR (с учётом поддерживающих капвложений) | C45: x | D45: =CashFlow!D30 -> - | E45: =CashFlow!E30 -> 1.2107809 | F45: =CashFlow!F30 -> 3.6712484 | G45: =CashFlow!G30 -> 6.8224687 | H45: =CashFlow!H30 -> 7.4868846 | I45: =CashFlow!I30 -> 8.1354714 | J45: =CashFlow!J30 -> 8.8828101
B46: Задолженность по кредиту на конец года | C46: USD | D46: =LOANS!$C$108 -> 17024290 | E46: =LOANS!$D$108 -> 14186908 | F46: =LOANS!$E$108 -> 11349526 | G46: =LOANS!$F$108 -> 8512144.8 | H46: =LOANS!$G$108 -> 5674763.2 | I46: =LOANS!$H$108 -> 2837381.6 | J46: =LOANS!$I$108 -> 0
...

Sheet ИНФОРМАЦИЯ
B2: ДАННЫЕ ПО ПРОЕКТУ
B4: ЗАЕМЩИК | C4: АО «Узбекский комбинат технологических металлов» (АО «Ўзбекистон ТМК», UzTMK)
B5: ИНН | C5: - (заполняется заемщиком)
B6: ДЕЯТЕЛЬНОСТЬ | C6: Добыча и переработка редких и тугоплавких металлов (вольфрам, молибден)
B7: НАИМЕНОВАНИЕ ПРОЕКТА | C7: Строительство нового гидрометаллургического завода по переработке вольфрамового концентрата (1-я очередь) (Цех по переработке вольфрамового концентрата)
B8: МЕСТО РЕАЛИЗАЦИИ | C8: Самаркандская обл., Нурабадский р-н, 9,6 га
B9: ПРОИЗВОДСТВЕННАЯ МОЩНОСТЬ | C9: Переработка 5 000 т вольфрамового концентрата в год
B10: ОСНОВНАЯ ПРОДУКЦИЯ | C10: Триоксид вольфрама WO3
B11: СТАДИЯ ПРОРАБОТКИ | C11: ТЭО (технико-экономическое обоснование)
B12: НАЧАЛО СТРОИТЕЛЬСТВА | C12: 01.10.2026
B13: НАЧАЛО ПРОИЗВОДСТВА | C13: 01.10.2027
B14: СРОК РЕАЛИЗАЦИИ (по данным заемщика) | C14: ноябрь 2027 г.
B16: УЧАСТНИКИ ПРОЕКТА
B17: Заемщик (инициатор проекта) | C17: АО «Узбекский комбинат технологических металлов» (АО «Ўзбекистон ТМК», UzTMK)
B18: Доля заемщика в проекте | C18: 100%
B19: Кредитор №1 | C19: Национальный банк внешнеэкономической деятельности Республики Узбекистан
B20: Генеральный подрядчик | C20: EPC-подрядчик (по EPC-контракту)
B22: ВАЛЮТА ПРОЕКТА | C22: Доллар США (экв.)
B23: 1 USD = (сум, средний курс 1-го года) | C23: 12231.234
B25: УСЛОВИЯ КРЕДИТА
B26: Сумма кредита, USD | C26: =O41 -> 17024290
B27: Процентная ставка, % годовых | C27: 0.07
B28: Срок кредита, месяцев | C28: 84
B29: Льготный период по основному долгу, месяцев | C29: 12
B30: Инвестиционный период, месяцев | C30: 12
B31: Дата выдачи кредита | C31: 46388
B32: База начисления процентов, дней в году (по форме банка) | C32: 360
B33: Погашение основного долга | C33: ежемесячно равными долями: 72 платежа, со 2-го по 7-й год
B34: Уплата процентов | C34: ежемесячно; в льготный период (1-й год) - за счёт собственных средств заемщика (включены в стоимость проекта)
B35: Целевое назначение | C35: 30% авансовый платёж по EPC-контракту (данные заемщика)
B36: Резерв (непредвиденные расходы) - % от суммы кредита (по форме банка) | C36: 0.01
B38: РАСПРЕДЕЛЕНИЕ КРЕДИТА 78 МЛН USD МЕЖДУ ПРОЕКТАМИ (по 30% авансу EPC-контрактов, файл заемщика от 14.10.2026)
B39: Проект | C39: Мощность | D39: Стоимость проекта, млн USD | E39: EPC: E (Engineering), млрд сум | F39: EPC: P (Procurement), млрд сум | G39: EPC: C (Construction), млрд сум | H39: EPC итого, млрд сум | I39: Курс EPC (тыс. сум/USD) | J39: EPC итого, экв. млн USD | K39: 30% аванс, млрд сум | L39: Курс аванса (тыс. сум/USD) | M39: 30% аванс, млн USD | N39: Доля в кредите | O39: Кредит, USD
B40: Освоение центральной части вольфрамового месторождения Сарикуль (1-я очередь) | C40: Переработка 600 тыс. т руды в год | D40: 158 | E40: 116.0323 | F40: 532.896 | G40: 1041.5674 | H40: =E40+F40+G40 -> 1690.4957 | I40: 12.2 | J40: =H40/I40 -> 138.56522 | K40: =H40*30% -> 507.1487 | L40: 11.838 | M40: =K40/L40 -> 42.840742 | N40: =M40/$M$43 -> 0.54851149 | O40: =N40*$O$44 -> 42783896
B41: Строительство нового гидрометаллургического завода по переработке вольфрамового концентрата (1-я очередь) | C41: Переработка 5 000 т вольфрамового концентрата в год | D41: 80 | E41: 25.272 | F41: 293.4 | G41: 353.99904 | H41: =E41+F41+G41 -> 672.67104 | I41: 12 | J41: =H41/I41 -> 56.05592 | K41: =H41*30% -> 201.80131 | L41: 11.838 | M41: =K41/L41 -> 17.046909 | N41: =M41/$M$43 -> 0.21826012 | O41: =N41*$O$44 -> 17024290
B42: Строительство нового гидрометаллургического завода по переработке промышленного продукта - молибденового огарка | C42: Переработка 5 000 т молибденового огарка (концентрата) в год | D42: 65 | E42: 25.35648 | F42: 251.13528 | G42: 442.311 | H42: =E42+F42+G42 -> 718.80276 | I42: 12 | J42: =H42/I42 -> 59.90023 | K42: =H42*30% -> 215.64083 | L42: 11.838 | M42: =K42/L42 -> 18.215985 | N42: =M42/$M$43 -> 0.23322838 | O42: =N42*$O$44 -> 18191814
B43: ИТОГО | D43: =SUM(D40:D42) -> 303 | E43: =SUM(E40:E42) -> 166.66078 | F43: =SUM(F40:F42) -> 1077.4313 | G43: =SUM(G40:G42) -> 1837.8774 | H43: =SUM(H40:H42) -> 3081.9695 | J43: =SUM(J40:J42) -> 254.52137 | K43: =SUM(K40:K42) -> 924.59084 | M43: =SUM(M40:M42) -> 78.103636 | N43: =SUM(N40:N42) -> 1 | O43: =SUM(O40:O42) -> 78000000
N44: Лимит кредита, USD | O44: 78000000
B46: Распределение кредита - пропорционально 30% авансу по EPC-контрактам, с приведением к лимиту 78,0 млн USD.

Sheet ProjCost
B2: ПЕРВОНАЧАЛЬНАЯ СТОИМОСТЬ ПРОЕКТА (в экв. долл. США) | F2: Приложение 1
B3: Инвестиционный период: с начала строительства до конца 1-го года (льготный период по кредиту).
B4: Наименование затрат | C4: МЕСТНАЯ ВАЛЮТА | D4: ТВЕРДАЯ ВАЛЮТА | E4: ВСЕГО | F4: СТРУКТУРА (%)
B5: ВСЕГО ФИКСИРОВАННЫЕ АКТИВЫ | C5: =SUM(C6:C9) -> 0 | D5: =SUM(D6:D9) -> 47761338 | E5: =SUM(E6:E9) -> 47761338 | F5: =IFERROR(E5/$E$16,0) -> 0.61136616
B6: Здания, сооружения и передаточные устройства | C6: 0 | D6: 28395000 | E6: =C6+D6 -> 28395000 | F6: =IFERROR(E6/$E$16,0) -> 0.36346851
B7: Машины и оборудование | C7: 0 | D7: 19089552 | E7: =C7+D7 -> 19089552 | F7: =IFERROR(E7/$E$16,0) -> 0.24435467
B8: Транспортные средства | C8: 0 | D8: 223214.29 | E8: =C8+D8 -> 223214.29 | F8: =IFERROR(E8/$E$16,0) -> 0.0028572412
B9: Мебель, оргтехника и офисное оборудование | C9: 0 | D9: 53571.429 | E9: =C9+D9 -> 53571.429 | F9: =IFERROR(E9/$E$16,0) -> 0.00068573788
B10: РАБОЧИЙ КАПИТАЛ | C10: =WorkCap!D23-D10 -> 17296073 | D10: =WorkCap!D16 -> 10984439 | E10: =C10+D10 -> 28280512 | F10: =IFERROR(E10/$E$16,0) -> 0.36200301
B11: ПРОЧИЕ ФИНАНСОВЫЕ ИЗДЕРЖКИ, ВКЛЮЧАЯ: | C11: =SUM(C12:C13) -> 701967.23 | D11: =SUM(D12:D13) -> 1208251.7 | E11: =SUM(E12:E13) -> 1910218.9 | F11: =IFERROR(E11/$E$16,0) -> 0.024451643
B12: Проценты по кредиту за льготный период (1-й год) - за счёт собственных средств | C12: 0 | D12: =LOANS!$C$106 -> 1208251.7 | E12: =C12+D12 -> 1208251.7 | F12: =IFERROR(E12/$E$16,0) -> 0.015466154
B13: Расходы подготовительного периода (административные и пусковые расходы) | C13: 701967.23 | D13: 0 | E13: =C13+D13 -> 701967.23 | F13: =IFERROR(E13/$E$16,0) -> 0.0089854898
B14: НЕПРЕДВИДЕННЫЕ РАСХОДЫ/РЕЗЕРВ (1% от суммы кредита) | C14: 0 | D14: =ИНФОРМАЦИЯ!$C$26*ИНФОРМАЦИЯ!$C$36 -> 170242.9 | E14: =C14+D14 -> 170242.9 | F14: =IFERROR(E14/$E$16,0) -> 0.0021791841
B16: ВСЕГО ПЕРВОНАЧАЛЬНАЯ СТОИМОСТЬ ПРОЕКТА | C16: =C5+C10+C11+C14 -> 17998040 | D16: =D5+D10+D11+D14 -> 60124271 | E16: =E5+E10+E11+E14 -> 78122312 | F16: =IFERROR(E16/$E$16,0) -> 1

Sheet FinPlan
B2: ФИНАНСОВЫЙ ПЛАН (в экв. долл. США) | G2: Приложение 2
B4: ПОКАЗАТЕЛИ | C4: МЕСТНАЯ ВАЛЮТА | D4: ТВЁРДАЯ ВАЛЮТА | E4: ВСЕГО | F4: СТРУКТУРА (%) | G4: ДОЛЯ В ФИНАНСИРОВАНИИ
B5: СОБСТВЕННЫЙ КАПИТАЛ
B6: АО «Узбекский комбинат технологических металлов» (АО «Ўзбекистон ТМК», UzTMK)
B7: Фиксированные активы | C7: ='Share of costs'!C6 -> 0 | D7: ='Share of costs'!D6 -> 30737048 | E7: =C7+D7 -> 30737048 | F7: =IFERROR(E7/$E$10,0) -> 0.50307763
B8: Рабочий капитал | C8: ='Share of costs'!C11 -> 17296073 | D8: ='Share of costs'!D11 -> 10984439 | E8: =C8+D8 -> 28280512 | F8: =IFERROR(E8/$E$10,0) -> 0.46287116
B9: Денежные средства (финансовые издержки льготного периода, расходы подготовительного периода, резерв) | C9: ='Share of costs'!C12+'Share of costs'!C15 -> 701967.23 | D9: ='Share of costs'!D12+'Share of costs'!D15 -> 1378494.6 | E9: =C9+D9 -> 2080461.8 | F9: =IFERROR(E9/$E$10,0) -> 0.034051214
B10: ВСЕГО | C10: =SUM(C7:C9) -> 17998040 | D10: =SUM(D7:D9) -> 43099982 | E10: =SUM(E7:E9) -> 61098022 | F10: =IFERROR(E10/$E$10,0) -> 1 | G10: =IFERROR(E10/$E$15,0) -> 0.78208159
B11: КРЕДИТЫ
B12: Национальный банк внешнеэкономической деятельности Республики Узбекистан (7% годовых, 84 мес., льготный период 12 мес.) | C12: =C13 -> 0 | D12: =D13 -> 17024290 | E12: =C12+D12 -> 17024290 | F12: =IFERROR(E12/$E$14,0) -> 1
B13: Фиксированные активы (30% аванс по EPC-контракту) | C13: ='Share of costs'!E6 -> 0 | D13: ='Share of costs'!F6 -> 17024290 | E13: =C13+D13 -> 17024290 | F13: =IFERROR(E13/$E$14,0) -> 1
B14: ВСЕГО | C14: =C12 -> 0 | D14: =D12 -> 17024290 | E14: =E12 -> 17024290 | F14: =IFERROR(E14/$E$14,0) -> 1 | G14: =IFERROR(E14/$E$15,0) -> 0.21791841
B15: ВСЕГО ФИНАНСИРОВАНИЯ | C15: =C14+C10 -> 17998040 | D15: =D14+D10 -> 60124271 | E15: =E14+E10 -> 78122312 | G15: =IFERROR(E15/$E$15,0) -> 1

Sheet Share of costs
B2: ПЕРВОНАЧАЛЬНАЯ СТОИМОСТЬ ПРОЕКТА ПО ИСТОЧНИКАМ ФИНАНСИРОВАНИЯ (в экв. долл. США) | H2: Приложение 3
B4: Наименование затрат | C4: Собственные средства заемщика | E4: Кредит НБУ | G4: Всего
C5: в местной валюте | D5: в твердой валюте | E5: в местной валюте | F5: в твердой валюте | G5: в местной валюте | H5: в твердой валюте
B6: ВСЕГО ФИКСИРОВАННЫЕ АКТИВЫ | C6: =SUM(C7:C10) -> 0 | D6: =SUM(D7:D10) -> 30737048 | E6: =SUM(E7:E10) -> 0 | F6: =SUM(F7:F10) -> 17024290 | G6: =SUM(G7:G10) -> 0 | H6: =SUM(H7:H10) -> 47761338
B7: Здания, сооружения и передаточные устройства | C7: =ProjCost!$C$6 -> 0 | D7: =ProjCost!$D$6-F7 -> 18796222 | E7: 0 | F7: =ИНФОРМАЦИЯ!$C$26*(1-ИНФОРМАЦИЯ!$F$41/ИНФОРМАЦИЯ!$H$41)*ProjCost!$E$6/(ProjCost!$E$6) -> 9598778.1 | G7: =C7+E7 -> 0 | H7: =D7+F7 -> 28395000
B8: Машины и оборудование | C8: =ProjCost!$C$7 -> 0 | D8: =ProjCost!$D$7-F8 -> 11770167 | E8: 0 | F8: =ИНФОРМАЦИЯ!$C$26*ИНФОРМАЦИЯ!$F$41/ИНФОРМАЦИЯ!$H$41*ProjCost!$E$7/(ProjCost!$E$7+ProjCost!$E$8+ProjCost!$E$9) -> 7319385.4 | G8: =C8+E8 -> 0 | H8: =D8+F8 -> 19089552
B9: Транспортные средства | C9: =ProjCost!$C$8 -> 0 | D9: =ProjCost!$D$8-F9 -> 137628.65 | E9: 0 | F9: =ИНФОРМАЦИЯ!$C$26*ИНФОРМАЦИЯ!$F$41/ИНФОРМАЦИЯ!$H$41*ProjCost!$E$8/(ProjCost!$E$7+ProjCost!$E$8+ProjCost!$E$9) -> 85585.632 | G9: =C9+E9 -> 0 | H9: =D9+F9 -> 223214.29
B10: Мебель, оргтехника и офисное оборудование | C10: =ProjCost!$C$9 -> 0 | D10: =ProjCost!$D$9-F10 -> 33030.877 | E10: 0 | F10: =ИНФОРМАЦИЯ!$C$26*ИНФОРМАЦИЯ!$F$41/ИНФОРМАЦИЯ!$H$41*ProjCost!$E$9/(ProjCost!$E$7+ProjCost!$E$8+ProjCost!$E$9) -> 20540.552 | G10: =C10+E10 -> 0 | H10: =D10+F10 -> 53571.429
B11: РАБОЧИЙ КАПИТАЛ | C11: =ProjCost!$C$10 -> 17296073 | D11: =ProjCost!$D$10 -> 10984439 | E11: 0 | F11: 0 | G11: =C11+E11 -> 17296073 | H11: =D11+F11 -> 10984439
B12: ПРОЧИЕ ФИНАНСОВЫЕ ИЗДЕРЖКИ | C12: =ProjCost!$C$11 -> 701967.23 | D12: =ProjCost!$D$11 -> 1208251.7 | E12: 0 | F12: 0 | G12: =C12+E12 -> 701967.23 | H12: =D12+F12 -> 1208251.7
B13: в т.ч. проценты по кредиту за льготный период | C13: =ProjCost!$C$12 -> 0 | D13: =ProjCost!$D$12 -> 1208251.7 | E13: 0 | F13: 0 | G13: =C13+E13 -> 0 | H13: =D13+F13 -> 1208251.7
B14: в т.ч. расходы подготовительного периода | C14: =ProjCost!$C$13 -> 701967.23 | D14: =ProjCost!$D$13 -> 0 | E14: 0 | F14: 0 | G14: =C14+E14 -> 701967.23 | H14: =D14+F14 -> 0
B15: НЕПРЕДВИДЕННЫЕ РАСХОДЫ/РЕЗЕРВ | C15: =ProjCost!$C$14 -> 0 | D15: =ProjCost!$D$14 -> 170242.9 | E15: 0 | F15: 0 | G15: =C15+E15 -> 0 | H15: =D15+F15 -> 170242.9
B17: ВСЕГО ПЕРВОНАЧАЛЬНАЯ СТОИМОСТЬ ПРОЕКТА | C17: =C6+C11+C12+C15 -> 17998040 | D17: =D6+D11+D12+D15 -> 43099982 | E17: =E6+E11+E12+E15 -> 0 | F17: =F6+F11+F12+F15 -> 17024290 | G17: =G6+G11+G12+G15 -> 17998040 | H17: =H6+H11+H12+H15 -> 60124271
B18: Итого по источнику | C18: =C17+D17 -> 61098022 | E18: =E17+F17 -> 17024290 | G18: =G17+H17 -> 78122312
B20: Кредит НБУ направляется на 30% авансовый платёж по EPC-контракту; распределение по группам активов - пропорционально составу EPC-контракта: P (поставка оборудования) - машины и оборудование, E+C (проектирование и строительство) - здания, сооружения и прочие объекты.

Sheet Depreciate
B2: АМОРТИЗАЦИЯ (в долл. США) | N2: Приложение 4
B3: Линейный метод. Проценты льготного периода капитализированы в стоимость основных средств (МСФО IAS 23).
B5: ОБЪЕКТЫ АМОРТИЗАЦИИ | C5: Группа основных средств | D5: Первоначальная стоимость | E5: Срок, лет | F5: Норма, % | G5: 1 год | H5: 2 год | I5: 3 год | J5: 4 год | K5: 5 год | L5: 6 год | M5: 7 год
B7: Разработка проектных документов (ТЭО и ЗВОС) | C7: Здания, сооружения и передаточные устройства | D7: 147321.43 | E7: 50 | F7: =1/E7 -> 0.02 | G7: 736.60714 | H7: 2946.4286 | I7: 2946.4286 | J7: 2946.4286 | K7: 2946.4286 | L7: 2946.4286 | M7: 2946.4286
B8: Разработка PFS проекта | C8: Здания, сооружения и передаточные устройства | D8: 321428.57 | E8: 50 | F8: =1/E8 -> 0.02 | G8: 1607.1429 | H8: 6428.5714 | I8: 6428.5714 | J8: 6428.5714 | K8: 6428.5714 | L8: 6428.5714 | M8: 6428.5714
B9: Проектно-инженерные работы | C9: Здания, сооружения и передаточные устройства | D9: 2232142.9 | E9: 50 | F9: =1/E9 -> 0.02 | G9: 11160.714 | H9: 44642.857 | I9: 44642.857 | J9: 44642.857 | K9: 44642.857 | L9: 44642.857 | M9: 44642.857
B10: Приобретение оборудования | C10: Машины и оборудование | D10: 18256161 | E10: 10 | F10: =1/E10 -> 0.1 | G10: 456404.02 | H10: 1825616.1 | I10: 1825616.1 | J10: 1825616.1 | K10: 1825616.1 | L10: 1825616.1 | M10: 1825616.1
B11: Строительство | C11: Здания, сооружения и передаточные устройства | D11: 22238750 | E11: 50 | F11: =1/E11 -> 0.02 | G11: 111193.75 | H11: 444775 | I11: 444775 | J11: 444775 | K11: 444775 | L11: 444775 | M11: 444775
B12: Земляные работы | C12: Здания, сооружения и передаточные устройства | D12: 178571.43 | E12: 50 | F12: =1/E12 -> 0.02 | G12: 892.85714 | H12: 3571.4286 | I12: 3571.4286 | J12: 3571.4286 | K12: 3571.4286 | L12: 3571.4286 | M12: 3571.4286
B13: Адаптация проектной документации | C13: Здания, сооружения и передаточные устройства | D13: 89285.714 | E13: 50 | F13: =1/E13 -> 0.02 | G13: 446.42857 | H13: 1785.7143 | I13: 1785.7143 | J13: 1785.7143 | K13: 1785.7143 | L13: 1785.7143 | M13: 1785.7143
B14: Строительство инфраструктуры (вода, газ, электроэнергия) | C14: Здания, сооружения и передаточные устройства | D14: 3125000 | E14: 50 | F14: =1/E14 -> 0.02 | G14: 15625 | H14: 62500 | I14: 62500 | J14: 62500 | K14: 62500 | L14: 62500 | M14: 62500
B15: Технологический транспорт | C15: Транспортные средства | D15: 223214.29 | E15: 10 | F15: =1/E15 -> 0.1 | G15: 5580.3571 | H15: 22321.429 | I15: 22321.429 | J15: 22321.429 | K15: 22321.429 | L15: 22321.429 | M15: 22321.429
B16: Солнечные панели | C16: Машины и оборудование | D16: 714285.71 | E16: 20 | F16: =1/E16 -> 0.05 | G16: 8928.5714 | H16: 35714.286 | I16: 35714.286 | J16: 35714.286 | K16: 35714.286 | L16: 35714.286 | M16: 35714.286
B17: Камеры наблюдения и вертикальные стойки | C17: Мебель, оргтехника и офисное оборудование | D17: 53571.429 | E17: 5 | F17: =1/E17 -> 0.2 | G17: 2678.5714 | H17: 10714.286 | I17: 10714.286 | J17: 10714.286 | K17: 10714.286 | L17: 8035.7143 | M17: 0
B18: Дополнительные расходы | C18: Здания, сооружения и передаточные устройства | D18: 62500 | E18: 50 | F18: =1/E18 -> 0.02 | G18: 312.5 | H18: 1250 | I18: 1250 | J18: 1250 | K18: 1250 | L18: 1250 | M18: 1250
B19: Поддерживающие капвложения (% от первоначальной стоимости ОС) | C19: Машины и оборудование | D19: 2977639.5 | E19: 10 | F19: =1/E19 -> 0.1 | G19: 1985.093 | H19: 59552.79 | I19: 107195.02 | J19: 154837.25 | K19: 202479.49 | L19: 250121.72 | M19: 297763.95
B20: Капитализированные проценты по кредиту за льготный период (1-й год) | C20: Затраты по займам (МСФО IAS 23) | D20: =LOANS!$C$106 -> 1208251.7 | E20: 50 | F20: =1/E20 -> 0.02 | G20: =D20/E20*3/12 -> 6041.2584 | H20: =D20/E20 -> 24165.033 | I20: =D20/E20 -> 24165.033 | J20: =D20/E20 -> 24165.033 | K20: =D20/E20 -> 24165.033 | L20: =D20/E20 -> 24165.033 | M20: =D20/E20 -> 24165.033
B21: ВСЕГО | C21: Х | D21: =SUM(D7:D20) -> 51828123 | G21: =SUM(G7:G20) -> 623592.87 | H21: =SUM(H7:H20) -> 2545983.9 | I21: =SUM(I7:I20) -> 2593626.1 | J21: =SUM(J7:J20) -> 2641268.4 | K21: =SUM(K7:K20) -> 2688910.6 | L21: =SUM(L7:L20) -> 2733874.3 | M21: =SUM(M7:M20) -> 2773480.8
B22: в т.ч. в себестоимости продукции | G22: =G21-G23 -> 620914.3 | H22: =H21-H23 -> 2535269.6 | I22: =I21-I23 -> 2582911.8 | J22: =J21-J23 -> 2630554.1 | K22: =K21-K23 -> 2678196.3 | L22: =L21-L23 -> 2725838.5 | M22: =M21-M23 -> 2773480.8
B23: в т.ч. в административных расходах | G23: 2678.5714 | H23: 10714.286 | I23: 10714.286 | J23: 10714.286 | K23: 10714.286 | L23: 8035.7143 | M23: 0
B25: Капитальные вложения (освоение; 1-й год вкл. подготовительный период) | G25: 47761338 | H25: 476422.32 | I25: 476422.32 | J25: 476422.32 | K25: 476422.32 | L25: 476422.32 | M25: 476422.32
B26: Накопленная амортизация | G26: =SUM($G$21:G21) -> 623592.87 | H26: =SUM($G$21:H21) -> 3169576.8 | I26: =SUM($G$21:I21) -> 5763202.9 | J26: =SUM($G$21:J21) -> 8404471.3 | K26: =SUM($G$21:K21) -> 11093382 | L26: =SUM($G$21:L21) -> 13827256 | M26: =SUM($G$21:M21) -> 16600737
B27: Остаточная стоимость основных средств (на конец года) | G27: =G25+$D$20-G21 -> 48345997 | H27: =G27+H25-H21 -> 46276435 | I27: =H27+I25-I21 -> 44159231 | J27: =I27+J25-J21 -> 41994385 | K27: =J27+K25-K21 -> 39781897 | L27: =K27+L25-L21 -> 37524445 | M27: =L27+M25-M21 -> 35227386

Sheet ProdPlan
B2: ПРОИЗВОДСТВЕННЫЙ ПЛАН | K2: Приложение 5
B4: Н А И М Е Н О В А Н И Е | C4: Ед. изм. | D4: Мощность в год | E4: Рынок сбыта | F4: Цена за единицу, USD (при проектной мощности) | G4: Выручка при полной мощности: экспорт | H4: Выручка при полной мощности: внутр. рынок
B5: Триоксид вольфрама WO3 | C5: t | D5: 2656.5 | E5: экспорт | F5: =F20 -> 117379 | G5: =D5*F5 -> 3.1181731e+08 | H5: 0
B6: Всего | G6: =SUM(G5:G5) -> 3.1181731e+08 | H6: =SUM(H5:H5) -> 0
B8: ПОКАЗАТЕЛИ | C8: Ед. изм. | D8: 1 год (льготный период) | E8: 2 год | F8: 3 год | G8: 4 год | H8: 5 год | I8: 6 год | J8: 7 год
B10: ОСВОЕНИЕ МОЩНОСТЕЙ
B11: Триоксид вольфрама WO3 | C11: % | D11: 0.10163749 | E11: 0.82971014 | F11: 1 | G11: 1 | H11: 1 | I11: 1 | J11: 1
B12: КОЛИЧЕСТВО ПРОИЗВОДСТВА
B13: Триоксид вольфрама WO3 | C13: t | D13: =$D$5*D11 -> 270 | E13: =$D$5*E11 -> 2204.125 | F13: =$D$5*F11 -> 2656.5 | G13: =$D$5*G11 -> 2656.5 | H13: =$D$5*H11 -> 2656.5 | I13: =$D$5*I11 -> 2656.5 | J13: =$D$5*J11 -> 2656.5
B14: КОЛИЧЕСТВО ДЛЯ РЕАЛИЗАЦИИ
B15: Триоксид вольфрама WO3 - экспорт | C15: t | D15: 250 | E15: 2154.125 | F15: 2623.2937 | G15: 2656.5 | H15: 2656.5 | I15: 2656.5 | J15: 2656.5
B16: Триоксид вольфрама WO3 - внутренний рынок | C16: t | D16: 0 | E16: 0 | F16: 0 | G16: 0 | H16: 0 | I16: 0 | J16: 0
B17: КОЛИЧЕСТВО ЗАПАСА ГОТОВОЙ ПРОДУКЦИИ НА КОНЕЦ ГОДА
B18: Триоксид вольфрама WO3 | C18: t | D18: =0+D13-D15-D16 -> 20 | E18: =D18+E13-E15-E16 -> 70 | F18: =E18+F13-F15-F16 -> 103.20625 | G18: =F18+G13-G15-G16 -> 103.20625 | H18: =G18+H13-H15-H16 -> 103.20625 | I18: =H18+I13-I15-I16 -> 103.20625 | J18: =I18+J13-J15-J16 -> 103.20625
B19: ЦЕНА РЕАЛИЗАЦИИ
B20: Триоксид вольфрама WO3 | C20: USD/t | D20: 113325 | E20: 114852 | F20: 117379 | G20: 119961 | H20: 122600 | I20: 125297 | J20: 128054

Sheet SalePlan
B2: ПЛАН ПРОДАЖ (в экв. долл. США, без НДС) | K2: Приложение 6
B4: ПОКАЗАТЕЛИ | C4: Ед. изм. | D4: 1 год (льготный период) | E4: 2 год | F4: 3 год | G4: 4 год | H4: 5 год | I4: 6 год | J4: 7 год
B6: ЭКСПОРТ
B7: Триоксид вольфрама WO3 | C7: USD | D7: =ProdPlan!D15*ProdPlan!D20 -> 28331250 | E7: =ProdPlan!E15*ProdPlan!E20 -> 2.4740556e+08 | F7: =ProdPlan!F15*ProdPlan!F20 -> 3.079196e+08 | G7: =ProdPlan!G15*ProdPlan!G20 -> 3.186764e+08 | H7: =ProdPlan!H15*ProdPlan!H20 -> 325686900 | I7: =ProdPlan!I15*ProdPlan!I20 -> 3.3285148e+08 | J7: =ProdPlan!J15*ProdPlan!J20 -> 340175451
B8: Всего | C8: USD | D8: =SUM(D7:D7) -> 28331250 | E8: =SUM(E7:E7) -> 2.4740556e+08 | F8: =SUM(F7:F7) -> 3.079196e+08 | G8: =SUM(G7:G7) -> 3.186764e+08 | H8: =SUM(H7:H7) -> 325686900 | I8: =SUM(I7:I7) -> 3.3285148e+08 | J8: =SUM(J7:J7) -> 340175451
B10: ВНУТРЕННИЕ ПРОДАЖИ
B11: Триоксид вольфрама WO3 | C11: USD | D11: =ProdPlan!D16*ProdPlan!D20 -> 0 | E11: =ProdPlan!E16*ProdPlan!E20 -> 0 | F11: =ProdPlan!F16*ProdPlan!F20 -> 0 | G11: =ProdPlan!G16*ProdPlan!G20 -> 0 | H11: =ProdPlan!H16*ProdPlan!H20 -> 0 | I11: =ProdPlan!I16*ProdPlan!I20 -> 0 | J11: =ProdPlan!J16*ProdPlan!J20 -> 0
B12: Всего | C12: USD | D12: =SUM(D11:D11) -> 0 | E12: =SUM(E11:E11) -> 0 | F12: =SUM(F11:F11) -> 0 | G12: =SUM(G11:G11) -> 0 | H12: =SUM(H11:H11) -> 0 | I12: =SUM(I11:I11) -> 0 | J12: =SUM(J11:J11) -> 0
B14: ВСЕГО ПРОДАЖ | C14: USD | D14: =D8+D12 -> 28331250 | E14: =E8+E12 -> 2.4740556e+08 | F14: =F8+F12 -> 3.079196e+08 | G14: =G8+G12 -> 3.186764e+08 | H14: =H8+H12 -> 325686900 | I14: =I8+I12 -> 3.3285148e+08 | J14: =J8+J12 -> 340175451
B15: Доля экспорта в выручке | C15: % | D15: =IFERROR(D8/D14,0) -> 1 | E15: =IFERROR(E8/E14,0) -> 1 | F15: =IFERROR(F8/F14,0) -> 1 | G15: =IFERROR(G8/G14,0) -> 1 | H15: =IFERROR(H8/H14,0) -> 1 | I15: =IFERROR(I8/I14,0) -> 1 | J15: =IFERROR(J8/J14,0) -> 1

Sheet RawMat
B2: СТОИМОСТЬ СЫРЬЯ И МАТЕРИАЛОВ ПРИ ПРОЕКТНОЙ МОЩНОСТИ (в экв. долл. США) | G2: Приложение 7
B3: Расчёт на 3-й год (освоение мощности 100%); цены в номинальном выражении; без НДС.
B5: НАИМЕНОВАНИЕ | C5: Ед. изм. | D5: Цена за единицу, USD | E5: Годовая потребность | F5: Годовая стоимость, USD | G5: ДОЛЯ (%) | H5: Примечание
B6: СЫРЬЁ, МАТЕРИАЛЫ И ПЕРЕМЕННЫЕ ЗАТРАТЫ С ЦЕНОЙ В ТВЁРДОЙ ВАЛЮТЕ (USD)
B7: Вольфрамовый концентрат 55% | C7: t | D7: =IFERROR(F7/E7,0) -> 51900.129 | E7: 5000 | F7: 2.5950064e+08 | G7: =IFERROR(F7/$F$24,0) -> 0.97811923 | H7: Сырьё
B8: ВСЕГО В ТВЁРДОЙ ВАЛЮТЕ | F8: =SUM(F7:F7) -> 2.5950064e+08 | G8: =IFERROR(F8/$F$24,0) -> 0.97811923
B10: СЫРЬЁ, МАТЕРИАЛЫ И ПЕРЕМЕННЫЕ ЗАТРАТЫ С ЦЕНОЙ В НАЦИОНАЛЬНОЙ ВАЛЮТЕ (UZS)
B11: Аммиачная вода 25% (на 100%) | C11: t | D11: =IFERROR(F11/E11,0) -> 211.5735 | E11: 449.61 | F11: 95125.559 | G11: =IFERROR(F11/$F$24,0) -> 0.00035855071 | H11: Вспомогательные материалы
B12: Соляная кислота 30% | C12: t | D12: =IFERROR(F12/E12,0) -> 65.644455 | E12: 9800 | F12: 643315.66 | G12: =IFERROR(F12/$F$24,0) -> 0.0024248087 | H12: Вспомогательные материалы
B13: Гидроксид натрия | C13: t | D13: =IFERROR(F13/E13,0) -> 998.8347 | E13: 2000 | F13: 1997669.4 | G13: =IFERROR(F13/$F$24,0) -> 0.0075296879 | H13: Вспомогательные материалы
B14: Карбонат натрия | C14: t | D14: =IFERROR(F14/E14,0) -> 493.61485 | E14: 3769.4 | F14: 1860631.8 | G14: =IFERROR(F14/$F$24,0) -> 0.0070131609 | H14: Вспомогательные материалы
B15: Гидроксид алюминия | C15: t | D15: =IFERROR(F15/E15,0) -> 947.52208 | E15: 163.5 | F15: 154919.86 | G15: =IFERROR(F15/$F$24,0) -> 0.00058392955 | H15: Вспомогательные материалы
B16: Хлорид аммония | C16: t | D16: =IFERROR(F16/E16,0) -> 451.48273 | E16: 2098.19 | F16: 947296.54 | G16: =IFERROR(F16/$F$24,0) -> 0.0035705845 | H16: Вспомогательные материалы
B17: Ионообменная смола | C17: t | D17: =IFERROR(F17/E17,0) -> 381.58791 | E17: 5.99 | F17: 2285.7116 | G17: =IFERROR(F17/$F$24,0) -> 8.615387e-06 | H17: Вспомогательные материалы
B18: Сульфид меди | C18: t | D18: =IFERROR(F18/E18,0) -> 213.46254 | E18: 6.79 | F18: 1449.4107 | G18: =IFERROR(F18/$F$24,0) -> 5.4631713e-06 | H18: Вспомогательные материалы
B19: Сульфид аммония | C19: t | D19: =IFERROR(F19/E19,0) -> 965.30407 | E19: 19.33 | F19: 18659.328 | G19: =IFERROR(F19/$F$24,0) -> 7.0331414e-05 | H19: Вспомогательные материалы
B20: Фильтроткань | C20: m2 | D20: =IFERROR(F20/E20,0) -> 14.64013 | E20: 4000 | F20: 58560.521 | G20: =IFERROR(F20/$F$24,0) -> 0.00022072844 | H20: Вспомогательные материалы
B21: Мешки 25 кг | C21: pcs | D21: =IFERROR(F21/E21,0) -> 0.23697446 | E21: 106260 | F21: 25180.906 | G21: =IFERROR(F21/$F$24,0) -> 9.4912784e-05 | H21: Вспомогательные материалы
B22: ВСЕГО В НАЦИОНАЛЬНОЙ ВАЛЮТЕ | F22: =SUM(F11:F21) -> 5805094.7 | G22: =IFERROR(F22/$F$24,0) -> 0.021880773
B24: ИТОГО СЫРЬЁ, МАТЕРИАЛЫ И ПРОЧИЕ ПЕРЕМЕННЫЕ ЗАТРАТЫ | F24: =F8+F22 -> 2.6530574e+08 | G24: =IFERROR(F24/$F$24,0) -> 1
B26: ПРОЧИЕ ПРОИЗВОДСТВЕННЫЕ РАСХОДЫ (постоянные)
B27: Статьи затрат | F27: Годовая стоимость, USD | H27: Состав затрат
B28: Ремонт и техническое обслуживание | F28: 945456.72 | H28: Ремонт СМР (0,5%); Ремонт оборудования (4%)
B29: Прочие производственные расходы (охрана труда, накладные и др.) | F29: 617586.5 | H29: Охрана труда; Прочие накладные СМР (0,5%); Прочие накладные оборудование (2%)
B30: Налог за пользование недрами (НДПИ) | F30: =CostSold!F19 -> 0
B31: Итого: | F31: =SUM(F28:F30) -> 1563043.2

Sheet Labour
B2: ЭНЕРГОРЕСУРСЫ И ОПЛАТА ТРУДА ПРИ ПРОЕКТНОЙ МОЩНОСТИ (в экв. долл. США) | G2: Приложение 8
B3: Расчёт на 3-й год.
B5: СТАТЬИ ЗАТРАТ | C5: Ед. изм. | D5: Годовая потребность | E5: Цена за единицу, USD | F5: Годовая стоимость, USD
B6: Электроэнергия - переменная часть 80% | C6: MWh | D6: 8388.832 | E6: =IFERROR(F6/D6,0) -> 112.58732 | F6: 944476.15
B7: Техническая вода - переменная часть 80% | C7: m3 | D7: 172529.28 | E7: =IFERROR(F7/D7,0) -> 0.63283144 | F7: 109181.95
B8: Природный газ - переменная часть 80% | C8: m3 | D8: 4675367.2 | E8: =IFERROR(F8/D8,0) -> 0.18890491 | F8: 883199.81
B9: Сброс сточных вод | C9: m3 | D9: 18463.472 | E9: =IFERROR(F9/D9,0) -> 0.48029244 | F9: 8867.866
B10: Электроэнергия - постоянная часть | F10: 236119.04
B11: Природный газ / топливо - постоянная часть | F11: 220799.95
B12: Вода - постоянная часть | F12: 27295.488
B13: ВСЕГО ЭНЕРГОРЕСУРСЫ | F13: =SUM(F6:F12) -> 2429940.3
B15: РАСЧЕТ ЗАРАБОТНОЙ ПЛАТЫ | F15: Ставка социального налога | G15: 0.12
B16: ПОКАЗАТЕЛИ | C16: Количество, чел. | D16: Среднемесячная з/плата на 1 чел., сум | E16: Среднемесячная з/плата на 1 чел., USD | F16: Годовой фонд з/платы, USD | G16: Отчисления (соц. налог), USD
B17: ПРОИЗВОДСТВЕННЫЙ ПЕРСОНАЛ
B18: Цех выщелачивания - начальник | C18: 1 | D18: 17835000 | E18: =IFERROR(F18/C18/12,0) -> 1609.0076 | F18: 19308.091 | G18: =F18*$G$15 -> 2316.9709
B19: Цех выщелачивания - операторы | C19: 16 | D19: 15457000 | E19: =IFERROR(F19/C19/12,0) -> 1394.4732 | F19: 267738.86 | G19: =F19*$G$15 -> 32128.663
B20: Цех ионного обмена - начальник | C20: 1 | D20: 17835000 | E20: =IFERROR(F20/C20/12,0) -> 1609.0076 | F20: 19308.091 | G20: =F20*$G$15 -> 2316.9709
B21: Операторы тонкой фильтрации | C21: 4 | D21: 15457000 | E21: =IFERROR(F21/C21/12,0) -> 1394.4732 | F21: 66934.714 | G21: =F21*$G$15 -> 8032.1657
B22: Операторы ионного обмена | C22: 8 | D22: 15457000 | E22: =IFERROR(F22/C22/12,0) -> 1394.4732 | F22: 133869.43 | G22: =F22*$G$15 -> 16064.331
B23: Операторы участка очистки | C23: 4 | D23: 15457000 | E23: =IFERROR(F23/C23/12,0) -> 1394.4732 | F23: 66934.714 | G23: =F23*$G$15 -> 8032.1657
B24: Цех APT и WO3 - руководитель | C24: 1 | D24: 17835000 | E24: =IFERROR(F24/C24/12,0) -> 1609.0076 | F24: 19308.091 | G24: =F24*$G$15 -> 2316.9709
B25: Выпаривание-кристаллизация | C25: 4 | D25: 15457000 | E25: =IFERROR(F25/C25/12,0) -> 1394.4732 | F25: 66934.714 | G25: =F25*$G$15 -> 8032.1657
B26: Фильтр-прессование и дробление | C26: 4 | D26: 15457000 | E26: =IFERROR(F26/C26/12,0) -> 1394.4732 | F26: 66934.714 | G26: =F26*$G$15 -> 8032.1657
B27: Пирометаллургия и очистка газов | C27: 8 | D27: 15457000 | E27: =IFERROR(F27/C27/12,0) -> 1394.4732 | F27: 133869.43 | G27: =F27*$G$15 -> 16064.331
B28: Очистка стоков - бригадир | C28: 1 | D28: 9512000 | E28: =IFERROR(F28/C28/12,0) -> 858.13736 | F28: 10297.648 | G28: =F28*$G$15 -> 1235.7178
B29: Очистка стоков - рабочие | C29: 8 | D29: 11592750 | E29: =IFERROR(F29/C29/12,0) -> 1045.8549 | F29: 100402.07 | G29: =F29*$G$15 -> 12048.249
... B37: Охрана | C37: 6 | D37: 8917500 | E37: =IFERROR(F37/C37/12,0) -> 804.50378 | F37: 57924.272 | G37: =F37*$G$15 -> 6950.9126
B38: ВСЕГО | C38: =SUM(C18:C37) -> 114 | F38: =SUM(F18:F37) -> 1524052 | G38: =SUM(G18:G37) -> 182886.23
B39: ИТОГО (фонд оплаты труда + социальный налог) | F39: =F38+G38 -> 1706938.2
B41: АДМИНИСТРАЦИЯ
B42: Генеральный директор | C42: 1 | D42: 35670000 | E42: =IFERROR(F42/C42/12,0) -> 3218.0151 | F42: 38616.181 | G42: =F42*$G$15 -> 4633.9418
B43: Заместитель ген. директора | C43: 1 | D43: 23780000 | E43: =IFERROR(F43/C43/12,0) -> 2145.3434 | F43: 25744.121 | G43: =F43*$G$15 -> 3089.2945
B44: Офисные служащие | C44: 2 | D44: 8323000 | E44: =IFERROR(F44/C44/12,0) -> 750.87019 | F44: 18020.885 | G44: =F44*$G$15 -> 2162.5062
B45: Руководитель финансового отдела | C45: 1 | D45: 14268000 | E45: =IFERROR(F45/C45/12,0) -> 1287.206 | F45: 15446.473 | G45: =F45*$G$15 -> 1853.5767
B46: Бухгалтер | C46: 1 | D46: 11890000 | E46: =IFERROR(F46/C46/12,0) -> 1072.6717 | F46: 12872.06 | G46: =F46*$G$15 -> 1544.6473
B47: Кассир | C47: 1 | D47: 8323000 | E47: =IFERROR(F47/C47/12,0) -> 750.87019 | F47: 9010.4423 | G47: =F47*$G$15 -> 1081.2531
B48: Руководитель отдела снабжения и сбыта | C48: 1 | D48: 14268000 | E48: =IFERROR(F48/C48/12,0) -> 1287.206 | F48: 15446.473 | G48: =F48*$G$15 -> 1853.5767
B49: Специалист по закупкам | C49: 1 | D49: 9512000 | E49: =IFERROR(F49/C49/12,0) -> 858.13736 | F49: 10297.648 | G49: =F49*$G$15 -> 1235.7178
B50: Специалист по сбыту | C50: 1 | D50: 9512000 | E50: =IFERROR(F50/C50/12,0) -> 858.13736 | F50: 10297.648 | G50: =F50*$G$15 -> 1235.7178
B51: Руководитель отдела кадров | C51: 1 | D51: 14268000 | E51: =IFERROR(F51/C51/12,0) -> 1287.206 | F51: 15446.473 | G51: =F51*$G$15 -> 1853.5767
...

Sheet Taxes
B2: НАЛОГИ И СБОРЫ (в экв. долл. США) | K2: Приложение 9
B4: ПОКАЗАТЕЛИ | C4: Ставка | D4: 1 год (льготный период) | E4: 2 год | F4: 3 год | G4: 4 год | H4: 5 год | I4: 6 год | J4: 7 год
B6: Налоги и сборы, включаемые в расходы | D6: =SUM(D7:D11) -> 187328.59 | E6: =SUM(E7:E11) -> 632638.68 | F6: =SUM(F7:F11) -> 628878.65 | G6: =SUM(G7:G11) -> 625244.72 | H6: =SUM(H7:H11) -> 621720.33 | I6: =SUM(I7:I11) -> 618305.8 | J6: =SUM(J7:J11) -> 615003.57
B7: Налог на имущество | C7: 1.50% | D7: =CostSold!D35 -> 106126.31 | E7: =CostSold!E35 -> 415276.88 | F7: =CostSold!F35 -> 406758.38 | G7: =CostSold!G35 -> 398239.88 | H7: =CostSold!H35 -> 389721.38 | I7: =CostSold!I35 -> 381202.88 | J7: =CostSold!J35 -> 372684.38
B8: Земельный налог | D8: =CostSold!D36 -> 0 | E8: =CostSold!E36 -> 0 | F8: =CostSold!F36 -> 0 | G8: =CostSold!G36 -> 0 | H8: =CostSold!H36 -> 0 | I8: =CostSold!I36 -> 0 | J8: =CostSold!J36 -> 0
B9: Специальный рентный налог | D9: =CostSold!D37 -> 0 | E9: =CostSold!E37 -> 0 | F9: =CostSold!F37 -> 0 | G9: =CostSold!G37 -> 0 | H9: =CostSold!H37 -> 0 | I9: =CostSold!I37 -> 0 | J9: =CostSold!J37 -> 0
B10: Налог за пользование недрами (НДПИ) - в себестоимости | D10: =CostSold!D19 -> 0 | E10: =CostSold!E19 -> 0 | F10: =CostSold!F19 -> 0 | G10: =CostSold!G19 -> 0 | H10: =CostSold!H19 -> 0 | I10: =CostSold!I19 -> 0 | J10: =CostSold!J19 -> 0
B11: Социальный налог (производственный и административный персонал) | C11: 12% | D11: 81202.279 | E11: 217361.81 | F11: 222120.27 | G11: 227004.84 | H11: 231998.95 | I11: 237102.93 | J11: 242319.19
B13: Прочие налоги | D13: =D14+D15 -> 516650.54 | E13: =E14+E15 -> 2852208.2 | F13: =F14+F15 -> 3693447.6 | G13: =G14+G15 -> 4030058 | H13: =H14+H15 -> 4155383.3 | I13: =I14+I15 -> 4283150.4 | J13: =J14+J15 -> 4414572.5
B14: Налог на прибыль (Приложение 13) | D14: =ProfLoss!D21 -> 516650.54 | E14: =ProfLoss!E21 -> 2852208.2 | F14: =ProfLoss!F21 -> 3693447.6 | G14: =ProfLoss!G21 -> 4030058 | H14: =ProfLoss!H21 -> 4155383.3 | I14: =ProfLoss!I21 -> 4283150.4 | J14: =ProfLoss!J21 -> 4414572.5
B15: НДС к уплате в бюджет (при превышении входящего НДС - к возмещению, см. ниже) | C15: 12% | D15: =MAX(0,D22) -> 0 | E15: =MAX(0,E22) -> 0 | F15: =MAX(0,F22) -> 0 | G15: =MAX(0,G22) -> 0 | H15: =MAX(0,H22) -> 0 | I15: =MAX(0,I22) -> 0 | J15: =MAX(0,J22) -> 0
B16: ВСЕГО НАЛОГОВ И ОТЧИСЛЕНИЙ | D16: =D6+D13 -> 703979.13 | E16: =E6+E13 -> 3484846.8 | F16: =F6+F13 -> 4322326.2 | G16: =G6+G13 -> 4655302.7 | H16: =H6+H13 -> 4777103.6 | I16: =I6+I13 -> 4901456.2 | J16: =J6+J13 -> 5029576.1
B18: Расчет НДС
B19: НДС исходящий (реализация на внутреннем рынке; экспорт - 0%) | D19: 0 | E19: 0 | F19: 0 | G19: 0 | H19: 0 | I19: 0 | J19: 0
B20: НДС входящий - по операционным затратам | D20: 3507350.7 | E20: 26814175 | F20: 32950208 | G20: 33677557 | H20: 34418463 | I20: 35175669 | J20: 35949534
B21: НДС входящий - по капитальным вложениям (1-й год вкл. подготовительный период) | D21: 5731360.5 | E21: 57170.679 | F21: 57170.679 | G21: 57170.679 | H21: 57170.679 | I21: 57170.679 | J21: 57170.679
B22: НДС к уплате (+) / к возмещению из бюджета (-) | D22: =D19-D20-D21 -> -9238711.2 | E22: =E19-E20-E21 -> -26871346 | F22: =F19-F20-F21 -> -33007379 | G22: =G19-G20-G21 -> -33734727 | H22: =H19-H20-H21 -> -34475634 | I22: =I19-I20-I21 -> -35232840 | J22: =J19-J20-J21 -> -36006705
B24: Расчет налога на прибыль
B25: Прибыль (убыток) до налогообложения (Приложение 13) | D25: =ProfLoss!D20 -> 3444336.9 | E25: =ProfLoss!E20 -> 19014721 | F25: =ProfLoss!F20 -> 24622984 | G25: =ProfLoss!G20 -> 26867053 | H25: =ProfLoss!H20 -> 27702555 | I25: =ProfLoss!I20 -> 28554336 | J25: =ProfLoss!J20 -> 29430483
B26: Налоговые корректировки | D26: 0 | E26: 0 | F26: 0 | G26: 0 | H26: 0 | I26: 0 | J26: 0
B27: Налогооблагаемая прибыль | D27: =D25+D26 -> 3444336.9 | E27: =E25+E26 -> 19014721 | F27: =F25+F26 -> 24622984 | G27: =G25+G26 -> 26867053 | H27: =H25+H26 -> 27702555 | I27: =I25+I26 -> 28554336 | J27: =J25+J26 -> 29430483
B28: Ставка налога на прибыль | C28: % | D28: 0.15 | E28: 0.15 | F28: 0.15 | G28: 0.15 | H28: 0.15 | I28: 0.15 | J28: 0.15
B29: Налог на прибыль | D29: =D27*D28 -> 516650.54 | E29: =E27*E28 -> 2852208.2 | F29: =F27*F28 -> 3693447.6 | G29: =G27*G28 -> 4030058 | H29: =H27*H28 -> 4155383.3 | I29: =I27*I28 -> 4283150.4 | J29: =J27*J28 -> 4414572.5

Sheet CostTotal
B2: СТОИМОСТЬ ПРОДУКЦИИ ПРИ ПРОЕКТНОЙ МОЩНОСТИ (в экв. долл. США) | H2: Приложение 10
B3: Расчёт на 3-й год; разделение на постоянные и переменные затраты.
B5: Статьи издержек | C5: Всего стоимость | D5: Доля постоянных затрат (%) | E5: Доля переменных затрат (%) | F5: Фиксированная стоимость | G5: Переменная стоимость
B6: Сырьё, материалы и прочие переменные затраты | C6: =C7+C8 -> 2.6530574e+08 | D6: =IFERROR(F6/C6,0) -> 0 | E6: =IFERROR(G6/C6,0) -> 1 | F6: =F7+F8 -> 0 | G6: =G7+G8 -> 2.6530574e+08
B7: с ценой в твёрдой валюте (USD) | C7: =F7+G7 -> 2.5950064e+08 | D7: =IFERROR(F7/C7,0) -> 0 | E7: =IFERROR(G7/C7,0) -> 1 | F7: 0 | G7: =RawMat!F8 -> 2.5950064e+08
B8: с ценой в национальной валюте | C8: =F8+G8 -> 5805094.7 | D8: =IFERROR(F8/C8,0) -> 0 | E8: =IFERROR(G8/C8,0) -> 1 | F8: 0 | G8: =RawMat!F22 -> 5805094.7
B9: Энергоресурсы (электроэнергия, газ, вода) | C9: =F9+G9 -> 2429940.3 | D9: =IFERROR(F9/C9,0) -> 0.19927012 | E9: =IFERROR(G9/C9,0) -> 0.80072988 | F9: =SUM(Labour!F10:F12) -> 484214.48 | G9: =SUM(Labour!F6:F9) -> 1945725.8
B10: Зарплата производственного персонала (с соц. налогом) | C10: =F10+G10 -> 1706938.2 | D10: =IFERROR(F10/C10,0) -> 1 | E10: =IFERROR(G10/C10,0) -> 0 | F10: =Labour!F39 -> 1706938.2 | G10: 0
B11: Зарплата административного персонала (с соц. налогом) | C11: =F11+G11 -> 366184.37 | D11: =IFERROR(F11/C11,0) -> 1 | E11: =IFERROR(G11/C11,0) -> 0 | F11: =Labour!F61 -> 366184.37 | G11: 0
B12: Ремонт и техническое обслуживание (постоянная часть) | C12: =F12+G12 -> 945456.72 | D12: =IFERROR(F12/C12,0) -> 1 | E12: =IFERROR(G12/C12,0) -> 0 | F12: =RawMat!F28 -> 945456.72 | G12: 0
B13: Прочие производственные расходы (постоянная часть) | C13: =F13+G13 -> 617586.5 | D13: =IFERROR(F13/C13,0) -> 1 | E13: =IFERROR(G13/C13,0) -> 0 | F13: =RawMat!F29 -> 617586.5 | G13: 0
B14: Налог за пользование недрами (НДПИ) | C14: =F14+G14 -> 0 | D14: =IFERROR(F14/C14,0) -> 0 | E14: =IFERROR(G14/C14,0) -> 0 | F14: 0 | G14: =RawMat!F30 -> 0
B15: Административные расходы (без персонала и амортизации) | C15: =F15+G15 -> 3712123.4 | D15: =IFERROR(F15/C15,0) -> 0.69006913 | E15: =IFERROR(G15/C15,0) -> 0.30993087 | F15: 2561621.8 | G15: 1150501.6
B16: Коммерческие расходы | C16: =F16+G16 -> 1539598 | D16: =IFERROR(F16/C16,0) -> 0 | E16: =IFERROR(G16/C16,0) -> 1 | F16: 0 | G16: =CostSold!F31 -> 1539598
B17: Налог на имущество и земельный налог | C17: =F17+G17 -> 406758.38 | D17: =IFERROR(F17/C17,0) -> 1 | E17: =IFERROR(G17/C17,0) -> 0 | F17: =CostSold!F35+CostSold!F36 -> 406758.38 | G17: 0
B18: Специальный рентный налог | C18: =F18+G18 -> 0 | D18: =IFERROR(F18/C18,0) -> 0 | E18: =IFERROR(G18/C18,0) -> 0 | F18: 0 | G18: =CostSold!F37 -> 0
B19: Резерв на непредвиденные операционные расходы | C19: =F19+G19 -> 5532471.3 | D19: =IFERROR(F19/C19,0) -> 0 | E19: =IFERROR(G19/C19,0) -> 1 | F19: 0 | G19: =CostSold!F38 -> 5532471.3
B20: Прочие операционные расходы / (доходы) | C20: =F20+G20 -> 0 | D20: =IFERROR(F20/C20,0) -> 0 | E20: =IFERROR(G20/C20,0) -> 0 | F20: =CostSold!F39 -> 0 | G20: 0
B21: Амортизация (Приложение 4) | C21: =F21+G21 -> 2593626.1 | D21: =IFERROR(F21/C21,0) -> 1 | E21: =IFERROR(G21/C21,0) -> 0 | F21: =Depreciate!I21 -> 2593626.1 | G21: 0
B22: ИТОГО | C22: =SUM(C6:C21)-C6 -> 2.8515642e+08 | D22: =IFERROR(F22/C22,0) -> 0.03395465 | E22: =IFERROR(G22/C22,0) -> 0.96604535 | F22: =SUM(F6:F21)-F6 -> 9682386.6 | G22: =SUM(G6:G21)-G6 -> 2.7547403e+08
B23: в т.ч. в местной валюте | C23: =C22-C24 -> 24201325
B24: в т.ч. в твёрдой валюте (производственные затраты в USD) | C24: 2.609551e+08
B26: Выручка при проектной мощности | C26: =SalePlan!F14 -> 3.079196e+08
B27: Затраты на 1 USD выручки | C27: =IFERROR(C22/C26,0) -> 0.92607428
B28: Полная себестоимость единицы основной продукции, USD/t | C28: =IFERROR(C22/ProdPlan!F13,0) -> 107342.9

Sheet CostSold
B2: ГОДОВАЯ СТОИМОСТЬ ПРОДАННОЙ ПРОДУКЦИИ (в экв. долл. США) | K2: Приложение 11
B4: ПОКАЗАТЕЛИ | C4: Ед. изм. | D4: 1 год (льготный период) | E4: 2 год | F4: 3 год | G4: 4 год | H4: 5 год | I4: 6 год | J4: 7 год
B6: Освоение мощностей (основная продукция) | C6: % | D6: =ProdPlan!D11 -> 0.10163749 | E6: =ProdPlan!E11 -> 0.82971014 | F6: =ProdPlan!F11 -> 1 | G6: =ProdPlan!G11 -> 1 | H6: =ProdPlan!H11 -> 1 | I6: =ProdPlan!I11 -> 1 | J6: =ProdPlan!J11 -> 1
B8: ПРОИЗВОДСТВЕННАЯ СЕБЕСТОИМОСТЬ ПО ЭЛЕМЕНТАМ
B9: Сырьё | C9: USD | D9: 25462057 | E9: 2.1067546e+08 | F9: 2.5950064e+08 | G9: 2.6520966e+08 | H9: 2.7104427e+08 | I9: 2.7700724e+08 | J9: 2.831014e+08
B10: Вспомогательные материалы | C10: USD | D10: 569592.63 | E10: 4712863 | F10: 5805094.7 | G10: 5932806.8 | H10: 6063328.5 | I10: 6196721.8 | J10: 6333049.6
B11: Электроэнергия | C11: USD | D11: 149650.33 | E11: 997808.69 | F11: 1180595.2 | G11: 1206568.3 | H11: 1233112.8 | I11: 1260241.3 | J11: 1287966.6
B12: Природный газ / топливо | C12: USD | D12: 139941.22 | E12: 933072.2 | F12: 1103999.8 | G12: 1128287.8 | H12: 1153110.1 | I12: 1178478.5 | J12: 1204405
B13: Вода | C13: USD | D13: 18169.769 | E13: 122546.59 | F13: 145345.31 | G13: 148542.9 | H13: 151810.85 | I13: 155150.69 | J13: 158564
B14: Заработная плата | C14: USD | D14: 361689.03 | E14: 1491402.3 | F14: 1524052 | G14: 1557566.9 | H14: 1591833.3 | I14: 1626853.7 | J14: 1662644.4
B15: Социальный налог | C15: USD | D15: 43402.684 | E15: 178968.28 | F15: 182886.23 | G15: 186908.02 | H15: 191020 | I15: 195222.44 | J15: 199517.33
B16: Амортизация (Приложение 4) | C16: USD | D16: =Depreciate!$G$22 -> 620914.3 | E16: =Depreciate!$H$22 -> 2535269.6 | F16: =Depreciate!$I$22 -> 2582911.8 | G16: =Depreciate!$J$22 -> 2630554.1 | H16: =Depreciate!$K$22 -> 2678196.3 | I16: =Depreciate!$L$22 -> 2725838.5 | J16: =Depreciate!$M$22 -> 2773480.8
B17: Ремонт и техобслуживание | C17: USD | D17: 92767.682 | E17: 767568.53 | F17: 945456.72 | G17: 966256.77 | H17: 987514.42 | I17: 1009239.7 | J17: 1031443
B18: Прочие производственные расходы (без НДПИ) | C18: USD | D18: 60597.24 | E18: 501387.26 | F18: 617586.5 | G18: 631173.4 | H18: 645059.22 | I18: 659250.52 | J18: 673754.03
B19: Налог за пользование недрами (НДПИ) | C19: USD | D19: 0 | E19: 0 | F19: 0 | G19: 0 | H19: 0 | I19: 0 | J19: 0
B20: Себестоимость произведенной продукции | C20: USD | D20: =SUM(D9:D19) -> 27518782 | E20: =SUM(E9:E19) -> 2.2291634e+08 | F20: =SUM(F9:F19) -> 2.7358857e+08 | G20: =SUM(G9:G19) -> 2.7959832e+08 | H20: =SUM(H9:H19) -> 2.8573925e+08 | I20: =SUM(I9:I19) -> 2.9201424e+08 | J20: =SUM(J9:J19) -> 2.9842623e+08
B21: Изменение остатков готовой продукции (- прирост запаса) | C21: USD | D21: -6425081.9 | E21: -5650593.3 | F21: -2773949.9 | G21: -326690.88 | H21: -333878.95 | I21: -341224.29 | J21: -348731.22
B22: Себестоимость реализованной продукции | C22: USD | D22: =D20+D21 -> 21093700 | E22: =E20+E21 -> 2.1726575e+08 | F22: =F20+F21 -> 2.7081462e+08 | G22: =G20+G21 -> 2.7927163e+08 | H22: =H20+H21 -> 2.8540538e+08 | I22: =I20+I21 -> 2.9167302e+08 | J22: =J20+J21 -> 2.980775e+08
B23: Доля затрат в твёрдой валюте (USD) в денежной себестоимости | C23: % | D23: 0.95211461 | E23: 0.96143498 | F23: 0.96291383 | G23: 0.96279906 | H23: 0.9626867 | I23: 0.96257677 | J23: 0.9624692
B24: в т.ч. затраты в твёрдой валюте (USD) | C24: USD | D24: =D22*D23 -> 20083620 | E24: =E22*E23 -> 2.0888689e+08 | F24: =F22*F23 -> 2.6077114e+08 | G24: =G22*G23 -> 2.6888246e+08 | H24: =H22*H23 -> 2.7475596e+08 | I24: =I22*I23 -> 2.8075767e+08 | J24: =J22*J23 -> 2.8689041e+08
B25: в т.ч. затраты в национальной валюте | C25: USD | D25: =D22-D24 -> 1010080 | E25: =E22-E24 -> 8378858 | F25: =F22-F24 -> 10043478 | G25: =G22-G24 -> 10389168 | H25: =H22-H24 -> 10649416 | I25: =I22-I24 -> 10915347 | J25: =J22-J24 -> 11187087
B27: РАСХОДЫ ПЕРИОДА
B28: Зарплата административного персонала (с соц. налогом) | C28: USD | D28: 352796.23 | E28: 358339.63 | F28: 366184.37 | G28: 374237.01 | H28: 382470.22 | I28: 390884.57 | J28: 399484.03
B29: Амортизация административных активов | C29: USD | D29: =Depreciate!$G$23 -> 2678.5714 | E29: =Depreciate!$H$23 -> 10714.286 | F29: =Depreciate!$I$23 -> 10714.286 | G29: =Depreciate!$J$23 -> 10714.286 | H29: =Depreciate!$K$23 -> 10714.286 | I29: =Depreciate!$L$23 -> 8035.7143 | J29: =Depreciate!$M$23 -> 0
B30: Прочие административные расходы (аренда, налог за воду, прочие) | C30: USD | D30: 2590303.2 | E30: 3475906.7 | F30: 3712123.4 | G30: 3793788.6 | H30: 3877251.9 | I30: 3962551.4 | J30: 4049727.6
B31: Коммерческие расходы (расходы по реализации) | C31: USD | D31: 141656.25 | E31: 1237027.8 | F31: 1539598 | G31: 1593382 | H31: 1628434.5 | I31: 1664257.4 | J31: 1700877.3
B32: Итого расходы периода | C32: USD | D32: =SUM(D28:D31) -> 3087434.2 | E32: =SUM(E28:E31) -> 5081988.4 | F32: =SUM(F28:F31) -> 5628620.1 | G32: =SUM(G28:G31) -> 5772121.8 | H32: =SUM(H28:H31) -> 5898870.9 | I32: =SUM(I28:I31) -> 6025729.1 | J32: =SUM(J28:J31) -> 6150088.9
B34: НАЛОГИ И ПРОЧИЕ ОПЕРАЦИОННЫЕ РАСХОДЫ
B35: Налог на имущество | C35: USD | D35: 106126.31 | E35: 415276.88 | F35: 406758.38 | G35: 398239.88 | H35: 389721.38 | I35: 381202.88 | J35: 372684.38
B36: Земельный налог | C36: USD | D36: 0 | E36: 0 | F36: 0 | G36: 0 | H36: 0 | I36: 0 | J36: 0
B37: Специальный рентный налог | C37: USD | D37: 0 | E37: 0 | F37: 0 | G37: 0 | H37: 0 | I37: 0 | J37: 0
B38: Резерв на непредвиденные операционные расходы | C38: USD | D38: 599652.47 | E38: 4509046.9 | F38: 5532471.3 | G38: 5654583.5 | H38: 5778984.3 | I38: 5906121.9 | J38: 6036056.7
B39: Прочие операционные расходы / (доходы) | C39: USD | D39: 0 | E39: 0 | F39: 0 | G39: 0 | H39: 0 | I39: 0 | J39: 0
B40: Итого налоги и прочие операционные расходы | C40: USD | D40: =SUM(D35:D39) -> 705778.78 | E40: =SUM(E35:E39) -> 4924323.8 | F40: =SUM(F35:F39) -> 5939229.7 | G40: =SUM(G35:G39) -> 6052823.4 | H40: =SUM(H35:H39) -> 6168705.7 | I40: =SUM(I35:I39) -> 6287324.8 | J40: =SUM(J35:J39) -> 6408741.1
B42: ФИНАНСОВЫЕ ИЗДЕРЖКИ
B43: Проценты за кредит (1-й год - капитализированы, оплачены за счёт собственных средств) | C43: USD | D43: 0 | E43: =LOANS!$D$106 -> 1118782.2 | F43: =LOANS!$E$106 -> 914142.62 | G43: =LOANS!$F$106 -> 712767.34 | H43: =LOANS!$G$106 -> 511392.06 | I43: =LOANS!$H$106 -> 311074.23 | J43: =LOANS!$I$106 -> 108641.5
B45: ПОЛНАЯ СТОИМОСТЬ ПРОДАННОЙ ПРОДУКЦИИ | C45: USD | D45: =D22+D32+D40+D43 -> 24886913 | E45: =E22+E32+E40+E43 -> 2.2839084e+08 | F45: =F22+F32+F40+F43 -> 2.8329661e+08 | G45: =G22+G32+G40+G43 -> 2.9180934e+08 | H45: =H22+H32+H40+H43 -> 2.9798434e+08 | I45: =I22+I32+I40+I43 -> 3.0429714e+08 | J45: =J22+J32+J40+J43 -> 3.1074497e+08
B46: Полная себестоимость единицы основной продукции | C46: USD/t | D46: =IFERROR(D45/(ProdPlan!D15+ProdPlan!D16),0) -> 99547.652 | E46: =IFERROR(E45/(ProdPlan!E15+ProdPlan!E16),0) -> 106024.88 | F46: =IFERROR(F45/(ProdPlan!F15+ProdPlan!F16),0) -> 107992.71 | G46: =IFERROR(G45/(ProdPlan!G15+ProdPlan!G16),0) -> 109847.3 | H46: =IFERROR(H45/(ProdPlan!H15+ProdPlan!H16),0) -> 112171.78 | I46: =IFERROR(I45/(ProdPlan!I15+ProdPlan!I16),0) -> 114548.14 | J46: =IFERROR(J45/(ProdPlan!J15+ProdPlan!J16),0) -> 116975.33

Sheet LOANS
B2: СХЕМА ВЫПЛАТЫ КРЕДИТА (в долл. США) | H2: Приложение 12
B5: Срок кредита | C5: =ИНФОРМАЦИЯ!$C$28 -> 84 | D5: месяцев
B6: Льготный период | C6: =ИНФОРМАЦИЯ!$C$29 -> 12 | D6: месяцев
B7: Инвестиционный период | C7: =ИНФОРМАЦИЯ!$C$30 -> 12 | D7: месяцев
B8: Процентная ставка | C8: =ИНФОРМАЦИЯ!$C$27 -> 0.07 | D8: годовых
B9: Сумма кредита | C9: =ИНФОРМАЦИЯ!$C$26 -> 17024290 | D9: USD
B10: Дата выдачи | C10: =ИНФОРМАЦИЯ!$C$31 -> 46388
B11: База начисления процентов | C11: =ИНФОРМАЦИЯ!$C$32 -> 360 | D11: дней
B12: Количество платежей по основному долгу | C12: =C5-C6 -> 72 | D12: платежей
B13: Ежемесячный платёж по основному долгу | C13: =C9/C12 -> 236448.47 | D13: USD
A15: № | B15: Дата платежа | C15: Остаток на начало | D15: Погашение основного долга | E15: Проценты | F15: Всего выплат | G15: Остаток на конец | H15: № года
A16: 1 | B16: =EOMONTH($C$10,0) -> 46418 | C16: =$C$9 -> 17024290 | D16: =IF(A16>$C$6,MIN(C16,$C$13),0) -> 0 | E16: =C16*$C$8*DAY(B16)/$C$11 -> 102618.64 | F16: =D16+E16 -> 102618.64 | G16: =C16-D16 -> 17024290 | H16: =YEAR(B16)-YEAR($C$10)+1 -> 1
A17: 2 | B17: =EOMONTH($C$10,1) -> 46446 | C17: =G16 -> 17024290 | D17: =IF(A17>$C$6,MIN(C17,$C$13),0) -> 0 | E17: =C17*$C$8*DAY(B17)/$C$11 -> 92687.799 | F17: =D17+E17 -> 92687.799 | G17: =C17-D17 -> 17024290 | H17: =YEAR(B17)-YEAR($C$10)+1 -> 1
A18: 3 | B18: =EOMONTH($C$10,2) -> 46477 | C18: =G17 -> 17024290 | D18: =IF(A18>$C$6,MIN(C18,$C$13),0) -> 0 | E18: =C18*$C$8*DAY(B18)/$C$11 -> 102618.64 | F18: =D18+E18 -> 102618.64 | G18: =C18-D18 -> 17024290 | H18: =YEAR(B18)-YEAR($C$10)+1 -> 1
A19: 4 | B19: =EOMONTH($C$10,3) -> 46507 | C19: =G18 -> 17024290 | D19: =IF(A19>$C$6,MIN(C19,$C$13),0) -> 0 | E19: =C19*$C$8*DAY(B19)/$C$11 -> 99308.357 | F19: =D19+E19 -> 99308.357 | G19: =C19-D19 -> 17024290 | H19: =YEAR(B19)-YEAR($C$10)+1 -> 1
A20: 5 | B20: =EOMONTH($C$10,4) -> 46538 | C20: =G19 -> 17024290 | D20: =IF(A20>$C$6,MIN(C20,$C$13),0) -> 0 | E20: =C20*$C$8*DAY(B20)/$C$11 -> 102618.64 | F20: =D20+E20 -> 102618.64 | G20: =C20-D20 -> 17024290 | H20: =YEAR(B20)-YEAR($C$10)+1 -> 1
A21: 6 | B21: =EOMONTH($C$10,5) -> 46568 | C21: =G20 -> 17024290 | D21: =IF(A21>$C$6,MIN(C21,$C$13),0) -> 0 | E21: =C21*$C$8*DAY(B21)/$C$11 -> 99308.357 | F21: =D21+E21 -> 99308.357 | G21: =C21-D21 -> 17024290 | H21: =YEAR(B21)-YEAR($C$10)+1 -> 1
A22: 7 | B22: =EOMONTH($C$10,6) -> 46599 | C22: =G21 -> 17024290 | D22: =IF(A22>$C$6,MIN(C22,$C$13),0) -> 0 | E22: =C22*$C$8*DAY(B22)/$C$11 -> 102618.64 | F22: =D22+E22 -> 102618.64 | G22: =C22-D22 -> 17024290 | H22: =YEAR(B22)-YEAR($C$10)+1 -> 1
A23: 8 | B23: =EOMONTH($C$10,7) -> 46630 | C23: =G22 -> 17024290 | D23: =IF(A23>$C$6,MIN(C23,$C$13),0) -> 0 | E23: =C23*$C$8*DAY(B23)/$C$11 -> 102618.64 | F23: =D23+E23 -> 102618.64 | G23: =C23-D23 -> 17024290 | H23: =YEAR(B23)-YEAR($C$10)+1 -> 1
A24: 9 | B24: =EOMONTH($C$10,8) -> 46660 | C24: =G23 -> 17024290 | D24: =IF(A24>$C$6,MIN(C24,$C$13),0) -> 0 | E24: =C24*$C$8*DAY(B24)/$C$11 -> 99308.357 | F24: =D24+E24 -> 99308.357 | G24: =C24-D24 -> 17024290 | H24: =YEAR(B24)-YEAR($C$10)+1 -> 1
A25: 10 | B25: =EOMONTH($C$10,9) -> 46691 | C25: =G24 -> 17024290 | D25: =IF(A25>$C$6,MIN(C25,$C$13),0) -> 0 | E25: =C25*$C$8*DAY(B25)/$C$11 -> 102618.64 | F25: =D25+E25 -> 102618.64 | G25: =C25-D25 -> 17024290 | H25: =YEAR(B25)-YEAR($C$10)+1 -> 1
A26: 11 | B26: =EOMONTH($C$10,10) -> 46721 | C26: =G25 -> 17024290 | D26: =IF(A26>$C$6,MIN(C26,$C$13),0) -> 0 | E26: =C26*$C$8*DAY(B26)/$C$11 -> 99308.357 | F26: =D26+E26 -> 99308.357 | G26: =C26-D26 -> 17024290 | H26: =YEAR(B26)-YEAR($C$10)+1 -> 1
A27: 12 | B27: =EOMONTH($C$10,11) -> 46752 | C27: =G26 -> 17024290 | D27: =IF(A27>$C$6,MIN(C27,$C$13),0) -> 0 | E27: =C27*$C$8*DAY(B27)/$C$11 -> 102618.64 | F27: =D27+E27 -> 102618.64 | G27: =C27-D27 -> 17024290 | H27: =YEAR(B27)-YEAR($C$10)+1 -> 1
A28: 13 | B28: =EOMONTH($C$10,12) -> 46783 | C28: =G27 -> 17024290 | D28: =IF(A28>$C$6,MIN(C28,$C$13),0) -> 236448.47 | E28: =C28*$C$8*DAY(B28)/$C$11 -> 102618.64 | F28: =D28+E28 -> 339067.1 | G28: =C28-D28 -> 16787841 | H28: =YEAR(B28)-YEAR($C$10)+1 -> 2
A29: 14 | B29: =EOMONTH($C$10,13) -> 46812 | C29: =G28 -> 16787841 | D29: =IF(A29>$C$6,MIN(C29,$C$13),0) -> 236448.47 | E29: =C29*$C$8*DAY(B29)/$C$11 -> 94664.771 | F29: =D29+E29 -> 331113.24 | G29: =C29-D29 -> 16551393 | H29: =YEAR(B29)-YEAR($C$10)+1 -> 2
A30: 15 | B30: =EOMONTH($C$10,14) -> 46843 | C30: =G29 -> 16551393 | D30: =IF(A30>$C$6,MIN(C30,$C$13),0) -> 236448.47 | E30: =C30*$C$8*DAY(B30)/$C$11 -> 99768.117 | F30: =D30+E30 -> 336216.59 | G30: =C30-D30 -> 16314944 | H30: =YEAR(B30)-YEAR($C$10)+1 -> 2
A31: 16 | B31: =EOMONTH($C$10,15) -> 46873 | C31: =G30 -> 16314944 | D31: =IF(A31>$C$6,MIN(C31,$C$13),0) -> 236448.47 | E31: =C31*$C$8*DAY(B31)/$C$11 -> 95170.508 | F31: =D31+E31 -> 331618.98 | G31: =C31-D31 -> 16078496 | H31: =YEAR(B31)-YEAR($C$10)+1 -> 2
A32: 17 | B32: =EOMONTH($C$10,16) -> 46904 | C32: =G31 -> 16078496 | D32: =IF(A32>$C$6,MIN(C32,$C$13),0) -> 236448.47 | E32: =C32*$C$8*DAY(B32)/$C$11 -> 96917.6 | F32: =D32+E32 -> 333366.07 | G32: =C32-D32 -> 15842047 | H32: =YEAR(B32)-YEAR($C$10)+1 -> 2
A33: 18 | B33: =EOMONTH($C$10,17) -> 46934 | C33: =G32 -> 15842047 | D33: =IF(A33>$C$6,MIN(C33,$C$13),0) -> 236448.47 | E33: =C33*$C$8*DAY(B33)/$C$11 -> 92411.943 | F33: =D33+E33 -> 328860.41 | G33: =C33-D33 -> 15605599 | H33: =YEAR(B33)-YEAR($C$10)+1 -> 2
A34: 19 | B34: =EOMONTH($C$10,18) -> 46965 | C34: =G33 -> 15605599 | D34: =IF(A34>$C$6,MIN(C34,$C$13),0) -> 236448.47 | E34: =C34*$C$8*DAY(B34)/$C$11 -> 94067.082 | F34: =D34+E34 -> 330515.55 | G34: =C34-D34 -> 15369150 | H34: =YEAR(B34)-YEAR($C$10)+1 -> 2
A35: 20 | B35: =EOMONTH($C$10,19) -> 46996 | C35: =G34 -> 15369150 | D35: =IF(A35>$C$6,MIN(C35,$C$13),0) -> 236448.47 | E35: =C35*$C$8*DAY(B35)/$C$11 -> 92641.823 | F35: =D35+E35 -> 329090.29 | G35: =C35-D35 -> 15132702 | H35: =YEAR(B35)-YEAR($C$10)+1 -> 2
A36: 21 | B36: =EOMONTH($C$10,20) -> 47026 | C36: =G35 -> 15132702 | D36: =IF(A36>$C$6,MIN(C36,$C$13),0) -> 236448.47 | E36: =C36*$C$8*DAY(B36)/$C$11 -> 88274.095 | F36: =D36+E36 -> 324722.56 | G36: =C36-D36 -> 14896253 | H36: =YEAR(B36)-YEAR($C$10)+1 -> 2
A37: 22 | B37: =EOMONTH($C$10,21) -> 47057 | C37: =G36 -> 14896253 | D37: =IF(A37>$C$6,MIN(C37,$C$13),0) -> 236448.47 | E37: =C37*$C$8*DAY(B37)/$C$11 -> 89791.306 | F37: =D37+E37 -> 326239.77 | G37: =C37-D37 -> 14659805 | H37: =YEAR(B37)-YEAR($C$10)+1 -> 2
A38: 23 | B38: =EOMONTH($C$10,22) -> 47087 | C38: =G37 -> 14659805 | D38: =IF(A38>$C$6,MIN(C38,$C$13),0) -> 236448.47 | E38: =C38*$C$8*DAY(B38)/$C$11 -> 85515.529 | F38: =D38+E38 -> 321964 | G38: =C38-D38 -> 14423357 | H38: =YEAR(B38)-YEAR($C$10)+1 -> 2
A39: 24 | B39: =EOMONTH($C$10,23) -> 47118 | C39: =G38 -> 14423357 | D39: =IF(A39>$C$6,MIN(C39,$C$13),0) -> 236448.47 | E39: =C39*$C$8*DAY(B39)/$C$11 -> 86940.788 | F39: =D39+E39 -> 323389.26 | G39: =C39-D39 -> 14186908 | H39: =YEAR(B39)-YEAR($C$10)+1 -> 2
A40: 25 | B40: =EOMONTH($C$10,24) -> 47149 | C40: =G39 -> 14186908 | D40: =IF(A40>$C$6,MIN(C40,$C$13),0) -> 236448.47 | E40: =C40*$C$8*DAY(B40)/$C$11 -> 85515.529 | F40: =D40+E40 -> 321964 | G40: =C40-D40 -> 13950460 | H40: =YEAR(B40)-YEAR($C$10)+1 -> 3
A41: 26 | B41: =EOMONTH($C$10,25) -> 47177 | C41: =G40 -> 13950460 | D41: =IF(A41>$C$6,MIN(C41,$C$13),0) -> 236448.47 | E41: =C41*$C$8*DAY(B41)/$C$11 -> 75952.502 | F41: =D41+E41 -> 312400.97 | G41: =C41-D41 -> 13714011 | H41: =YEAR(B41)-YEAR($C$10)+1 -> 3
A42: 27 | B42: =EOMONTH($C$10,26) -> 47208 | C42: =G41 -> 13714011 | D42: =IF(A42>$C$6,MIN(C42,$C$13),0) -> 236448.47 | E42: =C42*$C$8*DAY(B42)/$C$11 -> 82665.012 | F42: =D42+E42 -> 319113.48 | G42: =C42-D42 -> 13477563 | H42: =YEAR(B42)-YEAR($C$10)+1 -> 3
A43: 28 | B43: =EOMONTH($C$10,27) -> 47238 | C43: =G42 -> 13477563 | D43: =IF(A43>$C$6,MIN(C43,$C$13),0) -> 236448.47 | E43: =C43*$C$8*DAY(B43)/$C$11 -> 78619.116 | F43: =D43+E43 -> 315067.58 | G43: =C43-D43 -> 13241114 | H43: =YEAR(B43)-YEAR($C$10)+1 -> 3
A44: 29 | B44: =EOMONTH($C$10,28) -> 47269 | C44: =G43 -> 13241114 | D44: =IF(A44>$C$6,MIN(C44,$C$13),0) -> 236448.47 | E44: =C44*$C$8*DAY(B44)/$C$11 -> 79814.494 | F44: =D44+E44 -> 316262.96 | G44: =C44-D44 -> 13004666 | H44: =YEAR(B44)-YEAR($C$10)+1 -> 3
...

Sheet ProfLoss
B2: ПРЕДПОЛАГАЕМЫЕ СЧЕТА ПРИБЫЛЕЙ И УБЫТКОВ (в экв. долл. США) | K2: Приложение 13
B4: ПОКАЗАТЕЛИ | C4: Ед. изм. | D4: 1 год (льготный период) | E4: 2 год | F4: 3 год | G4: 4 год | H4: 5 год | I4: 6 год | J4: 7 год
B6: Выручка от реализации продукции (с НДС) | C6: USD | D6: =D7+D8 -> 28331250 | E6: =E7+E8 -> 2.4740556e+08 | F6: =F7+F8 -> 3.079196e+08 | G6: =G7+G8 -> 3.186764e+08 | H6: =H7+H8 -> 325686900 | I6: =I7+I8 -> 3.3285148e+08 | J6: =J7+J8 -> 340175451
B7: экспорт (в твёрдой валюте) | C7: USD | D7: =SalePlan!D8 -> 28331250 | E7: =SalePlan!E8 -> 2.4740556e+08 | F7: =SalePlan!F8 -> 3.079196e+08 | G7: =SalePlan!G8 -> 3.186764e+08 | H7: =SalePlan!H8 -> 325686900 | I7: =SalePlan!I8 -> 3.3285148e+08 | J7: =SalePlan!J8 -> 340175451
B8: внутренний рынок (с НДС) | C8: USD | D8: =SalePlan!D12+Taxes!D19 -> 0 | E8: =SalePlan!E12+Taxes!E19 -> 0 | F8: =SalePlan!F12+Taxes!F19 -> 0 | G8: =SalePlan!G12+Taxes!G19 -> 0 | H8: =SalePlan!H12+Taxes!H19 -> 0 | I8: =SalePlan!I12+Taxes!I19 -> 0 | J8: =SalePlan!J12+Taxes!J19 -> 0
B9: НДС, начисленный с реализации | C9: USD | D9: =Taxes!D19 -> 0 | E9: =Taxes!E19 -> 0 | F9: =Taxes!F19 -> 0 | G9: =Taxes!G19 -> 0 | H9: =Taxes!H19 -> 0 | I9: =Taxes!I19 -> 0 | J9: =Taxes!J19 -> 0
B10: Чистая выручка от реализации продукции | C10: USD | D10: =D6-D9 -> 28331250 | E10: =E6-E9 -> 2.4740556e+08 | F10: =F6-F9 -> 3.079196e+08 | G10: =G6-G9 -> 3.186764e+08 | H10: =H6-H9 -> 325686900 | I10: =I6-I9 -> 3.3285148e+08 | J10: =J6-J9 -> 340175451
B11: Себестоимость реализованной продукции | C11: USD | D11: =CostSold!D22 -> 21093700 | E11: =CostSold!E22 -> 2.1726575e+08 | F11: =CostSold!F22 -> 2.7081462e+08 | G11: =CostSold!G22 -> 2.7927163e+08 | H11: =CostSold!H22 -> 2.8540538e+08 | I11: =CostSold!I22 -> 2.9167302e+08 | J11: =CostSold!J22 -> 2.980775e+08
B12: в твёрдой валюте | C12: USD | D12: =CostSold!D24 -> 20083620 | E12: =CostSold!E24 -> 2.0888689e+08 | F12: =CostSold!F24 -> 2.6077114e+08 | G12: =CostSold!G24 -> 2.6888246e+08 | H12: =CostSold!H24 -> 2.7475596e+08 | I12: =CostSold!I24 -> 2.8075767e+08 | J12: =CostSold!J24 -> 2.8689041e+08
