Workbook

Sheet Резюме
B2: БИЗНЕС-ПЛАН ИНВЕСТИЦИОННОГО ПРОЕКТА
B3: Строительство нового гидрометаллургического завода по переработке промышленного продукта - молибденового огарка
B4: (Цех по производству триоксида молибдена)
B6: 1. ОБЩИЕ СВЕДЕНИЯ
B7: Суть проекта | C7: Строительство нового гидрометаллургического завода по переработке промышленного продукта - молибденового огарка. Переработка 5 000 т молибденового огарка (концентрата) в год; выпуск основной продукции - Триоксид молибдена MoO3 1 983.1 t/год при проектной мощности; реализация - экспорт.
B8: Заемщик | C8: АО «Узбекский комбинат технологических металлов» (АО «Ўзбекистон ТМК», UzTMK)
B9: Местоположение | C9: Ташкентская область, Ахангаранский район - новая площадка, 10,4 га
B10: Продукция | C10: Триоксид молибдена MoO3, Медный шлак (25% Cu) (попутная), Кальциевая селитра (попутная)
B11: Производственная мощность | C11: Переработка 5 000 т молибденового огарка (концентрата) в год; выпуск основной продукции - 1 983 t/год
B12: Рынок сбыта | C12: экспорт (100% выручки в USD)
B13: Сроки | C13: начало строительства - 01.10.2026; начало производства - 01.10.2027; выход на проектную мощность - 2030 г.
B14: Стадия проработки | C14: ТЭО
B16: 2. ПАРАМЕТРЫ КРЕДИТА
B17: Сумма кредита, USD | C17: =ИНФОРМАЦИЯ!$C$26 -> 18191814
B18: Процентная ставка | C18: =ИНФОРМАЦИЯ!$C$27 -> 0.07
B19: Срок кредита | C19: 84 месяца (7 лет): льготный (инвестиционный) период - 12 месяцев (2027 г.), погашение - 72 месяца (2028-2033 гг.)
B20: Порядок погашения | C20: основной долг - ежемесячно равными долями; проценты - ежемесячно на остаток задолженности
B21: Проценты льготного периода | C21: =TEXT(LOANS!$C$106,"#,##0") & " USD - уплачиваются за счёт собственных средств заемщика (включены в стоимость проекта)" -> 1,291,113 USD - уплачиваются за счёт собственных средств заемщика (включены в стоимость проекта)
B22: Целевое назначение | C22: 30% авансовый платёж по EPC-контракту (E - проектирование, P - поставка оборудования, C - строительство)
B24: 3. СТОИМОСТЬ ПРОЕКТА И ИСТОЧНИКИ ФИНАНСИРОВАНИЯ
B25: Статья | C25: USD | D25: Доля
B26: Фиксированные активы | C26: =ProjCost!E5 -> 54094706 | D26: =IFERROR(C26/ProjCost!$E$20,0) -> 0.78232047
B27: Рабочий капитал | C27: =ProjCost!E9 -> 12384487 | D27: =IFERROR(C27/ProjCost!$E$20,0) -> 0.1791051
B28: Проценты льготного периода и расходы подготовительного периода | C28: =ProjCost!E15 -> 2485367.5 | D28: =IFERROR(C28/ProjCost!$E$20,0) -> 0.035943516
B29: Резерв | C29: =ProjCost!E18 -> 181918.14 | D29: =IFERROR(C29/ProjCost!$E$20,0) -> 0.0026309097
B30: ВСЕГО СТОИМОСТЬ ПРОЕКТА | C30: =ProjCost!E20 -> 69146479 | D30: =IFERROR(C30/ProjCost!$E$20,0) -> 1
B31: Собственные средства заемщика | C31: =FinPlan!$E$10 -> 50954665 | D31: =IFERROR(C31/ProjCost!$E$20,0) -> 0.73690903
B32: Кредит банка | C32: =FinPlan!$E$14 -> 18191814 | D32: =IFERROR(C32/ProjCost!$E$20,0) -> 0.26309097
B34: 4. ОСНОВНЫЕ ФИНАНСОВЫЕ ПОКАЗАТЕЛИ ПО ГОДАМ
B35: ПОКАЗАТЕЛИ | C35: Ед. изм. | D35: 1 год (льготный / инвест.) | E35: 2 год | F35: 3 год | G35: 4 год | H35: 5 год | I35: 6 год | J35: 7 год
D36: 2027 | E36: 2028 | F36: 2029 | G36: 2030 | H36: 2031 | I36: 2032 | J36: 2033
B37: Выручка (без НДС) | C37: USD | D37: =ProfLoss!D10 -> 9058233.4 | E37: =ProfLoss!E10 -> 36777950 | F37: =ProfLoss!F10 -> 48825712 | G37: =ProfLoss!G10 -> 58917295 | H37: =ProfLoss!H10 -> 60592704 | I37: =ProfLoss!I10 -> 61925327 | J37: =ProfLoss!J10 -> 63287696
B38: EBITDA | C38: USD | D38: =ProfLoss!D27 -> 731448.94 | E38: =ProfLoss!E27 -> 11251688 | F38: =ProfLoss!F27 -> 16832637 | G38: =ProfLoss!G27 -> 21369559 | H38: =ProfLoss!H27 -> 21930327 | I38: =ProfLoss!I27 -> 22433613 | J38: =ProfLoss!J27 -> 22948165
B39: Чистая прибыль | C39: USD | D39: =ProfLoss!D22 -> 54544.337 | E39: =ProfLoss!E22 -> 6229315.9 | F39: =ProfLoss!F22 -> 11113129 | G39: =ProfLoss!G22 -> 15106555 | H39: =ProfLoss!H22 -> 15720250 | I39: =ProfLoss!I22 -> 16284124 | J39: =ProfLoss!J22 -> 16859496
B40: Операционный поток наличности (A) | C40: USD | D40: =CashFlow!D18 -> -12856918 | E40: =CashFlow!E18 -> 16865940 | F40: =CashFlow!F18 -> 13020261 | G40: =CashFlow!G18 -> 17181750 | H40: =CashFlow!H18 -> 18926304 | I40: =CashFlow!I18 -> 19356302 | J40: =CashFlow!J18 -> 19764802
B41: Обслуживание долга (проценты + основной долг) | C41: USD | D41: =LOANS!$C$107 -> 1291113.5 | E41: =LOANS!$D$107 -> 4227477.2 | F41: =LOANS!$E$107 -> 4008803.4 | G41: =LOANS!$F$107 -> 3793617.9 | H41: =LOANS!$G$107 -> 3578432.3 | I41: =LOANS!$H$107 -> 3364376.7 | J41: =LOANS!$I$107 -> 3148061.1
B42: Чистый поток наличности | C42: USD | D42: =CashFlow!D26 -> 903741.6 | E42: =CashFlow!E26 -> 12098865 | F42: =CashFlow!F26 -> 8471859.2 | G42: =CashFlow!G26 -> 12848534 | H42: =CashFlow!H26 -> 14808274 | I42: =CashFlow!I26 -> 15452327 | J42: =CashFlow!J26 -> 16077143
B43: Кумулятивный поток наличности | C43: USD | D43: =CashFlow!D27 -> 903741.6 | E43: =CashFlow!E27 -> 13002606 | F43: =CashFlow!F27 -> 21474465 | G43: =CashFlow!G27 -> 34323000 | H43: =CashFlow!H27 -> 49131273 | I43: =CashFlow!I27 -> 64583601 | J43: =CashFlow!J27 -> 80660744
B44: DSCR (с учётом поддерживающих капвложений) | C44: x | D44: =CashFlow!D30 -> - | E44: =CashFlow!E30 -> 3.8619586 | F44: =CashFlow!F30 -> 3.1133137 | G44: =CashFlow!G30 -> 4.3868816 | H44: =CashFlow!H30 -> 5.1382015 | I44: =CashFlow!I30 -> 5.5929243 | J44: =CashFlow!J30 -> 6.1069984
B45: Задолженность по кредиту на конец года | C45: USD | D45: =LOANS!$C$108 -> 18191814 | E45: =LOANS!$D$108 -> 15159845 | F45: =LOANS!$E$108 -> 12127876 | G45: =LOANS!$F$108 -> 9095907 | H45: =LOANS!$G$108 -> 6063938 | I45: =LOANS!$H$108 -> 3031969 | J45: =LOANS!$I$108 -> 0
...

Sheet ИНФОРМАЦИЯ
B2: ДАННЫЕ ПО ПРОЕКТУ
B4: ЗАЕМЩИК | C4: АО «Узбекский комбинат технологических металлов» (АО «Ўзбекистон ТМК», UzTMK)
B5: ИНН | C5: - (заполняется заемщиком)
B6: ДЕЯТЕЛЬНОСТЬ | C6: Добыча и переработка редких и тугоплавких металлов (вольфрам, молибден)
B7: НАИМЕНОВАНИЕ ПРОЕКТА | C7: Строительство нового гидрометаллургического завода по переработке промышленного продукта - молибденового огарка (Цех по производству триоксида молибдена)
B8: МЕСТО РЕАЛИЗАЦИИ | C8: Ташкентская область, Ахангаранский район - новая площадка, 10,4 га
B9: ПРОИЗВОДСТВЕННАЯ МОЩНОСТЬ | C9: Переработка 5 000 т молибденового огарка (концентрата) в год
B10: ОСНОВНАЯ ПРОДУКЦИЯ | C10: Триоксид молибдена MoO3, Медный шлак (25% Cu), Кальциевая селитра
B11: СТАДИЯ ПРОРАБОТКИ | C11: ТЭО (технико-экономическое обоснование)
B12: НАЧАЛО СТРОИТЕЛЬСТВА | C12: 01.10.2026
B13: НАЧАЛО ПРОИЗВОДСТВА | C13: 01.10.2027
B14: СРОК РЕАЛИЗАЦИИ (по данным заемщика) | C14: декабрь 2027 г.
B16: УЧАСТНИКИ ПРОЕКТА
B17: Заемщик (инициатор проекта) | C17: АО «Узбекский комбинат технологических металлов» (АО «Ўзбекистон ТМК», UzTMK)
B18: Доля заемщика в проекте | C18: 100%
B19: Кредитор №1 | C19: Банк-кредитор (наименование уточняется)
B20: Генеральный подрядчик | C20: EPC-подрядчик (по EPC-контракту)
B22: ВАЛЮТА ПРОЕКТА | C22: Доллар США (экв.)
B23: 1 USD = (сум, средний курс 1-го года) | C23: 12218.063
B25: УСЛОВИЯ КРЕДИТА
B26: Сумма кредита, USD | C26: =O42 -> 18191814
B27: Процентная ставка, % годовых | C27: 0.07
B28: Срок кредита, месяцев | C28: 84
B29: Льготный период по основному долгу, месяцев | C29: 12
B30: Инвестиционный период, месяцев | C30: 12
B31: Дата выдачи кредита | C31: 46388
B32: База начисления процентов, дней в году (по форме банка) | C32: 360
B33: Погашение основного долга | C33: ежемесячно равными долями (72 платежа), с 31.01.2028 по 31.12.2033
B34: Уплата процентов | C34: ежемесячно; в льготный период (2027 г.) - за счёт собственных средств заемщика (включены в стоимость проекта)
B35: Целевое назначение | C35: 30% авансовый платёж по EPC-контракту (данные заемщика)
B36: Резерв (непредвиденные расходы) - % от суммы кредита (по форме банка) | C36: 0.01
B38: РАСПРЕДЕЛЕНИЕ КРЕДИТА 78 МЛН USD МЕЖДУ ПРОЕКТАМИ (по 30% авансу EPC-контрактов, файл заемщика от 14.10.2026)
B39: Проект | C39: Мощность | D39: Стоимость проекта, млн USD | E39: EPC: E (Engineering), млрд сум | F39: EPC: P (Procurement), млрд сум | G39: EPC: C (Construction), млрд сум | H39: EPC итого, млрд сум | I39: Курс EPC (тыс. сум/USD) | J39: EPC итого, экв. млн USD | K39: 30% аванс, млрд сум | L39: Курс аванса (тыс. сум/USD) | M39: 30% аванс, млн USD | N39: Доля в кредите | O39: Кредит, USD
B40: Освоение центральной части вольфрамового месторождения Сарикуль (1-я очередь) | C40: Переработка 600 тыс. т руды в год | D40: 158 | E40: 116.0323 | F40: 532.896 | G40: 1041.5674 | H40: =E40+F40+G40 -> 1690.4957 | I40: 12.2 | J40: =H40/I40 -> 138.56522 | K40: =H40*30% -> 507.1487 | L40: 11.838 | M40: =K40/L40 -> 42.840742 | N40: =M40/$M$43 -> 0.54851149 | O40: =N40*$O$44 -> 42783896
B41: Строительство нового гидрометаллургического завода по переработке вольфрамового концентрата (1-я очередь) | C41: Переработка 5 000 т вольфрамового концентрата в год | D41: 80 | E41: 25.272 | F41: 293.4 | G41: 353.99904 | H41: =E41+F41+G41 -> 672.67104 | I41: 12 | J41: =H41/I41 -> 56.05592 | K41: =H41*30% -> 201.80131 | L41: 11.838 | M41: =K41/L41 -> 17.046909 | N41: =M41/$M$43 -> 0.21826012 | O41: =N41*$O$44 -> 17024290
B42: Строительство нового гидрометаллургического завода по переработке промышленного продукта - молибденового огарка | C42: Переработка 5 000 т молибденового огарка (концентрата) в год | D42: 65 | E42: 25.35648 | F42: 251.13528 | G42: 442.311 | H42: =E42+F42+G42 -> 718.80276 | I42: 12 | J42: =H42/I42 -> 59.90023 | K42: =H42*30% -> 215.64083 | L42: 11.838 | M42: =K42/L42 -> 18.215985 | N42: =M42/$M$43 -> 0.23322838 | O42: =N42*$O$44 -> 18191814
B43: ИТОГО | D43: =SUM(D40:D42) -> 303 | E43: =SUM(E40:E42) -> 166.66078 | F43: =SUM(F40:F42) -> 1077.4313 | G43: =SUM(G40:G42) -> 1837.8774 | H43: =SUM(H40:H42) -> 3081.9695 | J43: =SUM(J40:J42) -> 254.52137 | K43: =SUM(K40:K42) -> 924.59084 | M43: =SUM(M40:M42) -> 78.103636 | N43: =SUM(N40:N42) -> 1 | O43: =SUM(O40:O42) -> 78000000
N44: Лимит кредита, USD | O44: 78000000
B46: Распределение кредита - пропорционально 30% авансу по EPC-контрактам, с приведением к лимиту 78,0 млн USD.

Sheet ProjCost
B2: ПЕРВОНАЧАЛЬНАЯ СТОИМОСТЬ ПРОЕКТА (в экв. долл. США) | F2: Приложение 1
B3: Инвестиционный период: с начала строительства по 31.12.2027 (1-й год кредита, льготный период).
B4: Наименование затрат | C4: МЕСТНАЯ ВАЛЮТА | D4: ТВЕРДАЯ ВАЛЮТА | E4: ВСЕГО | F4: СТРУКТУРА (%)
B5: ВСЕГО ФИКСИРОВАННЫЕ АКТИВЫ | C5: =SUM(C6:C8) -> 0 | D5: =SUM(D6:D8) -> 54094706 | E5: =SUM(E6:E8) -> 54094706 | F5: =IFERROR(E5/$E$20,0) -> 0.78232047
B6: Здания, сооружения и передаточные устройства | C6: =0 -> 0 | D6: 35274145 | E6: =C6+D6 -> 35274145 | F6: =IFERROR(E6/$E$20,0) -> 0.51013654
B7: Машины и оборудование | C7: =0 -> 0 | D7: 16465650 | E7: =C7+D7 -> 16465650 | F7: =IFERROR(E7/$E$20,0) -> 0.2381271
B8: Мебель, оргтехника и офисное оборудование | C8: =0 -> 0 | D8: 2354910.1 | E8: =C8+D8 -> 2354910.1 | F8: =IFERROR(E8/$E$20,0) -> 0.034056833
B9: РАБОЧИЙ КАПИТАЛ (на 31.12.2027), ВКЛЮЧАЯ: | C9: =SUM(C10:C14) -> 8872986.9 | D9: =SUM(D10:D14) -> 3511500.4 | E9: =SUM(E10:E14) -> 12384487 | F9: =IFERROR(E9/$E$20,0) -> 0.1791051
B10: Запасы сырья, материалов и готовой продукции | C10: 1919043.6 | D10: 0 | E10: =C10+D10 -> 1919043.6 | F10: =IFERROR(E10/$E$20,0) -> 0.027753309
B11: Дебиторская задолженность покупателей | C11: 0 | D11: 3511500.4 | E11: =C11+D11 -> 3511500.4 | F11: =IFERROR(E11/$E$20,0) -> 0.050783503
B12: НДС к возмещению (в т.ч. по капитальным вложениям) | C12: 7100743.1 | D12: 0 | E12: =C12+D12 -> 7100743.1 | F12: =IFERROR(E12/$E$20,0) -> 0.10269132
B13: Кредиторская задолженность поставщикам (уменьшает потребность) | C13: 0 | D13: 0 | E13: =C13+D13 -> 0 | F13: =IFERROR(E13/$E$20,0) -> 0
B14: Задолженность по оплате труда и налогам с ФОТ (уменьшает потребность) | C14: -146799.77 | D14: 0 | E14: =C14+D14 -> -146799.77 | F14: =IFERROR(E14/$E$20,0) -> -0.002123026
B15: ПРОЧИЕ ФИНАНСОВЫЕ ИЗДЕРЖКИ, ВКЛЮЧАЯ: | C15: =SUM(C16:C17) -> 1194254.1 | D15: =SUM(D16:D17) -> 1291113.5 | E15: =SUM(E16:E17) -> 2485367.5 | F15: =IFERROR(E15/$E$20,0) -> 0.035943516
B16: Проценты по кредиту за льготный период (2027 г.) - за счёт собственных средств | C16: 0 | D16: =LOANS!$C$106 -> 1291113.5 | E16: =C16+D16 -> 1291113.5 | F16: =IFERROR(E16/$E$20,0) -> 0.018672151
B17: Расходы подготовительного периода 2026 г. (административные и пусковые расходы) | C17: 1194254.1 | D17: 0 | E17: =C17+D17 -> 1194254.1 | F17: =IFERROR(E17/$E$20,0) -> 0.017271365
B18: НЕПРЕДВИДЕННЫЕ РАСХОДЫ/РЕЗЕРВ (1% от суммы кредита) | C18: 0 | D18: =ИНФОРМАЦИЯ!$C$26*ИНФОРМАЦИЯ!$C$36 -> 181918.14 | E18: =C18+D18 -> 181918.14 | F18: =IFERROR(E18/$E$20,0) -> 0.0026309097
B20: ВСЕГО ПЕРВОНАЧАЛЬНАЯ СТОИМОСТЬ ПРОЕКТА | C20: =C5+C9+C15+C18 -> 10067241 | D20: =D5+D9+D15+D18 -> 59079238 | E20: =E5+E9+E15+E18 -> 69146479 | F20: =IFERROR(E20/$E$20,0) -> 1

Sheet FinPlan
B2: ФИНАНСОВЫЙ ПЛАН (в экв. долл. США) | G2: Приложение 2
B4: ПОКАЗАТЕЛИ | C4: МЕСТНАЯ ВАЛЮТА | D4: ТВЁРДАЯ ВАЛЮТА | E4: ВСЕГО | F4: СТРУКТУРА (%) | G4: ДОЛЯ В ФИНАНСИРОВАНИИ
B5: СОБСТВЕННЫЙ КАПИТАЛ
B6: АО «Узбекский комбинат технологических металлов» (АО «Ўзбекистон ТМК», UzTMK)
B7: Фиксированные активы | C7: ='Share of costs'!C6 -> 0 | D7: ='Share of costs'!D6 -> 35902892 | E7: =C7+D7 -> 35902892 | F7: =IFERROR(E7/$E$10,0) -> 0.70460461
B8: Рабочий капитал | C8: ='Share of costs'!C10 -> 8872986.9 | D8: ='Share of costs'!D10 -> 3511500.4 | E8: =C8+D8 -> 12384487 | F8: =IFERROR(E8/$E$10,0) -> 0.24304914
B9: Денежные средства (финансовые издержки льготного периода, расходы подготовительного периода, резерв) | C9: ='Share of costs'!C11+'Share of costs'!C14 -> 1194254.1 | D9: ='Share of costs'!D11+'Share of costs'!D14 -> 1473031.6 | E9: =C9+D9 -> 2667285.7 | F9: =IFERROR(E9/$E$10,0) -> 0.052346251
B10: ВСЕГО | C10: =SUM(C7:C9) -> 10067241 | D10: =SUM(D7:D9) -> 40887424 | E10: =SUM(E7:E9) -> 50954665 | F10: =IFERROR(E10/$E$10,0) -> 1 | G10: =IFERROR(E10/$E$15,0) -> 0.73690903
B11: КРЕДИТЫ
B12: Банк (кредит 7% годовых, 84 мес., льготный период 12 мес.) | C12: =C13 -> 0 | D12: =D13 -> 18191814 | E12: =C12+D12 -> 18191814 | F12: =IFERROR(E12/$E$14,0) -> 1
B13: Фиксированные активы (30% аванс по EPC-контракту) | C13: ='Share of costs'!E6 -> 0 | D13: ='Share of costs'!F6 -> 18191814 | E13: =C13+D13 -> 18191814 | F13: =IFERROR(E13/$E$14,0) -> 1
B14: ВСЕГО | C14: =C12 -> 0 | D14: =D12 -> 18191814 | E14: =E12 -> 18191814 | F14: =IFERROR(E14/$E$14,0) -> 1 | G14: =IFERROR(E14/$E$15,0) -> 0.26309097
B15: ВСЕГО ФИНАНСИРОВАНИЯ | C15: =C14+C10 -> 10067241 | D15: =D14+D10 -> 59079238 | E15: =E14+E10 -> 69146479 | G15: =IFERROR(E15/$E$15,0) -> 1

Sheet Share of costs
B2: ПЕРВОНАЧАЛЬНАЯ СТОИМОСТЬ ПРОЕКТА ПО ИСТОЧНИКАМ ФИНАНСИРОВАНИЯ (в экв. долл. США) | H2: Приложение 3
B4: Наименование затрат | C4: Собственные средства заемщика | E4: Кредит банка | G4: Всего
C5: в местной валюте | D5: в твердой валюте | E5: в местной валюте | F5: в твердой валюте | G5: в местной валюте | H5: в твердой валюте
B6: ВСЕГО ФИКСИРОВАННЫЕ АКТИВЫ | C6: =SUM(C7:C9) -> 0 | D6: =SUM(D7:D9) -> 35902892 | E6: =SUM(E7:E9) -> 0 | F6: =SUM(F7:F9) -> 18191814 | G6: =SUM(G7:G9) -> 0 | H6: =SUM(H7:H9) -> 54094706
B7: Здания, сооружения и передаточные устройства | C7: =ProjCost!$C$6 -> 0 | D7: =ProjCost!$D$6-F7 -> 23438187 | E7: 0 | F7: =ИНФОРМАЦИЯ!$C$26*(1-ИНФОРМАЦИЯ!$F$42/ИНФОРМАЦИЯ!$H$42)*ProjCost!$E$6/(ProjCost!$E$6) -> 11835959 | G7: =C7+E7 -> 0 | H7: =D7+F7 -> 35274145
B8: Машины и оборудование | C8: =ProjCost!$C$7 -> 0 | D8: =ProjCost!$D$7-F8 -> 10905067 | E8: 0 | F8: =ИНФОРМАЦИЯ!$C$26*ИНФОРМАЦИЯ!$F$42/ИНФОРМАЦИЯ!$H$42*ProjCost!$E$7/(ProjCost!$E$7+ProjCost!$E$8) -> 5560583.1 | G8: =C8+E8 -> 0 | H8: =D8+F8 -> 16465650
B9: Мебель, оргтехника и офисное оборудование | C9: =ProjCost!$C$8 -> 0 | D9: =ProjCost!$D$8-F9 -> 1559637.9 | E9: 0 | F9: =ИНФОРМАЦИЯ!$C$26*ИНФОРМАЦИЯ!$F$42/ИНФОРМАЦИЯ!$H$42*ProjCost!$E$8/(ProjCost!$E$7+ProjCost!$E$8) -> 795272.16 | G9: =C9+E9 -> 0 | H9: =D9+F9 -> 2354910.1
B10: РАБОЧИЙ КАПИТАЛ | C10: =ProjCost!$C$9 -> 8872986.9 | D10: =ProjCost!$D$9 -> 3511500.4 | E10: 0 | F10: 0 | G10: =C10+E10 -> 8872986.9 | H10: =D10+F10 -> 3511500.4
B11: ПРОЧИЕ ФИНАНСОВЫЕ ИЗДЕРЖКИ | C11: =ProjCost!$C$15 -> 1194254.1 | D11: =ProjCost!$D$15 -> 1291113.5 | E11: 0 | F11: 0 | G11: =C11+E11 -> 1194254.1 | H11: =D11+F11 -> 1291113.5
B12: в т.ч. проценты по кредиту за льготный период | C12: =ProjCost!$C$16 -> 0 | D12: =ProjCost!$D$16 -> 1291113.5 | E12: 0 | F12: 0 | G12: =C12+E12 -> 0 | H12: =D12+F12 -> 1291113.5
B13: в т.ч. расходы подготовительного периода 2026 г. | C13: =ProjCost!$C$17 -> 1194254.1 | D13: =ProjCost!$D$17 -> 0 | E13: 0 | F13: 0 | G13: =C13+E13 -> 1194254.1 | H13: =D13+F13 -> 0
B14: НЕПРЕДВИДЕННЫЕ РАСХОДЫ/РЕЗЕРВ | C14: =ProjCost!$C$18 -> 0 | D14: =ProjCost!$D$18 -> 181918.14 | E14: 0 | F14: 0 | G14: =C14+E14 -> 0 | H14: =D14+F14 -> 181918.14
B16: ВСЕГО ПЕРВОНАЧАЛЬНАЯ СТОИМОСТЬ ПРОЕКТА | C16: =C6+C10+C11+C14 -> 10067241 | D16: =D6+D10+D11+D14 -> 40887424 | E16: =E6+E10+E11+E14 -> 0 | F16: =F6+F10+F11+F14 -> 18191814 | G16: =G6+G10+G11+G14 -> 10067241 | H16: =H6+H10+H11+H14 -> 59079238
B17: Итого по источнику | C17: =C16+D16 -> 50954665 | E17: =E16+F16 -> 18191814 | G17: =G16+H16 -> 69146479
B19: Кредит банка направляется на 30% авансовый платёж по EPC-контракту; распределение по группам активов - пропорционально составу EPC-контракта: P (поставка оборудования) - машины и оборудование, E+C (проектирование и строительство) - здания, сооружения и прочие объекты.

Sheet Depreciate
B2: АМОРТИЗАЦИЯ (в долл. США) | N2: Приложение 4
B3: Линейный метод. Проценты льготного периода капитализированы в стоимость основных средств (МСФО IAS 23).
B5: ОБЪЕКТЫ АМОРТИЗАЦИИ | C5: Группа основных средств | D5: Первоначальная стоимость | E5: Срок, лет | F5: Норма, % | G5: 1 год | H5: 2 год | I5: 3 год | J5: 4 год | K5: 5 год | L5: 6 год | M5: 7 год
G6: 2027 | H6: 2028 | I6: 2029 | J6: 2030 | K6: 2031 | L6: 2032 | M6: 2033
B7: Проектирование: ТЭО/ЗВОС и PFS | C7: Здания, сооружения и передаточные устройства | D7: 477455.36 | E7: 50 | F7: =1/E7 -> 0.02 | G7: 2387.2768 | H7: 9549.1071 | I7: 9549.1071 | J7: 9549.1071 | K7: 9549.1071 | L7: 9549.1071 | M7: 9549.1071
B8: Строительство - цеха | C8: Здания, сооружения и передаточные устройства | D8: 7979203.1 | E8: 50 | F8: =1/E8 -> 0.02 | G8: 39896.015 | H8: 159584.06 | I8: 159584.06 | J8: 159584.06 | K8: 159584.06 | L8: 159584.06 | M8: 159584.06
B9: Строительство - АБК и соцобъекты | C9: Здания, сооружения и передаточные устройства | D9: 8453466.9 | E9: 50 | F9: =1/E9 -> 0.02 | G9: 42267.335 | H9: 169069.34 | I9: 169069.34 | J9: 169069.34 | K9: 169069.34 | L9: 169069.34 | M9: 169069.34
B10: Прочие затраты на строительство | C10: Здания, сооружения и передаточные устройства | D10: 8236950 | E10: 50 | F10: =1/E10 -> 0.02 | G10: 41184.75 | H10: 164739 | I10: 164739 | J10: 164739 | K10: 164739 | L10: 164739 | M10: 164739
B11: Инфраструктура (вода, газ, эл.) | C11: Здания, сооружения и передаточные устройства | D11: 3710280 | E11: 50 | F11: =1/E11 -> 0.02 | G11: 18551.4 | H11: 74205.6 | I11: 74205.6 | J11: 74205.6 | K11: 74205.6 | L11: 74205.6 | M11: 74205.6
B12: Строительство ж.д. | C12: Здания, сооружения и передаточные устройства | D12: 1473000 | E12: 50 | F12: =1/E12 -> 0.02 | G12: 7365 | H12: 29460 | I12: 29460 | J12: 29460 | K12: 29460 | L12: 29460 | M12: 29460
B13: Технол. оборудование с монтажом | C13: Машины и оборудование | D13: 16330751 | E13: 10 | F13: =1/E13 -> 0.1 | G13: 408268.77 | H13: 1633075.1 | I13: 1633075.1 | J13: 1633075.1 | K13: 1633075.1 | L13: 1633075.1 | M13: 1633075.1
B14: Оборудование АБК и соцобъектов | C14: Мебель, оргтехника и офисное оборудование | D14: 2354910.1 | E14: 10 | F14: =1/E14 -> 0.1 | G14: 58872.752 | H14: 235491.01 | I14: 235491.01 | J14: 235491.01 | K14: 235491.01 | L14: 235491.01 | M14: 235491.01
B15: Непредвиденные расходы | C15: Здания, сооружения и передаточные устройства | D15: 4943790 | E15: 50 | F15: =1/E15 -> 0.02 | G15: 24718.95 | H15: 98875.8 | I15: 98875.8 | J15: 98875.8 | K15: 98875.8 | L15: 98875.8 | M15: 98875.8
B16: Поддерживающие капвложения (% от первоначальной стоимости ОС) | C16: Машины и оборудование | D16: 3372487.9 | E16: 10 | F16: =1/E16 -> 0.1 | G16: 2248.3253 | H16: 67449.758 | I16: 121409.56 | J16: 175369.37 | K16: 229329.18 | L16: 283288.98 | M16: 337248.79
B17: Капитализированные проценты по кредиту за льготный период (2027 г.) | C17: Затраты по займам (МСФО IAS 23) | D17: =LOANS!$C$106 -> 1291113.5 | E17: 15 | F17: =1/E17 -> 0.066666667 | G17: 21518.558 | H17: =D17/E17 -> 86074.231 | I17: =D17/E17 -> 86074.231 | J17: =D17/E17 -> 86074.231 | K17: =D17/E17 -> 86074.231 | L17: =D17/E17 -> 86074.231 | M17: =D17/E17 -> 86074.231
B18: ВСЕГО | C18: Х | D18: =SUM(D7:D17) -> 58623407 | G18: =SUM(G7:G17) -> 667279.13 | H18: =SUM(H7:H17) -> 2727573 | I18: =SUM(I7:I17) -> 2781532.8 | J18: =SUM(J7:J17) -> 2835492.6 | K18: =SUM(K7:K17) -> 2889452.4 | L18: =SUM(L7:L17) -> 2943412.2 | M18: =SUM(M7:M17) -> 2997372
B19: в т.ч. в себестоимости продукции | G19: =G18-G20 -> 566139.04 | H19: =H18-H20 -> 2323012.6 | I19: =I18-I20 -> 2376972.4 | J19: =J18-J20 -> 2430932.2 | K19: =K18-K20 -> 2484892 | L19: =L18-L20 -> 2538851.8 | M19: =M18-M20 -> 2592811.7
B20: в т.ч. в административных расходах | G20: 101140.09 | H20: 404560.35 | I20: 404560.35 | J20: 404560.35 | K20: 404560.35 | L20: 404560.35 | M20: 404560.35
B22: Накопленная амортизация | G22: =SUM($G$18:G18) -> 667279.13 | H22: =SUM($G$18:H18) -> 3394852.1 | I22: =SUM($G$18:I18) -> 6176384.9 | J22: =SUM($G$18:J18) -> 9011877.4 | K22: =SUM($G$18:K18) -> 11901330 | L22: =SUM($G$18:L18) -> 14844742 | M22: =SUM($G$18:M18) -> 17842114
B23: Остаточная стоимость основных средств (на конец года) | G23: 54718540 | H23: 52530565 | I23: 50288630 | J23: 47992736 | K23: 45642881 | L23: 43239067 | M23: 40781293

Sheet ProdPlan
B2: ПРОИЗВОДСТВЕННЫЙ ПЛАН | K2: Приложение 5
B4: Н А И М Е Н О В А Н И Е | C4: Ед. изм. | D4: Мощность в год | E4: Рынок сбыта | F4: Цена за единицу, USD (2030 г.) | G4: Выручка при полной мощности: экспорт | H4: Выручка при полной мощности: внутр. рынок
B5: Триоксид молибдена MoO3 | C5: t | D5: 1983.07 | E5: экспорт | F5: 29897 | G5: =D5*F5 -> 59287844 | H5: 0
B6: Медный шлак (25% Cu) | C6: t | D6: 609.57 | E6: внутренний рынок | F6: 0 | G6: 0 | H6: =D6*F6 -> 0
B7: Кальциевая селитра | C7: t | D7: 3000 | E7: внутренний рынок | F7: 0 | G7: 0 | H7: =D7*F7 -> 0
B8: Всего | G8: =SUM(G5:G7) -> 59287844 | H8: =SUM(H5:H7) -> 0
B10: ПОКАЗАТЕЛИ | C10: Ед. изм. | D10: 1 год (льготный / инвест.) | E10: 2 год | F10: 3 год | G10: 4 год | H10: 5 год | I10: 6 год | J10: 7 год
D11: 2027 | E11: 2028 | F11: 2029 | G11: 2030 | H11: 2031 | I11: 2032 | J11: 2033
B12: ОСВОЕНИЕ МОЩНОСТЕЙ
B13: Триоксид молибдена MoO3 | C13: % | D13: 0.15 | E13: 0.65 | F13: 0.85 | G13: 1 | H13: 1 | I13: 1 | J13: 1
B14: Медный шлак (25% Cu) | C14: % | D14: 0.15 | E14: 0.65 | F14: 0.85 | G14: 1 | H14: 1 | I14: 1 | J14: 1
B15: Кальциевая селитра | C15: % | D15: 0.15 | E15: 0.65 | F15: 0.85 | G15: 1 | H15: 1 | I15: 1 | J15: 1
B16: КОЛИЧЕСТВО ПРОИЗВОДСТВА
B17: Триоксид молибдена MoO3 | C17: t | D17: =$D$5*D13 -> 297.4605 | E17: =$D$5*E13 -> 1288.9955 | F17: =$D$5*F13 -> 1685.6095 | G17: =$D$5*G13 -> 1983.07 | H17: =$D$5*H13 -> 1983.07 | I17: =$D$5*I13 -> 1983.07 | J17: =$D$5*J13 -> 1983.07
B18: Медный шлак (25% Cu) | C18: t | D18: =$D$6*D14 -> 91.4355 | E18: =$D$6*E14 -> 396.2205 | F18: =$D$6*F14 -> 518.1345 | G18: =$D$6*G14 -> 609.57 | H18: =$D$6*H14 -> 609.57 | I18: =$D$6*I14 -> 609.57 | J18: =$D$6*J14 -> 609.57
B19: Кальциевая селитра | C19: t | D19: =$D$7*D15 -> 450 | E19: =$D$7*E15 -> 1950 | F19: =$D$7*F15 -> 2550 | G19: =$D$7*G15 -> 3000 | H19: =$D$7*H15 -> 3000 | I19: =$D$7*I15 -> 3000 | J19: =$D$7*J15 -> 3000
B20: КОЛИЧЕСТВО ДЛЯ РЕАЛИЗАЦИИ
B21: Триоксид молибдена MoO3 - экспорт | C21: t | D21: 247.88375 | E21: 1284.8641 | F21: 1669.0839 | G21: 1970.6758 | H21: 1983.07 | I21: 1983.07 | J21: 1983.07
B22: Триоксид молибдена MoO3 - внутренний рынок | C22: t | D22: 0 | E22: 0 | F22: 0 | G22: 0 | H22: 0 | I22: 0 | J22: 0
B23: Медный шлак (25% Cu) - экспорт | C23: t | D23: 0 | E23: 0 | F23: 0 | G23: 0 | H23: 0 | I23: 0 | J23: 0
B24: Медный шлак (25% Cu) - внутренний рынок | C24: t | D24: 76.19625 | E24: 394.95056 | F24: 513.05475 | G24: 605.76019 | H24: 609.57 | I24: 609.57 | J24: 609.57
B25: Кальциевая селитра - экспорт | C25: t | D25: 0 | E25: 0 | F25: 0 | G25: 0 | H25: 0 | I25: 0 | J25: 0
B26: Кальциевая селитра - внутренний рынок | C26: t | D26: 375 | E26: 1943.75 | F26: 2525 | G26: 2981.25 | H26: 3000 | I26: 3000 | J26: 3000
B27: КОЛИЧЕСТВО ЗАПАСА ГОТОВОЙ ПРОДУКЦИИ НА КОНЕЦ ГОДА
B28: Триоксид молибдена MoO3 | C28: t | D28: =0+D17-D21-D22 -> 49.57675 | E28: =D28+E17-E21-E22 -> 53.708146 | F28: =E28+F17-F21-F22 -> 70.233729 | G28: =F28+G17-G21-G22 -> 82.627917 | H28: =G28+H17-H21-H22 -> 82.627917 | I28: =H28+I17-I21-I22 -> 82.627917 | J28: =I28+J17-J21-J22 -> 82.627917
B29: Медный шлак (25% Cu) | C29: t | D29: =0+D18-D23-D24 -> 15.23925 | E29: =D29+E18-E23-E24 -> 16.509188 | F29: =E29+F18-F23-F24 -> 21.588938 | G29: =F29+G18-G23-G24 -> 25.39875 | H29: =G29+H18-H23-H24 -> 25.39875 | I29: =H29+I18-I23-I24 -> 25.39875 | J29: =I29+J18-J23-J24 -> 25.39875
B30: Кальциевая селитра | C30: t | D30: =0+D19-D25-D26 -> 75 | E30: =D30+E19-E25-E26 -> 81.25 | F30: =E30+F19-F25-F26 -> 106.25 | G30: =F30+G19-G25-G26 -> 125 | H30: =G30+H19-H25-H26 -> 125 | I30: =H30+I19-I25-I26 -> 125 | J30: =I30+J19-J25-J26 -> 125
B31: ЦЕНА РЕАЛИЗАЦИИ
B32: Триоксид молибдена MoO3 | C32: USD/t | D32: 36542.264 | E32: 28624 | F32: 29253 | G32: 29897 | H32: 30555 | I32: 31227 | J32: 31914
B33: Медный шлак (25% Cu) | C33: USD/t | D33: 0 | E33: 0 | F33: 0 | G33: 0 | H33: 0 | I33: 0 | J33: 0
B34: Кальциевая селитра | C34: USD/t | D34: 0 | E34: 0 | F34: 0 | G34: 0 | H34: 0 | I34: 0 | J34: 0
B36: Попутная продукция (медный шлак, кальциевая селитра) в базовом сценарии ТЭО выручки не формирует - отражена в натуральном выражении (консервативный подход).

Sheet SalePlan
B2: ПЛАН ПРОДАЖ (в экв. долл. США, без НДС) | K2: Приложение 6
B4: ПОКАЗАТЕЛИ | C4: Ед. изм. | D4: 1 год (льготный / инвест.) | E4: 2 год | F4: 3 год | G4: 4 год | H4: 5 год | I4: 6 год | J4: 7 год
D5: 2027 | E5: 2028 | F5: 2029 | G5: 2030 | H5: 2031 | I5: 2032 | J5: 2033
B6: ЭКСПОРТ
B7: Триоксид молибдена MoO3 | C7: USD | D7: =ProdPlan!D21*ProdPlan!D32 -> 9058233.4 | E7: =ProdPlan!E21*ProdPlan!E32 -> 36777950 | F7: =ProdPlan!F21*ProdPlan!F32 -> 48825712 | G7: =ProdPlan!G21*ProdPlan!G32 -> 58917295 | H7: =ProdPlan!H21*ProdPlan!H32 -> 60592704 | I7: =ProdPlan!I21*ProdPlan!I32 -> 61925327 | J7: =ProdPlan!J21*ProdPlan!J32 -> 63287696
B8: Медный шлак (25% Cu) | C8: USD | D8: =ProdPlan!D23*ProdPlan!D33 -> 0 | E8: =ProdPlan!E23*ProdPlan!E33 -> 0 | F8: =ProdPlan!F23*ProdPlan!F33 -> 0 | G8: =ProdPlan!G23*ProdPlan!G33 -> 0 | H8: =ProdPlan!H23*ProdPlan!H33 -> 0 | I8: =ProdPlan!I23*ProdPlan!I33 -> 0 | J8: =ProdPlan!J23*ProdPlan!J33 -> 0
B9: Кальциевая селитра | C9: USD | D9: =ProdPlan!D25*ProdPlan!D34 -> 0 | E9: =ProdPlan!E25*ProdPlan!E34 -> 0 | F9: =ProdPlan!F25*ProdPlan!F34 -> 0 | G9: =ProdPlan!G25*ProdPlan!G34 -> 0 | H9: =ProdPlan!H25*ProdPlan!H34 -> 0 | I9: =ProdPlan!I25*ProdPlan!I34 -> 0 | J9: =ProdPlan!J25*ProdPlan!J34 -> 0
B10: Всего | C10: USD | D10: =SUM(D7:D9) -> 9058233.4 | E10: =SUM(E7:E9) -> 36777950 | F10: =SUM(F7:F9) -> 48825712 | G10: =SUM(G7:G9) -> 58917295 | H10: =SUM(H7:H9) -> 60592704 | I10: =SUM(I7:I9) -> 61925327 | J10: =SUM(J7:J9) -> 63287696
B12: ВНУТРЕННИЕ ПРОДАЖИ
B13: Триоксид молибдена MoO3 | C13: USD | D13: =ProdPlan!D22*ProdPlan!D32 -> 0 | E13: =ProdPlan!E22*ProdPlan!E32 -> 0 | F13: =ProdPlan!F22*ProdPlan!F32 -> 0 | G13: =ProdPlan!G22*ProdPlan!G32 -> 0 | H13: =ProdPlan!H22*ProdPlan!H32 -> 0 | I13: =ProdPlan!I22*ProdPlan!I32 -> 0 | J13: =ProdPlan!J22*ProdPlan!J32 -> 0
B14: Медный шлак (25% Cu) | C14: USD | D14: =ProdPlan!D24*ProdPlan!D33 -> 0 | E14: =ProdPlan!E24*ProdPlan!E33 -> 0 | F14: =ProdPlan!F24*ProdPlan!F33 -> 0 | G14: =ProdPlan!G24*ProdPlan!G33 -> 0 | H14: =ProdPlan!H24*ProdPlan!H33 -> 0 | I14: =ProdPlan!I24*ProdPlan!I33 -> 0 | J14: =ProdPlan!J24*ProdPlan!J33 -> 0
B15: Кальциевая селитра | C15: USD | D15: =ProdPlan!D26*ProdPlan!D34 -> 0 | E15: =ProdPlan!E26*ProdPlan!E34 -> 0 | F15: =ProdPlan!F26*ProdPlan!F34 -> 0 | G15: =ProdPlan!G26*ProdPlan!G34 -> 0 | H15: =ProdPlan!H26*ProdPlan!H34 -> 0 | I15: =ProdPlan!I26*ProdPlan!I34 -> 0 | J15: =ProdPlan!J26*ProdPlan!J34 -> 0
B16: Всего | C16: USD | D16: =SUM(D13:D15) -> 0 | E16: =SUM(E13:E15) -> 0 | F16: =SUM(F13:F15) -> 0 | G16: =SUM(G13:G15) -> 0 | H16: =SUM(H13:H15) -> 0 | I16: =SUM(I13:I15) -> 0 | J16: =SUM(J13:J15) -> 0
B18: ВСЕГО ПРОДАЖ | C18: USD | D18: =D10+D16 -> 9058233.4 | E18: =E10+E16 -> 36777950 | F18: =F10+F16 -> 48825712 | G18: =G10+G16 -> 58917295 | H18: =H10+H16 -> 60592704 | I18: =I10+I16 -> 61925327 | J18: =J10+J16 -> 63287696
B19: Доля экспорта в выручке | C19: % | D19: =IFERROR(D10/D18,0) -> 1 | E19: =IFERROR(E10/E18,0) -> 1 | F19: =IFERROR(F10/F18,0) -> 1 | G19: =IFERROR(G10/G18,0) -> 1 | H19: =IFERROR(H10/H18,0) -> 1 | I19: =IFERROR(I10/I18,0) -> 1 | J19: =IFERROR(J10/J18,0) -> 1

Sheet RawMat
B2: СТОИМОСТЬ СЫРЬЯ И МАТЕРИАЛОВ ПРИ ПРОЕКТНОЙ МОЩНОСТИ (в экв. долл. США, 2030 г.) | G2: Приложение 7
B3: Базовый год - 2030 г. (освоение мощности 100%); цены - в номинальном выражении ТЭО; без НДС.
B5: НАИМЕНОВАНИЕ | C5: Ед. изм. | D5: Цена за единицу, USD | E5: Годовая потребность | F5: Годовая стоимость, USD | G5: ДОЛЯ (%) | H5: Примечание
B6: СЫРЬЁ, МАТЕРИАЛЫ И ПЕРЕМЕННЫЕ ЗАТРАТЫ С ЦЕНОЙ В ТВЁРДОЙ ВАЛЮТЕ (USD)
B7: Ингибитор | C7: t | D7: =IFERROR(F7/E7,0) -> 11086.394 | E7: 50 | F7: 554319.68 | G7: =IFERROR(F7/$F$20,0) -> 0.020277742 | H7: Вспомогательные материалы
B8: Фильтроткань | C8: m2 | D8: =IFERROR(F8/E8,0) -> 12.383081 | E8: 2000 | F8: 24766.162 | G8: =IFERROR(F8/$F$20,0) -> 0.00090597874 | H8: Вспомогательные материалы
B9: ВСЕГО В ТВЁРДОЙ ВАЛЮТЕ | F9: =SUM(F7:F8) -> 579085.84 | G9: =IFERROR(F9/$F$20,0) -> 0.021183721
B11: СЫРЬЁ, МАТЕРИАЛЫ И ПЕРЕМЕННЫЕ ЗАТРАТЫ С ЦЕНОЙ В НАЦИОНАЛЬНОЙ ВАЛЮТЕ (UZS)
B12: Молибденовый огарок | C12: t | D12: =IFERROR(F12/E12,0) -> 4937.0381 | E12: 5000 | F12: 24685190 | G12: =IFERROR(F12/$F$20,0) -> 0.90301669 | H12: Сырьё
B13: Аммиачная вода | C13: t | D13: =IFERROR(F13/E13,0) -> 341.7778 | E13: 1119.94 | F13: 382770.63 | G13: =IFERROR(F13/$F$20,0) -> 0.014002253 | H13: Вспомогательные материалы
B14: Азотная кислота | C14: t | D14: =IFERROR(F14/E14,0) -> 348.43471 | E14: 3334.62 | F14: 1161897.4 | G14: =IFERROR(F14/$F$20,0) -> 0.042503732 | H14: Вспомогательные материалы
B15: Гидроксид натрия | C15: t | D15: =IFERROR(F15/E15,0) -> 1080.5373 | E15: 162.56 | F15: 175652.15 | G15: =IFERROR(F15/$F$20,0) -> 0.0064255863 | H15: Вспомогательные материалы
B16: Оксид кальция | C16: t | D16: =IFERROR(F16/E16,0) -> 88.308413 | E16: 2000 | F16: 176616.83 | G16: =IFERROR(F16/$F$20,0) -> 0.0064608756 | H16: Вспомогательные материалы
B17: Сульфид аммония | C17: t | D17: =IFERROR(F17/E17,0) -> 872.94594 | E17: 200.64 | F17: 175147.87 | G17: =IFERROR(F17/$F$20,0) -> 0.0064071393 | H17: Вспомогательные материалы
B18: ВСЕГО В НАЦИОНАЛЬНОЙ ВАЛЮТЕ | F18: =SUM(F12:F17) -> 26757275 | G18: =IFERROR(F18/$F$20,0) -> 0.97881628
B20: ИТОГО СЫРЬЁ, МАТЕРИАЛЫ И ПРОЧИЕ ПЕРЕМЕННЫЕ ЗАТРАТЫ | F20: =F9+F18 -> 27336361 | G20: =IFERROR(F20/$F$20,0) -> 1
B22: ПРОЧИЕ ПРОИЗВОДСТВЕННЫЕ РАСХОДЫ (постоянные)
B23: Статьи затрат | F23: Годовая стоимость, USD | H23: Состав затрат
B24: Ремонт и техническое обслуживание | F24: 1018194 | H24: Ремонт и содержание зданий; Ремонт и обслуживание оборудования
B25: Прочие производственные расходы (охрана труда, накладные и др.) | F25: 94026.769 | H25: Охрана труда; Стоки (канализация); Кек возвратный, вода из скважин, прочее
B26: Налог за пользование недрами (НДПИ) | F26: 0
B27: Итого: | F27: =SUM(F24:F26) -> 1112220.8

Sheet Labour
B2: ЭНЕРГОРЕСУРСЫ И ОПЛАТА ТРУДА ПРИ ПРОЕКТНОЙ МОЩНОСТИ (в экв. долл. США, 2030 г.) | G2: Приложение 8
B5: СТАТЬИ ЗАТРАТ | C5: Ед. изм. | D5: Годовая потребность | E5: Цена за единицу, USD | F5: Годовая стоимость, USD
B6: Электроэнергия - переменная часть | C6: kWh | D6: 7619042.4 | E6: =IFERROR(F6/D6,0) -> 0.10284668 | F6: 783593.24
B7: Природный газ - переменная часть | C7: m3 | D7: 2959722.4 | E7: =IFERROR(F7/D7,0) -> 0.17256152 | F7: 510734.2
B8: Электроэнергия - постоянная часть | F8: 324288.72
B9: Природный газ / топливо - постоянная часть | F9: 0
B10: Вода - постоянная часть | F10: 0
B11: ВСЕГО ЭНЕРГОРЕСУРСЫ | F11: =SUM(F6:F10) -> 1618616.2
B13: РАСЧЕТ ЗАРАБОТНОЙ ПЛАТЫ
B14: ПОКАЗАТЕЛИ | C14: Количество, чел. | D14: Среднемесячная з/плата на 1 чел., сум (в ценах 2026 г.) | E14: Среднемесячная з/плата на 1 чел., USD | F14: Годовой фонд з/платы, USD | G14: Отчисления (соц. налог), USD
B15: ПРОИЗВОДСТВЕННЫЙ ПЕРСОНАЛ
B16: Начальник цеха | C16: 1 | D16: 17835000 | E16: =IFERROR(F16/C16/12,0) -> 1646.1634 | F16: 19753.96 | G16: 2370.4752
B17: Операторы промывки и выщелачивания | C17: 40 | D17: 15457000 | E17: =IFERROR(F17/C17/12,0) -> 1426.6749 | F17: 684803.95 | G17: 82176.475
B18: Начальник цеха | C18: 1 | D18: 17835000 | E18: =IFERROR(F18/C18/12,0) -> 1646.1634 | F18: 19753.96 | G18: 2370.4752
B19: Операторы очистки и осаждения | C19: 8 | D19: 15457000 | E19: =IFERROR(F19/C19/12,0) -> 1426.6749 | F19: 136960.79 | G19: 16435.295
B20: Начальник цеха | C20: 1 | D20: 17835000 | E20: =IFERROR(F20/C20/12,0) -> 1646.1634 | F20: 19753.96 | G20: 2370.4752
B21: Операторы фильтр-прессов и прокалки | C21: 12 | D21: 15457000 | E21: =IFERROR(F21/C21/12,0) -> 1426.6749 | F21: 205441.19 | G21: 24652.942
B22: Бригадир очистки сточных вод | C22: 1 | D22: 9512000 | E22: =IFERROR(F22/C22/12,0) -> 877.95379 | F22: 10535.445 | G22: 1264.2535
B23: Рабочие очистки сточных вод | C23: 8 | D23: 11592750 | E23: =IFERROR(F23/C23/12,0) -> 1070.0062 | F23: 102720.59 | G23: 12326.471
B24: Операторы котельной | C24: 8 | D24: 11592750 | E24: =IFERROR(F24/C24/12,0) -> 1070.0062 | F24: 102720.59 | G24: 12326.471
B25: Персонал РУ и обслуживания систем | C25: 12 | D25: 11592750 | E25: =IFERROR(F25/C25/12,0) -> 1070.0062 | F25: 154080.89 | G25: 18489.707
B26: Водители | C26: 10 | D26: 7134000 | E26: =IFERROR(F26/C26/12,0) -> 658.46534 | F26: 79015.841 | G26: 9481.9009
B27: Автовесовая и охрана КПП | C27: 8 | D27: 8917500 | E27: =IFERROR(F27/C27/12,0) -> 823.08168 | F27: 79015.841 | G27: 9481.9009
B28: ВСЕГО | C28: =SUM(C16:C27) -> 110 | F28: =SUM(F16:F27) -> 1614557 | G28: =SUM(G16:G27) -> 193746.84
B29: ИТОГО (фонд оплаты труда + социальный налог) | F29: =F28+G28 -> 1808303.9
B31: АДМИНИСТРАЦИЯ
B32: Генеральный директор | C32: 1 | D32: 35670000 | E32: =IFERROR(F32/C32/12,0) -> 3292.3267 | F32: 39507.92 | G32: 4740.9505
B33: Заместитель ген. директора | C33: 1 | D33: 23780000 | E33: =IFERROR(F33/C33/12,0) -> 2194.8845 | F33: 26338.614 | G33: 3160.6336
B34: Офисные служащие | C34: 3 | D34: 8323000 | E34: =IFERROR(F34/C34/12,0) -> 768.20956 | F34: 27655.544 | G34: 3318.6653
B35: Руководитель фин.-эконом. отдела | C35: 1 | D35: 14268000 | E35: =IFERROR(F35/C35/12,0) -> 1316.9307 | F35: 15803.168 | G35: 1896.3802
B36: Бухгалтер | C36: 1 | D36: 11890000 | E36: =IFERROR(F36/C36/12,0) -> 1097.4422 | F36: 13169.307 | G36: 1580.3168
B37: Кассир | C37: 1 | D37: 8323000 | E37: =IFERROR(F37/C37/12,0) -> 768.20956 | F37: 9218.5148 | G37: 1106.2218
B38: Руководитель отдела снабжения и сбыта | C38: 1 | D38: 14268000 | E38: =IFERROR(F38/C38/12,0) -> 1316.9307 | F38: 15803.168 | G38: 1896.3802
B39: Специалист по закупкам | C39: 1 | D39: 9512000 | E39: =IFERROR(F39/C39/12,0) -> 877.95379 | F39: 10535.445 | G39: 1264.2535
B40: Менеджер по продажам | C40: 1 | D40: 9512000 | E40: =IFERROR(F40/C40/12,0) -> 877.95379 | F40: 10535.445 | G40: 1264.2535
B41: Руководитель отдела кадров | C41: 1 | D41: 14268000 | E41: =IFERROR(F41/C41/12,0) -> 1316.9307 | F41: 15803.168 | G41: 1896.3802
B42: Специалист по кадрам | C42: 1 | D42: 9512000 | E42: =IFERROR(F42/C42/12,0) -> 877.95379 | F42: 10535.445 | G42: 1264.2535
B43: Специалист по обучению | C43: 1 | D43: 9512000 | E43: =IFERROR(F43/C43/12,0) -> 877.95379 | F43: 10535.445 | G43: 1264.2535
... B49: Прочий обслуживающий персонал | C49: 3 | D49: 7134000 | E49: =IFERROR(F49/C49/12,0) -> 658.46534 | F49: 23704.752 | G49: 2844.5703
B50: ВСЕГО | C50: =SUM(C32:C49) -> 28 | F50: =SUM(F32:F49) -> 351620.49 | G50: =SUM(G32:G49) -> 42194.459
...

Sheet Taxes
B2: НАЛОГИ И СБОРЫ (в экв. долл. США) | K2: Приложение 9
B4: ПОКАЗАТЕЛИ | C4: Ставка | D4: 1 год (льготный / инвест.) | E4: 2 год | F4: 3 год | G4: 4 год | H4: 5 год | I4: 6 год | J4: 7 год
D5: 2027 | E5: 2028 | F5: 2029 | G5: 2030 | H5: 2031 | I5: 2032 | J5: 2033
B6: Налоги и сборы, включаемые в расходы | D6: =SUM(D7:D11) -> 354260.87 | E6: =SUM(E7:E11) -> 741803.03 | F6: =SUM(F7:F11) -> 736166.57 | G6: =SUM(G7:G11) -> 730661.19 | H6: =SUM(H7:H11) -> 725269.65 | I6: =SUM(I7:I11) -> 719992.32 | J6: =SUM(J7:J11) -> 714831.68 | K6: =SUM(K7:K11) -> 0
B7: Налог на имущество | C7: 1.50% | D7: =CostSold!D34 -> 131837.12 | E7: =CostSold!E34 -> 515884.38 | F7: =CostSold!F34 -> 505302.13 | G7: =CostSold!G34 -> 494719.89 | H7: =CostSold!H34 -> 484137.65 | I7: =CostSold!I34 -> 473555.4 | J7: =CostSold!J34 -> 462973.16
B8: Земельный налог | D8: =CostSold!D35 -> 0 | E8: =CostSold!E35 -> 0 | F8: =CostSold!F35 -> 0 | G8: =CostSold!G35 -> 0 | H8: =CostSold!H35 -> 0 | I8: =CostSold!I35 -> 0 | J8: =CostSold!J35 -> 0
B9: Специальный рентный налог | D9: =CostSold!D36 -> 0 | E9: =CostSold!E36 -> 0 | F9: =CostSold!F36 -> 0 | G9: =CostSold!G36 -> 0 | H9: =CostSold!H36 -> 0 | I9: =CostSold!I36 -> 0 | J9: =CostSold!J36 -> 0
B10: Налог за пользование недрами (НДПИ) - в себестоимости | D10: =CostSold!D19 -> 0 | E10: =CostSold!E19 -> 0 | F10: =CostSold!F19 -> 0 | G10: =CostSold!G19 -> 0 | H10: =CostSold!H19 -> 0 | I10: =CostSold!I19 -> 0 | J10: =CostSold!J19 -> 0
B11: Социальный налог (производственный и административный персонал) | C11: 12% | D11: 222423.75 | E11: 225918.65 | F11: 230864.44 | G11: 235941.3 | H11: 241132.01 | I11: 246436.91 | J11: 251858.53
B13: Прочие налоги | D13: =D14+D15 -> 9625.4712 | E13: =E14+E15 -> 1099291 | F13: =F14+F15 -> 1961140.5 | G13: =G14+G15 -> 2665862.7 | H13: =H14+H15 -> 2774161.7 | I13: =I14+I15 -> 2873669 | J13: =J14+J15 -> 2975205.2 | K13: =K14+K15 -> 0
B14: Налог на прибыль (Приложение 13) | D14: =ProfLoss!D21 -> 9625.4712 | E14: =ProfLoss!E21 -> 1099291 | F14: =ProfLoss!F21 -> 1961140.5 | G14: =ProfLoss!G21 -> 2665862.7 | H14: =ProfLoss!H21 -> 2774161.7 | I14: =ProfLoss!I21 -> 2873669 | J14: =ProfLoss!J21 -> 2975205.2
B15: НДС к уплате в бюджет (при превышении входящего НДС - к возмещению, см. ниже) | C15: 12% | D15: =MAX(0,D22) -> 0 | E15: =MAX(0,E22) -> 0 | F15: =MAX(0,F22) -> 0 | G15: =MAX(0,G22) -> 0 | H15: =MAX(0,H22) -> 0 | I15: =MAX(0,I22) -> 0 | J15: =MAX(0,J22) -> 0
B16: ВСЕГО НАЛОГОВ И ОТЧИСЛЕНИЙ | D16: =D6+D13 -> 363886.34 | E16: =E6+E13 -> 1841094.1 | F16: =F6+F13 -> 2697307.1 | G16: =G6+G13 -> 3396523.9 | H16: =H6+H13 -> 3499431.4 | I16: =I6+I13 -> 3593661.3 | J16: =J6+J13 -> 3690036.8
B18: Расчет НДС
B19: НДС исходящий (реализация на внутреннем рынке; экспорт - 0%) | D19: 0 | E19: 0 | F19: 0 | G19: 0 | H19: 0 | I19: 0 | J19: 0
B20: НДС входящий - по операционным затратам | D20: 867145.92 | E20: 2710683.4 | F20: 3505443.9 | G20: 4146349.5 | H20: 4237863.2 | I20: 4331096.1 | J20: 4426380.3
B21: НДС входящий - по капитальным вложениям (1-й год вкл. 2026 г.) | D21: 6491364.7 | E21: 64751.767 | F21: 64751.767 | G21: 64751.767 | H21: 64751.767 | I21: 64751.767 | J21: 64751.767
B22: НДС к уплате (+) / к возмещению из бюджета (-) | D22: =D19-D20-D21 -> -7358510.6 | E22: =E19-E20-E21 -> -2775435.1 | F22: =F19-F20-F21 -> -3570195.6 | G22: =G19-G20-G21 -> -4211101.3 | H22: =H19-H20-H21 -> -4302614.9 | I22: =I19-I20-I21 -> -4395847.9 | J22: =J19-J20-J21 -> -4491132
B24: Расчет налога на прибыль
B25: Прибыль (убыток) до налогообложения (Приложение 13) | D25: =ProfLoss!D20 -> 64169.808 | E25: =ProfLoss!E20 -> 7328607 | F25: =ProfLoss!F20 -> 13074270 | G25: =ProfLoss!G20 -> 17772418 | H25: =ProfLoss!H20 -> 18494412 | I25: =ProfLoss!I20 -> 19157793 | J25: =ProfLoss!J20 -> 19834701
B26: Налоговые корректировки | D26: -1.2805685e-09 | E26: 0 | F26: 0 | G26: 0 | H26: 0 | I26: 7.4505806e-09 | J26: 0
B27: Налогооблагаемая прибыль | D27: =D25+D26 -> 64169.808 | E27: =E25+E26 -> 7328607 | F27: =F25+F26 -> 13074270 | G27: =G25+G26 -> 17772418 | H27: =H25+H26 -> 18494412 | I27: =I25+I26 -> 19157793 | J27: =J25+J26 -> 19834701
B28: Ставка налога на прибыль | C28: % | D28: 0.15 | E28: 0.15 | F28: 0.15 | G28: 0.15 | H28: 0.15 | I28: 0.15 | J28: 0.15
B29: Налог на прибыль | D29: =D27*D28 -> 9625.4712 | E29: =E27*E28 -> 1099291 | F29: =F27*F28 -> 1961140.5 | G29: =G27*G28 -> 2665862.7 | H29: =H27*H28 -> 2774161.7 | I29: =I27*I28 -> 2873669 | J29: =J27*J28 -> 2975205.2

Sheet CostTotal
B2: СТОИМОСТЬ ПРОДУКЦИИ ПРИ ПРОЕКТНОЙ МОЩНОСТИ (в экв. долл. США, 2030 г.) | H2: Приложение 10
B3: Разделение на постоянные и переменные затраты.
B5: Статьи издержек | C5: Всего стоимость | D5: Доля постоянных затрат (%) | E5: Доля переменных затрат (%) | F5: Фиксированная стоимость | G5: Переменная стоимость
B6: Сырьё, материалы и прочие переменные затраты по статьям ТЭО | C6: =C7+C8 -> 27336361 | D6: =IFERROR(F6/C6,0) -> 0 | E6: =IFERROR(G6/C6,0) -> 1 | F6: =F7+F8 -> 0 | G6: =G7+G8 -> 27336361
B7: с ценой в твёрдой валюте (USD) | C7: =F7+G7 -> 579085.84 | D7: =IFERROR(F7/C7,0) -> 0 | E7: =IFERROR(G7/C7,0) -> 1 | F7: 0 | G7: 579085.84
B8: с ценой в национальной валюте | C8: =F8+G8 -> 26757275 | D8: =IFERROR(F8/C8,0) -> 0 | E8: =IFERROR(G8/C8,0) -> 1 | F8: 0 | G8: 26757275
B9: Энергоресурсы (электроэнергия, газ, вода) | C9: =F9+G9 -> 1618616.2 | D9: =IFERROR(F9/C9,0) -> 0.20034937 | E9: =IFERROR(G9/C9,0) -> 0.79965063 | F9: 324288.72 | G9: 1294327.4
B10: Зарплата производственного персонала (с соц. налогом) | C10: =F10+G10 -> 1808303.9 | D10: =IFERROR(F10/C10,0) -> 1 | E10: =IFERROR(G10/C10,0) -> 0 | F10: 1808303.9 | G10: 0
B11: Зарплата административного персонала (с соц. налогом) | C11: =F11+G11 -> 393814.95 | D11: =IFERROR(F11/C11,0) -> 1 | E11: =IFERROR(G11/C11,0) -> 0 | F11: 393814.95 | G11: 0
B12: Ремонт и техническое обслуживание (постоянная часть) | C12: =F12+G12 -> 1018194 | D12: =IFERROR(F12/C12,0) -> 1 | E12: =IFERROR(G12/C12,0) -> 0 | F12: 1018194 | G12: 0
B13: Прочие производственные расходы (постоянная часть) | C13: =F13+G13 -> 94026.769 | D13: =IFERROR(F13/C13,0) -> 1 | E13: =IFERROR(G13/C13,0) -> 0 | F13: 94026.769 | G13: 0
B14: Налог за пользование недрами (НДПИ) | C14: =F14+G14 -> 0 | D14: =IFERROR(F14/C14,0) -> 0 | E14: =IFERROR(G14/C14,0) -> 0 | F14: 0 | G14: 0
B15: Административные расходы (без персонала и амортизации) | C15: =F15+G15 -> 4104621.3 | D15: =IFERROR(F15/C15,0) -> 0.68936962 | E15: =IFERROR(G15/C15,0) -> 0.31063038 | F15: 2829601.3 | G15: 1275020.1
B16: Коммерческие расходы | C16: =F16+G16 -> 294586.47 | D16: =IFERROR(F16/C16,0) -> 0 | E16: =IFERROR(G16/C16,0) -> 1 | F16: 0 | G16: 294586.47
B17: Налог на имущество и земельный налог | C17: =F17+G17 -> 494719.89 | D17: =IFERROR(F17/C17,0) -> 1 | E17: =IFERROR(G17/C17,0) -> 0 | F17: 494719.89 | G17: 0
B18: Специальный рентный налог | C18: =F18+G18 -> 0 | D18: =IFERROR(F18/C18,0) -> 0 | E18: =IFERROR(G18/C18,0) -> 0 | F18: 0 | G18: 0
B19: Резерв на непредвиденные операционные расходы | C19: =F19+G19 -> 733370.49 | D19: =IFERROR(F19/C19,0) -> 0 | E19: =IFERROR(G19/C19,0) -> 1 | F19: 0 | G19: 733370.49
B20: Прочие операционные расходы / (доходы) | C20: =F20+G20 -> 0 | D20: =IFERROR(F20/C20,0) -> 0 | E20: =IFERROR(G20/C20,0) -> 0 | F20: 0 | G20: 0
B21: Амортизация (Приложение 4) | C21: =F21+G21 -> 2835492.6 | D21: =IFERROR(F21/C21,0) -> 1 | E21: =IFERROR(G21/C21,0) -> 0 | F21: =Depreciate!J18 -> 2835492.6 | G21: 0
B22: ИТОГО | C22: =SUM(C6:C21)-C6 -> 40732108 | D22: =IFERROR(F22/C22,0) -> 0.24055819 | E22: =IFERROR(G22/C22,0) -> 0.75944181 | F22: =SUM(F6:F21)-F6 -> 9798442.1 | G22: =SUM(G6:G21)-G6 -> 30933666
B23: в т.ч. в местной валюте | C23: =C22-C24 -> 39146524
B24: в т.ч. в твёрдой валюте (производственные затраты в USD) | C24: 1585583.8
B26: Выручка (2030 г.) | C26: =SalePlan!G18 -> 58917295
B27: Затраты на 1 USD выручки | C27: =IFERROR(C22/C26,0) -> 0.69134382
B28: Полная себестоимость единицы основной продукции, USD/t | C28: =IFERROR(C22/ProdPlan!G17,0) -> 20539.924

Sheet CostSold
B2: ГОДОВАЯ СТОИМОСТЬ ПРОДАННОЙ ПРОДУКЦИИ (в экв. долл. США) | K2: Приложение 11
B4: ПОКАЗАТЕЛИ | C4: Ед. изм. | D4: 1 год (льготный / инвест.) | E4: 2 год | F4: 3 год | G4: 4 год | H4: 5 год | I4: 6 год | J4: 7 год
D5: 2027 | E5: 2028 | F5: 2029 | G5: 2030 | H5: 2031 | I5: 2032 | J5: 2033
B6: Освоение мощностей (основная продукция) | C6: % | D6: =ProdPlan!D13 -> 0.15 | E6: =ProdPlan!E13 -> 0.65 | F6: =ProdPlan!F13 -> 0.85 | G6: =ProdPlan!G13 -> 1 | H6: =ProdPlan!H13 -> 1 | I6: =ProdPlan!I13 -> 1 | J6: =ProdPlan!J13 -> 1
B8: ПРОИЗВОДСТВЕННАЯ СЕБЕСТОИМОСТЬ ПО ЭЛЕМЕНТАМ
B9: Сырьё | C9: USD | D9: 3497193.1 | E9: 15362010 | F9: 20530736 | G9: 24685190 | H9: 25228265 | I9: 25783286 | J9: 26350519
B10: Вспомогательные материалы | C10: USD | D10: 375595.88 | E10: 1649868.2 | F10: 2204985.4 | G10: 2651170.7 | H10: 2709496.4 | I10: 2769105.4 | J10: 2830025.7
B11: Электроэнергия | C11: USD | D11: 187583.89 | E11: 798120.72 | F11: 969024.43 | G11: 1107882 | H11: 1132255.4 | I11: 1157165 | J11: 1182622.6
B12: Природный газ / топливо | C12: USD | D12: 72356.588 | E12: 317838.5 | F12: 424778.94 | G12: 510734.2 | H12: 521970.36 | I12: 533453.7 | J12: 545189.69
B13: Вода | C13: USD | D13: 0 | E13: 0 | F13: 0 | G13: 0 | H13: 0 | I13: 0 | J13: 0
B14: Заработная плата | C14: USD | D14: 1522055.8 | E14: 1545971.6 | F14: 1579815.8 | G14: 1614557 | H14: 1650077.3 | I14: 1686379 | J14: 1723479.3
B15: Социальный налог | C15: USD | D15: 182646.7 | E15: 185516.59 | F15: 189577.9 | G15: 193746.84 | H15: 198009.27 | I15: 202365.48 | J15: 206817.52
B16: Амортизация (Приложение 4) | C16: USD | D16: =Depreciate!$G$19 -> 566139.04 | E16: =Depreciate!$H$19 -> 2323012.6 | F16: =Depreciate!$I$19 -> 2376972.4 | G16: =Depreciate!$J$19 -> 2430932.2 | H16: =Depreciate!$K$19 -> 2484892 | I16: =Depreciate!$L$19 -> 2538851.8 | J16: =Depreciate!$M$19 -> 2592811.7
B17: Ремонт и техобслуживание | C17: USD | D17: 144249.29 | E17: 633639.3 | F17: 846834.56 | G17: 1018194 | H17: 1040594.3 | I17: 1063487.4 | J17: 1086884.1
B18: Прочие производственные расходы (без НДПИ) | C18: USD | D18: 13320.933 | E18: 58514.443 | F18: 78202.303 | G18: 94026.769 | H18: 96095.358 | I18: 98209.456 | J18: 100370.06
B19: Налог за пользование недрами (НДПИ) | C19: USD | D19: 0 | E19: 0 | F19: 0 | G19: 0 | H19: 0 | I19: 0 | J19: 0
B20: Себестоимость произведенной продукции | C20: USD | D20: =SUM(D9:D19) -> 6561141.3 | E20: =SUM(E9:E19) -> 22874492 | F20: =SUM(F9:F19) -> 29200927 | G20: =SUM(G9:G19) -> 34306434 | H20: =SUM(H9:H19) -> 35061655 | I20: =SUM(I9:I19) -> 35832304 | J20: =SUM(J9:J19) -> 36618719
B21: Изменение остатков готовой продукции (- прирост запаса) | C21: USD | D21: -2578055.9 | E21: -126098.79 | F21: -433201.8 | G21: -348879.66 | H21: -48431.841 | I21: -49497.342 | J21: -50586.283
B22: Себестоимость реализованной продукции | C22: USD | D22: =D20+D21 -> 3983085.3 | E22: =E20+E21 -> 22748393 | F22: =F20+F21 -> 28767726 | G22: =G20+G21 -> 33957554 | H22: =H20+H21 -> 35013223 | I22: =I20+I21 -> 35782806 | J22: =J20+J21 -> 36568133
B23: в т.ч. затраты в твёрдой валюте (USD) | C23: USD | D23: 154815.25 | E23: 1123057.2 | F23: 1434045.7 | G23: 1689151.4 | H23: 1717864.5 | I23: 1731824.2 | J23: 1746035.3
B24: в т.ч. затраты в национальной валюте | C24: USD | D24: =D22-D23 -> 3828270.1 | E24: =E22-E23 -> 21625336 | F24: =F22-F23 -> 27333680 | G24: =G22-G23 -> 32268403 | H24: =H22-H23 -> 33295359 | I24: =I22-I23 -> 34050982 | J24: =J22-J23 -> 34822098
B26: РАСХОДЫ ПЕРИОДА
B27: Зарплата административного персонала (с соц. налогом) | C27: USD | D27: 371252.51 | E27: 377085.92 | F27: 385341.05 | G27: 393814.95 | H27: 402478.88 | I27: 411333.42 | J27: 420382.75
B28: Амортизация административных активов | C28: USD | D28: =Depreciate!$G$20 -> 101140.09 | E28: =Depreciate!$H$20 -> 404560.35 | F28: =Depreciate!$I$20 -> 404560.35 | G28: =Depreciate!$J$20 -> 404560.35 | H28: =Depreciate!$K$20 -> 404560.35 | I28: =Depreciate!$L$20 -> 404560.35 | J28: =Depreciate!$M$20 -> 404560.35
B29: Прочие административные расходы (аренда, налог за воду, прочие) | C29: USD | D29: 2890625.1 | E29: 3531149.3 | F29: 3841648.3 | G29: 4104621.3 | H29: 4194923 | I29: 4287211.3 | J29: 4381530
B30: Коммерческие расходы (расходы по реализации) | C30: USD | D30: 45291.167 | E30: 183889.75 | F30: 244128.56 | G30: 294586.47 | H30: 302963.52 | I30: 309626.63 | J30: 316438.48
B31: Итого расходы периода | C31: USD | D31: =SUM(D27:D30) -> 3408308.9 | E31: =SUM(E27:E30) -> 4496685.3 | F31: =SUM(F27:F30) -> 4875678.2 | G31: =SUM(G27:G30) -> 5197583.1 | H31: =SUM(H27:H30) -> 5304925.8 | I31: =SUM(I27:I30) -> 5412731.7 | J31: =SUM(J27:J30) -> 5522911.5
B33: НАЛОГИ И ПРОЧИЕ ОПЕРАЦИОННЫЕ РАСХОДЫ
B34: Налог на имущество | C34: USD | D34: 131837.12 | E34: 515884.38 | F34: 505302.13 | G34: 494719.89 | H34: 484137.65 | I34: 473555.4 | J34: 462973.16
B35: Земельный налог | C35: USD | D35: 0 | E35: 0 | F35: 0 | G35: 0 | H35: 0 | I35: 0 | J35: 0
B36: Специальный рентный налог | C36: USD | D36: 0 | E36: 0 | F36: 0 | G36: 0 | H36: 0 | I36: 0 | J36: 0
B37: Резерв на непредвиденные операционные расходы | C37: USD | D37: 186043.42 | E37: 492872.09 | F37: 625901.46 | G37: 733370.49 | H37: 749542.57 | I37: 766032.46 | J37: 782885.18
B38: Прочие операционные расходы / (доходы) | C38: USD | D38: 1284788.8 | E38: 0 | F38: 0 | G38: 0 | H38: 0 | I38: 0 | J38: 0
B39: Итого налоги и прочие операционные расходы | C39: USD | D39: =SUM(D34:D38) -> 1602669.4 | E39: =SUM(E34:E38) -> 1008756.5 | F39: =SUM(F34:F38) -> 1131203.6 | G39: =SUM(G34:G38) -> 1228090.4 | H39: =SUM(H34:H38) -> 1233680.2 | I39: =SUM(I34:I38) -> 1239587.9 | J39: =SUM(J34:J38) -> 1245858.3
B41: ФИНАНСОВЫЕ ИЗДЕРЖКИ
B42: Проценты за кредит (1-й год - капитализированы, оплачены за счёт собственных средств) | C42: USD | D42: =0 -> 0 | E42: =LOANS!$D$106 -> 1195508.2 | F42: =LOANS!$E$106 -> 976834.44 | G42: =LOANS!$F$106 -> 761648.86 | H42: =LOANS!$G$106 -> 546463.28 | I42: =LOANS!$H$106 -> 332407.67 | J42: =LOANS!$I$106 -> 116092.13
B44: ПОЛНАЯ СТОИМОСТЬ ПРОДАННОЙ ПРОДУКЦИИ | C44: USD | D44: =D22+D31+D39+D42 -> 8994063.6 | E44: =E22+E31+E39+E42 -> 29449343 | F44: =F22+F31+F39+F42 -> 35751442 | G44: =G22+G31+G39+G42 -> 41144877 | H44: =H22+H31+H39+H42 -> 42098292 | I44: =I22+I31+I39+I42 -> 42767533 | J44: =J22+J31+J39+J42 -> 43452995
B45: Полная себестоимость единицы основной продукции | C45: USD/t | D45: =IFERROR(D44/(ProdPlan!D21+ProdPlan!D22),0) -> 36283.393 | E45: =IFERROR(E44/(ProdPlan!E21+ProdPlan!E22),0) -> 22920.201 | F45: =IFERROR(F44/(ProdPlan!F21+ProdPlan!F22),0) -> 21419.799 | G45: =IFERROR(G44/(ProdPlan!G21+ProdPlan!G22),0) -> 20878.562 | H45: =IFERROR(H44/(ProdPlan!H21+ProdPlan!H22),0) -> 21228.848 | I45: =IFERROR(I44/(ProdPlan!I21+ProdPlan!I22),0) -> 21566.326 | J45: =IFERROR(J44/(ProdPlan!J21+ProdPlan!J22),0) -> 21911.982

Sheet LOANS
B2: СХЕМА ВЫПЛАТЫ КРЕДИТА (в долл. США) | H2: Приложение 12
B5: Срок кредита | C5: =ИНФОРМАЦИЯ!$C$28 -> 84 | D5: месяцев
B6: Льготный период | C6: =ИНФОРМАЦИЯ!$C$29 -> 12 | D6: месяцев
B7: Инвестиционный период | C7: =ИНФОРМАЦИЯ!$C$30 -> 12 | D7: месяцев
B8: Процентная ставка | C8: =ИНФОРМАЦИЯ!$C$27 -> 0.07 | D8: годовых
B9: Сумма кредита | C9: =ИНФОРМАЦИЯ!$C$26 -> 18191814 | D9: USD
B10: Дата выдачи | C10: =ИНФОРМАЦИЯ!$C$31 -> 46388
B11: База начисления процентов | C11: =ИНФОРМАЦИЯ!$C$32 -> 360 | D11: дней
B12: Количество платежей по основному долгу | C12: =C5-C6 -> 72 | D12: платежей
B13: Ежемесячный платёж по основному долгу | C13: =C9/C12 -> 252664.08 | D13: USD
A15: № | B15: Дата платежа | C15: Остаток на начало | D15: Погашение основного долга | E15: Проценты | F15: Всего выплат | G15: Остаток на конец | H15: Год | I15: № года
A16: 1 | B16: =EOMONTH($C$10,0) -> 46418 | C16: =$C$9 -> 18191814 | D16: =IF(A16>$C$6,MIN(C16,$C$13),0) -> 0 | E16: =C16*$C$8*DAY(B16)/$C$11 -> 109656.21 | F16: =D16+E16 -> 109656.21 | G16: =C16-D16 -> 18191814 | H16: =YEAR(B16) -> 2027 | I16: =H16-2026 -> 1
A17: 2 | B17: =EOMONTH($C$10,1) -> 46446 | C17: =G16 -> 18191814 | D17: =IF(A17>$C$6,MIN(C17,$C$13),0) -> 0 | E17: =C17*$C$8*DAY(B17)/$C$11 -> 99044.32 | F17: =D17+E17 -> 99044.32 | G17: =C17-D17 -> 18191814 | H17: =YEAR(B17) -> 2027 | I17: =H17-2026 -> 1
A18: 3 | B18: =EOMONTH($C$10,2) -> 46477 | C18: =G17 -> 18191814 | D18: =IF(A18>$C$6,MIN(C18,$C$13),0) -> 0 | E18: =C18*$C$8*DAY(B18)/$C$11 -> 109656.21 | F18: =D18+E18 -> 109656.21 | G18: =C18-D18 -> 18191814 | H18: =YEAR(B18) -> 2027 | I18: =H18-2026 -> 1
A19: 4 | B19: =EOMONTH($C$10,3) -> 46507 | C19: =G18 -> 18191814 | D19: =IF(A19>$C$6,MIN(C19,$C$13),0) -> 0 | E19: =C19*$C$8*DAY(B19)/$C$11 -> 106118.91 | F19: =D19+E19 -> 106118.91 | G19: =C19-D19 -> 18191814 | H19: =YEAR(B19) -> 2027 | I19: =H19-2026 -> 1
A20: 5 | B20: =EOMONTH($C$10,4) -> 46538 | C20: =G19 -> 18191814 | D20: =IF(A20>$C$6,MIN(C20,$C$13),0) -> 0 | E20: =C20*$C$8*DAY(B20)/$C$11 -> 109656.21 | F20: =D20+E20 -> 109656.21 | G20: =C20-D20 -> 18191814 | H20: =YEAR(B20) -> 2027 | I20: =H20-2026 -> 1
A21: 6 | B21: =EOMONTH($C$10,5) -> 46568 | C21: =G20 -> 18191814 | D21: =IF(A21>$C$6,MIN(C21,$C$13),0) -> 0 | E21: =C21*$C$8*DAY(B21)/$C$11 -> 106118.91 | F21: =D21+E21 -> 106118.91 | G21: =C21-D21 -> 18191814 | H21: =YEAR(B21) -> 2027 | I21: =H21-2026 -> 1
A22: 7 | B22: =EOMONTH($C$10,6) -> 46599 | C22: =G21 -> 18191814 | D22: =IF(A22>$C$6,MIN(C22,$C$13),0) -> 0 | E22: =C22*$C$8*DAY(B22)/$C$11 -> 109656.21 | F22: =D22+E22 -> 109656.21 | G22: =C22-D22 -> 18191814 | H22: =YEAR(B22) -> 2027 | I22: =H22-2026 -> 1
A23: 8 | B23: =EOMONTH($C$10,7) -> 46630 | C23: =G22 -> 18191814 | D23: =IF(A23>$C$6,MIN(C23,$C$13),0) -> 0 | E23: =C23*$C$8*DAY(B23)/$C$11 -> 109656.21 | F23: =D23+E23 -> 109656.21 | G23: =C23-D23 -> 18191814 | H23: =YEAR(B23) -> 2027 | I23: =H23-2026 -> 1
A24: 9 | B24: =EOMONTH($C$10,8) -> 46660 | C24: =G23 -> 18191814 | D24: =IF(A24>$C$6,MIN(C24,$C$13),0) -> 0 | E24: =C24*$C$8*DAY(B24)/$C$11 -> 106118.91 | F24: =D24+E24 -> 106118.91 | G24: =C24-D24 -> 18191814 | H24: =YEAR(B24) -> 2027 | I24: =H24-2026 -> 1
A25: 10 | B25: =EOMONTH($C$10,9) -> 46691 | C25: =G24 -> 18191814 | D25: =IF(A25>$C$6,MIN(C25,$C$13),0) -> 0 | E25: =C25*$C$8*DAY(B25)/$C$11 -> 109656.21 | F25: =D25+E25 -> 109656.21 | G25: =C25-D25 -> 18191814 | H25: =YEAR(B25) -> 2027 | I25: =H25-2026 -> 1
A26: 11 | B26: =EOMONTH($C$10,10) -> 46721 | C26: =G25 -> 18191814 | D26: =IF(A26>$C$6,MIN(C26,$C$13),0) -> 0 | E26: =C26*$C$8*DAY(B26)/$C$11 -> 106118.91 | F26: =D26+E26 -> 106118.91 | G26: =C26-D26 -> 18191814 | H26: =YEAR(B26) -> 2027 | I26: =H26-2026 -> 1
A27: 12 | B27: =EOMONTH($C$10,11) -> 46752 | C27: =G26 -> 18191814 | D27: =IF(A27>$C$6,MIN(C27,$C$13),0) -> 0 | E27: =C27*$C$8*DAY(B27)/$C$11 -> 109656.21 | F27: =D27+E27 -> 109656.21 | G27: =C27-D27 -> 18191814 | H27: =YEAR(B27) -> 2027 | I27: =H27-2026 -> 1
A28: 13 | B28: =EOMONTH($C$10,12) -> 46783 | C28: =G27 -> 18191814 | D28: =IF(A28>$C$6,MIN(C28,$C$13),0) -> 252664.08 | E28: =C28*$C$8*DAY(B28)/$C$11 -> 109656.21 | F28: =D28+E28 -> 362320.29 | G28: =C28-D28 -> 17939150 | H28: =YEAR(B28) -> 2028 | I28: =H28-2026 -> 2
A29: 14 | B29: =EOMONTH($C$10,13) -> 46812 | C29: =G28 -> 17939150 | D29: =IF(A29>$C$6,MIN(C29,$C$13),0) -> 252664.08 | E29: =C29*$C$8*DAY(B29)/$C$11 -> 101156.87 | F29: =D29+E29 -> 353820.96 | G29: =C29-D29 -> 17686486 | H29: =YEAR(B29) -> 2028 | I29: =H29-2026 -> 2
A30: 15 | B30: =EOMONTH($C$10,14) -> 46843 | C30: =G29 -> 17686486 | D30: =IF(A30>$C$6,MIN(C30,$C$13),0) -> 252664.08 | E30: =C30*$C$8*DAY(B30)/$C$11 -> 106610.21 | F30: =D30+E30 -> 359274.29 | G30: =C30-D30 -> 17433822 | H30: =YEAR(B30) -> 2028 | I30: =H30-2026 -> 2
A31: 16 | B31: =EOMONTH($C$10,15) -> 46873 | C31: =G30 -> 17433822 | D31: =IF(A31>$C$6,MIN(C31,$C$13),0) -> 252664.08 | E31: =C31*$C$8*DAY(B31)/$C$11 -> 101697.29 | F31: =D31+E31 -> 354361.38 | G31: =C31-D31 -> 17181158 | H31: =YEAR(B31) -> 2028 | I31: =H31-2026 -> 2
A32: 17 | B32: =EOMONTH($C$10,16) -> 46904 | C32: =G31 -> 17181158 | D32: =IF(A32>$C$6,MIN(C32,$C$13),0) -> 252664.08 | E32: =C32*$C$8*DAY(B32)/$C$11 -> 103564.2 | F32: =D32+E32 -> 356228.28 | G32: =C32-D32 -> 16928494 | H32: =YEAR(B32) -> 2028 | I32: =H32-2026 -> 2
A33: 18 | B33: =EOMONTH($C$10,17) -> 46934 | C33: =G32 -> 16928494 | D33: =IF(A33>$C$6,MIN(C33,$C$13),0) -> 252664.08 | E33: =C33*$C$8*DAY(B33)/$C$11 -> 98749.546 | F33: =D33+E33 -> 351413.63 | G33: =C33-D33 -> 16675829 | H33: =YEAR(B33) -> 2028 | I33: =H33-2026 -> 2
A34: 19 | B34: =EOMONTH($C$10,18) -> 46965 | C34: =G33 -> 16675829 | D34: =IF(A34>$C$6,MIN(C34,$C$13),0) -> 252664.08 | E34: =C34*$C$8*DAY(B34)/$C$11 -> 100518.19 | F34: =D34+E34 -> 353182.28 | G34: =C34-D34 -> 16423165 | H34: =YEAR(B34) -> 2028 | I34: =H34-2026 -> 2
A35: 20 | B35: =EOMONTH($C$10,19) -> 46996 | C35: =G34 -> 16423165 | D35: =IF(A35>$C$6,MIN(C35,$C$13),0) -> 252664.08 | E35: =C35*$C$8*DAY(B35)/$C$11 -> 98995.191 | F35: =D35+E35 -> 351659.27 | G35: =C35-D35 -> 16170501 | H35: =YEAR(B35) -> 2028 | I35: =H35-2026 -> 2
A36: 21 | B36: =EOMONTH($C$10,20) -> 47026 | C36: =G35 -> 16170501 | D36: =IF(A36>$C$6,MIN(C36,$C$13),0) -> 252664.08 | E36: =C36*$C$8*DAY(B36)/$C$11 -> 94327.924 | F36: =D36+E36 -> 346992.01 | G36: =C36-D36 -> 15917837 | H36: =YEAR(B36) -> 2028 | I36: =H36-2026 -> 2
A37: 22 | B37: =EOMONTH($C$10,21) -> 47057 | C37: =G36 -> 15917837 | D37: =IF(A37>$C$6,MIN(C37,$C$13),0) -> 252664.08 | E37: =C37*$C$8*DAY(B37)/$C$11 -> 95949.185 | F37: =D37+E37 -> 348613.27 | G37: =C37-D37 -> 15665173 | H37: =YEAR(B37) -> 2028 | I37: =H37-2026 -> 2
A38: 23 | B38: =EOMONTH($C$10,22) -> 47087 | C38: =G37 -> 15665173 | D38: =IF(A38>$C$6,MIN(C38,$C$13),0) -> 252664.08 | E38: =C38*$C$8*DAY(B38)/$C$11 -> 91380.177 | F38: =D38+E38 -> 344044.26 | G38: =C38-D38 -> 15412509 | H38: =YEAR(B38) -> 2028 | I38: =H38-2026 -> 2
A39: 24 | B39: =EOMONTH($C$10,23) -> 47118 | C39: =G38 -> 15412509 | D39: =IF(A39>$C$6,MIN(C39,$C$13),0) -> 252664.08 | E39: =C39*$C$8*DAY(B39)/$C$11 -> 92903.18 | F39: =D39+E39 -> 345567.26 | G39: =C39-D39 -> 15159845 | H39: =YEAR(B39) -> 2028 | I39: =H39-2026 -> 2
A40: 25 | B40: =EOMONTH($C$10,24) -> 47149 | C40: =G39 -> 15159845 | D40: =IF(A40>$C$6,MIN(C40,$C$13),0) -> 252664.08 | E40: =C40*$C$8*DAY(B40)/$C$11 -> 91380.177 | F40: =D40+E40 -> 344044.26 | G40: =C40-D40 -> 14907181 | H40: =YEAR(B40) -> 2029 | I40: =H40-2026 -> 3
A41: 26 | B41: =EOMONTH($C$10,25) -> 47177 | C41: =G40 -> 14907181 | D41: =IF(A41>$C$6,MIN(C41,$C$13),0) -> 252664.08 | E41: =C41*$C$8*DAY(B41)/$C$11 -> 81161.318 | F41: =D41+E41 -> 333825.4 | G41: =C41-D41 -> 14654517 | H41: =YEAR(B41) -> 2029 | I41: =H41-2026 -> 3
A42: 27 | B42: =EOMONTH($C$10,26) -> 47208 | C42: =G41 -> 14654517 | D42: =IF(A42>$C$6,MIN(C42,$C$13),0) -> 252664.08 | E42: =C42*$C$8*DAY(B42)/$C$11 -> 88334.171 | F42: =D42+E42 -> 340998.25 | G42: =C42-D42 -> 14401853 | H42: =YEAR(B42) -> 2029 | I42: =H42-2026 -> 3
A43: 28 | B43: =EOMONTH($C$10,27) -> 47238 | C43: =G42 -> 14401853 | D43: =IF(A43>$C$6,MIN(C43,$C$13),0) -> 252664.08 | E43: =C43*$C$8*DAY(B43)/$C$11 -> 84010.808 | F43: =D43+E43 -> 336674.89 | G43: =C43-D43 -> 14149189 | H43: =YEAR(B43) -> 2029 | I43: =H43-2026 -> 3
A44: 29 | B44: =EOMONTH($C$10,28) -> 47269 | C44: =G43 -> 14149189 | D44: =IF(A44>$C$6,MIN(C44,$C$13),0) -> 252664.08 | E44: =C44*$C$8*DAY(B44)/$C$11 -> 85288.165 | F44: =D44+E44 -> 337952.25 | G44: =C44-D44 -> 13896525 | H44: =YEAR(B44) -> 2029 | I44: =H44-2026 -> 3
...

Sheet ProfLoss
B2: ПРЕДПОЛАГАЕМЫЕ СЧЕТА ПРИБЫЛЕЙ И УБЫТКОВ (в экв. долл. США) | K2: Приложение 13
B4: ПОКАЗАТЕЛИ | C4: Ед. изм. | D4: 1 год (льготный / инвест.) | E4: 2 год | F4: 3 год | G4: 4 год | H4: 5 год | I4: 6 год | J4: 7 год
D5: 2027 | E5: 2028 | F5: 2029 | G5: 2030 | H5: 2031 | I5: 2032 | J5: 2033
